Workbook

Sheet Ventas
A1: Articulo | B1: Descripcion | C1: Codigos Barras | D1: Vta.Jul/25 | E1: Vta.Ago/25 | F1: Vta.Sep/25 | G1: Vta.Oct/25 | H1: Vta.Nov/25 | I1: Vta.Dic/25 | J1: Vta.Ene/26 | K1: Vta.Feb/26 | L1: Vta.Mar/26 | M1: Vta.Abr/26 | N1: Vta.May/26 | O1: Vta.Jun/26 | P1: Vta.Jul/26 | Q1: Jul/25 | R1: Ago/25 | S1: Sep/25 | T1: Oct/25 | U1: Nov/25 | V1: Dic/25 | W1: Ene/26 | X1: Feb/26 | Y1: Mar/26 | Z1: Abr/26 | AA1: May/26 | AB1: Jun/26 | AC1: Jul/26 | AD1: Rotacion DesEstac. | AE1: Rot. Manual | AF1: Estado Art.
A2: HX076 | B2: LLAVERO FANTECH | Q2: 0 | R2: 0 | S2: 0 | T2: 0 | U2: 0 | V2: 0 | W2: 0 | X2: 0 | Y2: 0 | Z2: 0 | AA2: 0 | AB2: 0 | AC2: 0 | AF2: A
A3: HX077 | B3: CINTA VELCRO ORGANIZ. DE CABLES FANTECH | Q3: 0 | R3: 0 | S3: 0 | T3: 0 | U3: 0 | V3: 0 | W3: 0 | X3: 0 | Y3: 0 | Z3: 0 | AA3: 0 | AB3: 0 | AC3: 0 | AF3: A
A4: HX033 | B4: GORRA FANTECH | Q4: 0 | R4: 0 | S4: 0 | T4: 0 | U4: 0 | V4: 0 | W4: 0 | X4: 0 | Y4: 0 | Z4: 0 | AA4: 0 | AB4: 0 | AC4: 0 | AF4: A
A5: HX034 | B5: VASO FANTECH NEGRO | Q5: 0 | R5: 0 | S5: 0 | T5: 0 | U5: 0 | V5: 0 | W5: 0 | X5: 0 | Y5: 0 | Z5: 0 | AA5: 0 | AB5: 0 | AC5: 0 | AF5: A
A6: HX035 | B6: CAMPERA DE NYLON FANTECH XL - NO USAR | Q6: 0 | R6: 0 | S6: 0 | T6: 0 | U6: 0 | V6: 0 | W6: 0 | X6: 0 | Y6: 0 | Z6: 0 | AA6: 0 | AB6: 0 | AC6: 0 | AF6: A
A7: HX036 | B7: CAMPERA DE NYLON FANTECH XXL | Q7: 0 | R7: 0 | S7: 0 | T7: 0 | U7: 0 | V7: 0 | W7: 0 | X7: 0 | Y7: 0 | Z7: 0 | AA7: 0 | AB7: 0 | AC7: 0 | AF7: A
A8: HX040 | B8: REMERA FANTECH M - NO USAR | Q8: 0 | R8: 0 | S8: 0 | T8: 0 | U8: 0 | V8: 0 | W8: 0 | X8: 0 | Y8: 0 | Z8: 0 | AA8: 0 | AB8: 0 | AC8: 0 | AF8: A
A9: HX041 | B9: REMERA FANTECH L - NO USAR | Q9: 0 | R9: 0 | S9: 0 | T9: 0 | U9: 0 | V9: 0 | W9: 0 | X9: 0 | Y9: 0 | Z9: 0 | AA9: 0 | AB9: 0 | AC9: 0 | AF9: A
A10: HX046 | B10: VASO FANTECH ROJO | Q10: 0 | R10: 0 | S10: 0 | T10: 0 | U10: 0 | V10: 0 | W10: 0 | X10: 0 | Y10: 0 | Z10: 0 | AA10: 0 | AB10: 0 | AC10: 0 | AF10: A
A11: HX047 | B11: REMERA FANTECH M RED - NO USAR | Q11: 0 | R11: 0 | S11: 0 | T11: 0 | U11: 0 | V11: 0 | W11: 0 | X11: 0 | Y11: 0 | Z11: 0 | AA11: 0 | AB11: 0 | AC11: 0 | AF11: A
A12: HX048 | B12: REMERA FANTECH L RED - NO USAR | Q12: 0 | R12: 0 | S12: 0 | T12: 0 | U12: 0 | V12: 0 | W12: 0 | X12: 0 | Y12: 0 | Z12: 0 | AA12: 0 | AB12: 0 | AC12: 0 | AF12: A
A13: HX049 | B13: REMERA FANTECH XL RED - NO USAR | Q13: 0 | R13: 0 | S13: 0 | T13: 0 | U13: 0 | V13: 0 | W13: 0 | X13: 0 | Y13: 0 | Z13: 0 | AA13: 0 | AB13: 0 | AC13: 0 | AF13: A
... A38: I001168 | B38: VASO FANTECH NEGRO - NO USAR | Q38: 0 | R38: 0 | S38: 0 | T38: 0 | U38: 0 | V38: 0 | W38: 0 | X38: 0 | Y38: 0 | Z38: 0 | AA38: 0 | AB38: 0 | AC38: 0 | AF38: A
A39: I00975 | B39: MOUSE GAMING X17 BK BLAKE FANTECH | E39: 6 | Q39: 0 | R39: 0.4615 | S39: 0 | T39: 0 | U39: 0 | V39: 0 | W39: 0 | X39: 0 | Y39: 0 | Z39: 0 | AA39: 0 | AB39: 0 | AC39: 0 | AF39: D
A40: I00976 | B40: TECLADO FANTECH CABLEADO NEGRO K513 | Q40: 0 | R40: 0 | S40: 0 | T40: 0 | U40: 0 | V40: 0 | W40: 0 | X40: 0 | Y40: 0 | Z40: 0 | AA40: 0 | AB40: 0 | AC40: 0 | AF40: A
A41: I00977 | B41: TECLADO MECANICO FANTECH CABLEADO NEGRO MK851RGB | Q41: 0 | R41: 0 | S41: 0 | T41: 0 | U41: 0 | V41: 0 | W41: 0 | X41: 0 | Y41: 0 | Z41: 0 | AA41: 0 | AB41: 0 | AC41: 0 | AF41: A
A42: I00978 | B42: AURICULAR CABLEADO FANTECH 7.1 BK HG15 | Q42: 0 | R42: 0 | S42: 0 | T42: 0 | U42: 0 | V42: 0 | W42: 0 | X42: 0 | Y42: 0 | Z42: 0 | AA42: 0 | AB42: 0 | AC42: 0 | AF42: A
A43: I00980 | B43: PARLANTE 2.0 USB FANTECH BLACK / WHITE GS201 | Q43: 0 | R43: 0 | S43: 0 | T43: 0 | U43: 0 | V43: 0 | W43: 0 | X43: 0 | Y43: 0 | Z43: 0 | AA43: 0 | AB43: 0 | AC43: 0 | AF43: A
A44: I00981 | B44: PARLANTE USB/3.5M GS202 BK RGB FANTECH | D44: 13 | E44: 8 | F44: 4 | G44: 3 | H44: 3 | I44: 6 | J44: 5 | K44: 7 | L44: 5 | M44: 1 | N44: 4 | O44: 5 | P44: 1 | Q44: 0.233 | R44: 0.2581 | S44: 0.1905 | T44: 0.0968 | U44: 0.0909 | V44: 0.1382 | W44: 0.2016 | X44: 0.3571 | Y44: 0.1792 | Z44: 0.0417 | AA44: 0.129 | AB44: 0.1667 | AC44: 0.0179 | AD44: 0.1736 | AE44: 0.1736 | AF44: A
A45: I00982 | B45: NO FACTURAR PARLANTE 2.0 USB FANTECH BK GS203 | Q45: 0 | R45: 0 | S45: 0 | T45: 0 | U45: 0 | V45: 0 | W45: 0 | X45: 0 | Y45: 0 | Z45: 0 | AA45: 0 | AB45: 0 | AC45: 0 | AF45: A
A46: I00983 | B46: PARLANTE BARRA BS150 BT SPACE EDITION FANTECH | Q46: 0 | R46: 0 | S46: 0 | T46: 0 | U46: 0 | V46: 0 | W46: 0 | X46: 0 | Y46: 0 | Z46: 0 | AA46: 0 | AB46: 0 | AC46: 0 | AF46: D
A47: I00984 | B47: FAN FC124 RGB FANTECH | Q47: 0 | R47: 0 | S47: 0 | T47: 0 | U47: 0 | V47: 0 | W47: 0 | X47: 0 | Y47: 0 | Z47: 0 | AA47: 0 | AB47: 0 | AC47: 0 | AF47: D
A48: I00985 | B48: KIT FAN COOLER FB301 RGB FANTECH | Q48: 0 | R48: 0 | S48: 0 | T48: 0 | U48: 0 | V48: 0 | W48: 0 | X48: 0 | Y48: 0 | Z48: 0 | AA48: 0 | AB48: 0 | AC48: 0 | AF48: D
A49: I00986 | B49: VENTILADOR PC RGB FANTECH FB302 | Q49: 0 | R49: 0 | S49: 0 | T49: 0 | U49: 0 | V49: 0 | W49: 0 | X49: 0 | Y49: 0 | Z49: 0 | AA49: 0 | AB49: 0 | AC49: 0 | AF49: A
A50: I01003 | B50: PARLANTE USB/3.5M GS203 BK RGB FANTECH | D50: 65 | E50: 8 | F50: 38 | G50: 31 | H50: 11 | I50: 17 | J50: 16 | K50: 31 | L50: 17 | M50: 45 | N50: 30 | O50: 24 | P50: 36 | Q50: 1.1649 | R50: 0.2581 | S50: 1.8095 | T50: 1 | U50: 0.3333 | V50: 0.3917 | W50: 0.6452 | X50: 1.5816 | Y50: 0.6093 | Z50: 1.875 | AA50: 0.9677 | AB50: 0.8 | AC50: 0.6452 | AD50: 0.953 | AE50: 0.953 | AF50: A
A51: I01004 | B51: PARLANTE USB/3.5M GS203 WH RGB SPACE EDIT FANTECH | D51: 15 | E51: 10 | F51: 9 | G51: 15 | H51: 20 | I51: 2 | J51: 10 | K51: 10 | L51: 24 | M51: 14 | N51: 9 | O51: 15 | Q51: 0.2688 | R51: 0.3226 | S51: 0.4286 | T51: 0.4839 | U51: 0.6061 | V51: 0.0461 | W51: 0.4032 | X51: 0.5102 | Y51: 0.8602 | Z51: 0.5833 | AA51: 0.2903 | AB51: 0.5 | AC51: 0 | AD51: 0.4419 | AE51: 0.4419 | AF51: A
A52: I01060 | B52: TECLADO MECÁNICO MK852 FANTECH SAKURA | Q52: 0 | R52: 0 | S52: 0 | T52: 0 | U52: 0 | V52: 0 | W52: 0 | X52: 0 | Y52: 0 | Z52: 0 | AA52: 0 | AB52: 0 | AC52: 0 | AF52: A
A53: I01061 | B53: MOUSEPAD SAKURA MPR800s PINK FANTECH | D53: 6 | F53: -1 | G53: 2 | I53: 2 | J53: 5 | K53: 1 | L53: 2 | M53: 25 | N53: 1 | O53: 3 | P53: 3 | Q53: 0.1075 | R53: 0 | S53: -0.0476 | T53: 0.0645 | U53: 0 | V53: 0.0461 | W53: 0.2016 | X53: 0.051 | Y53: 0.0717 | Z53: 1.0417 | AA53: 0.0323 | AB53: 0.1 | AC53: 0.0538 | AD53: 0.1391 | AE53: 0.1391 | AF53: A
A54: I01062 | B54: SOPORTE AURICULAR AC3001 FANTECH SAKURA | D54: 5 | E54: 9 | F54: 3 | G54: -3 | H54: 4 | I54: 10 | J54: 10 | K54: 1 | L54: 1 | M54: 3 | O54: 2 | Q54: 0.0896 | R54: 0.2903 | S54: 0.1429 | T54: -0.0968 | U54: 0.1212 | V54: 0.2304 | W54: 0.4032 | X54: 0.051 | Y54: 0.0358 | Z54: 0.125 | AA54: 0 | AB54: 0.0667 | AC54: 0 | AD54: 0.1216 | AE54: 0.1216 | AF54: A
A55: I01063 | B55: MOUSE GAMING VX7 SAKURA EDITION FANTECH | D55: 5 | E55: 10 | F55: 24 | G55: 5 | H55: 1 | I55: 5 | J55: 2 | K55: 8 | L55: 4 | M55: 25 | N55: 7 | O55: 9 | Q55: 0.0896 | R55: 0.3226 | S55: 1.1429 | T55: 0.1613 | U55: 0.0303 | V55: 0.1152 | W55: 0.0806 | X55: 0.4082 | Y55: 0.1434 | Z55: 1.0417 | AA55: 0.2258 | AB55: 0.3 | AC55: 0 | AD55: 0.3385 | AE55: 0.3385 | AF55: A
A56: I01064 | B56: AURICULAR GAMING HG20 PINK SAKURA FANTECH | D56: 6 | E56: 5 | F56: -1 | H56: 4 | I56: 6 | J56: 6 | K56: 2 | L56: 2 | M56: -2 | O56: 9 | P56: 1 | Q56: 0.1075 | R56: 0.1613 | S56: -0.0476 | T56: 0 | U56: 0.1212 | V56: 0.1382 | W56: 0.2419 | X56: 0.102 | Y56: 0.0717 | Z56: -0.0833 | AA56: 0 | AB56: 0.3 | AC56: 0.0179 | AD56: 0.0927 | AE56: 0.0927 | AF56: A
A57: I01065 | B57: TECLADO GAMING SAKURA K613L PINK FANTECH | Q57: 0 | R57: 0 | S57: 0 | T57: 0 | U57: 0 | V57: 0 | W57: 0 | X57: 0 | Y57: 0 | Z57: 0 | AA57: 0 | AB57: 0 | AC57: 0 | AF57: D
A58: I01066 | B58: MOUSEPAD SAKURA MP35 PINK FANTECH | D58: 15 | E58: 11 | F58: 1 | G58: 2 | H58: 5 | Q58: 0.2688 | R58: 0.3548 | S58: 0.0476 | T58: 0.0909 | U58: 0 | V58: 0 | W58: 0 | X58: 0 | Y58: 0 | Z58: 0 | AA58: 0 | AB58: 0 | AC58: 0 | AD58: 0.2237 | AE58: 0.2237 | AF58: A
A59: I01067 | B59: PARLANTE 2,0 SAKURA USB GS202 PINK FANTECH | D59: 1 | Q59: 0 | R59: 0 | S59: 0 | T59: 0 | U59: 0 | V59: 0 | W59: 0 | X59: 0 | Y59: 0 | Z59: 0 | AA59: 0 | AB59: 0 | AC59: 0 | AF59: D
A60: I01076 | B60: MOUSE GAMING VX7 SPACE EDITION FANTECH | D60: 19 | E60: 10 | F60: 3 | G60: 11 | H60: 7 | I60: 3 | J60: 4 | K60: 6 | L60: 5 | M60: 11 | N60: 8 | O60: 4 | P60: 1 | Q60: 0.3405 | R60: 0.3226 | S60: 0.1429 | T60: 0.3548 | U60: 0.2121 | V60: 0.0691 | W60: 0.1613 | X60: 0.3061 | Y60: 0.1792 | Z60: 0.4583 | AA60: 0.2581 | AB60: 0.1333 | AC60: 0.0179 | AD60: 0.2449 | AE60: 0.2449 | AF60: A
A61: I01077 | B61: -NO FACTURAR -MOUSE VX 7 FANTECH SAK | Q61: 0 | R61: 0 | S61: 0 | T61: 0 | U61: 0 | V61: 0 | W61: 0 | X61: 0 | Y61: 0 | Z61: 0 | AA61: 0 | AB61: 0 | AC61: 0 | AF61: A
A62: I01078 | B62: MOUSE GAMING X17 SPACE EDITION FANTECH | D62: 3 | E62: 1 | F62: 2 | G62: 1 | J62: 1 | Q62: 0.0538 | R62: 0.0385 | S62: 0 | T62: 0 | U62: 0 | V62: 0 | W62: 0 | X62: 0 | Y62: 0 | Z62: 0 | AA62: 0 | AB62: 0 | AC62: 0 | AD62: 0.0538 | AE62: 0.0538 | AF62: A
A63: I01079 | B63: TECLADO MECÁNICO MK852 BROWN FANTECH SPACE EDITION | D63: -1 | Q63: 0 | R63: 0 | S63: 0 | T63: 0 | U63: 0 | V63: 0 | W63: 0 | X63: 0 | Y63: 0 | Z63: 0 | AA63: 0 | AB63: 0 | AC63: 0 | AF63: A
A64: I01080 | B64: LIBRE PARA USAR | Q64: 0 | R64: 0 | S64: 0 | T64: 0 | U64: 0 | V64: 0 | W64: 0 | X64: 0 | Y64: 0 | Z64: 0 | AA64: 0 | AB64: 0 | AC64: 0 | AF64: A
...

Sheet Compras
A1: Fecha Proxima Importacion | B1: 46331 | D1: Dias Pedido | E1: 100 | G1: Dias Duracion | H1: 60 | J1: Relacion Venta Marcas | K1: 1 | L1: 1 | M1: 1
E3: I M P O R T A C I O N - 598 | N3: I M P O R T A C I O N - 600 | W3: S T O C K A L 05/11/2026 | AF3: S T O C K A L 04/01/2027
A4: Codigos Barras | B4: Descripcion | C4: Articulo.1 | D4: Stock Act.1 | E4: Arribo | F4: Dias Arribo. | G4: Quiebre Stk.1 | H4: % Proteccion.1 | I4: Pedidos.1 | J4: Stk.Arribo.1 | K4: FOB Arribo.1 | L4: UnidxEnv | M4: Volumen | N4: Arribo | O4: Dias Arribo. | P4: Quiebre Stk.1 | Q4: % Proteccion.1 | R4: Pedidos.1 | S4: Stk.Arribo.1 | T4: FOB Arribo.1 | U4: UnidxEnv | V4: Volumen | W4: Arribo Prox. | X4: Dias Arribo | Y4: Quiebre Stk.1 | Z4: % Proteccion.1 | AA4: Pedir Artic.1 | AB4: Confirmado Art.1 | AC4: Stk.Acumulado.1 | AD4: FOB U$S Art.1 | AE4: Prov. Cpa. Art.1 | AF4: Stk.Final.1 | AG4: % Proteccion.1 | AH4: Estado Art.1
B5: GORRA FANTECH | C5: HX033 | D5: 81 | E5: 46230 | F5: 5 | G5: =(D5-(0)+0-(F5*Ventas!AE4*0.0000)) | I5: 6 | J5: =IF(G5>0,G5+I5,I5) | N5: 46275 | O5: 45 | P5: =(IF(G5>0,G5+I5,I5)-(O5*Ventas!AE4*1.0000)) | R5: 0 | S5: =IF(P5>0,P5+R5,R5) | W5: 46331 | X5: 56 | Y5: =(IF(P5>0,P5+R5,R5)-(X5*Ventas!AE4*1.0000)) | AA5: =(100*(Ventas!AE4*1.0000) - IF(Y5>0,Y5,0)) | AB5: =IF(AA5>0,AA5,0) | AC5: =IF(Y5>0,Y5+IF(AB5>0,AB5,0),AB5) | AE5: 3027 | AH5: A
B6: REMERA FANTECH M | C6: HX055 | D6: 14 | E6: 46230 | F6: 5 | G6: =(D6-(0)+0-(F6*Ventas!AE18*0.0000)) | I6: 0 | J6: =IF(G6>0,G6+I6,I6) | N6: 46275 | O6: 45 | P6: =(IF(G6>0,G6+I6,I6)-(O6*Ventas!AE18*1.0000)) | R6: 0 | S6: =IF(P6>0,P6+R6,R6) | W6: 46331 | X6: 56 | Y6: =(IF(P6>0,P6+R6,R6)-(X6*Ventas!AE18*1.0000)) | AA6: =(100*(Ventas!AE18*1.0000) - IF(Y6>0,Y6,0)) | AB6: =IF(AA6>0,AA6,0) | AC6: =IF(Y6>0,Y6+IF(AB6>0,AB6,0),AB6) | AE6: 3027 | AH6: A
B7: VASO FANTECH BLANCO | C7: HX056 | E7: 46230 | F7: 5 | G7: =(D7-(0)+0-(F7*Ventas!AE19*0.0000)) | I7: 0 | J7: =IF(G7>0,G7+I7,I7) | N7: 46275 | O7: 45 | P7: =(IF(G7>0,G7+I7,I7)-(O7*Ventas!AE19*1.0000)) | R7: 0 | S7: =IF(P7>0,P7+R7,R7) | W7: 46331 | X7: 56 | Y7: =(IF(P7>0,P7+R7,R7)-(X7*Ventas!AE19*1.0000)) | AA7: =(100*(Ventas!AE19*1.0000) - IF(Y7>0,Y7,0)) | AB7: =IF(AA7>0,AA7,0) | AC7: =IF(Y7>0,Y7+IF(AB7>0,AB7,0),AB7) | AH7: A
B8: REMERA FANTECH M RED | C8: HX057 | D8: 8 | E8: 46230 | F8: 5 | G8: =(D8-(0)+0-(F8*Ventas!AE20*0.0000)) | I8: 15 | J8: =IF(G8>0,G8+I8,I8) | N8: 46275 | O8: 45 | P8: =(IF(G8>0,G8+I8,I8)-(O8*Ventas!AE20*1.0000)) | R8: 0 | S8: =IF(P8>0,P8+R8,R8) | W8: 46331 | X8: 56 | Y8: =(IF(P8>0,P8+R8,R8)-(X8*Ventas!AE20*1.0000)) | AA8: =(100*(Ventas!AE20*1.0000) - IF(Y8>0,Y8,0)) | AB8: =IF(AA8>0,AA8,0) | AC8: =IF(Y8>0,Y8+IF(AB8>0,AB8,0),AB8) | AE8: 3027 | AH8: A
B9: REMERA FANTECH L RED | C9: HX058 | D9: 19 | E9: 46230 | F9: 5 | G9: =(D9-(0)+0-(F9*Ventas!AE21*0.0000)) | I9: 0 | J9: =IF(G9>0,G9+I9,I9) | N9: 46275 | O9: 45 | P9: =(IF(G9>0,G9+I9,I9)-(O9*Ventas!AE21*1.0000)) | R9: 0 | S9: =IF(P9>0,P9+R9,R9) | W9: 46331 | X9: 56 | Y9: =(IF(P9>0,P9+R9,R9)-(X9*Ventas!AE21*1.0000)) | AA9: =(100*(Ventas!AE21*1.0000) - IF(Y9>0,Y9,0)) | AB9: =IF(AA9>0,AA9,0) | AC9: =IF(Y9>0,Y9+IF(AB9>0,AB9,0),AB9) | AH9: A
B10: REMERA FANTECH XL RED | C10: HX059 | D10: 16 | E10: 46230 | F10: 5 | G10: =(D10-(0)+0-(F10*Ventas!AE22*0.0000)) | I10: 10 | J10: =IF(G10>0,G10+I10,I10) | N10: 46275 | O10: 45 | P10: =(IF(G10>0,G10+I10,I10)-(O10*Ventas!AE22*1.0000)) | R10: 0 | S10: =IF(P10>0,P10+R10,R10) | W10: 46331 | X10: 56 | Y10: =(IF(P10>0,P10+R10,R10)-(X10*Ventas!AE22*1.0000)) | AA10: =(100*(Ventas!AE22*1.0000) - IF(Y10>0,Y10,0)) | AB10: =IF(AA10>0,AA10,0) | AC10: =IF(Y10>0,Y10+IF(AB10>0,AB10,0),AB10) | AE10: 3027 | AH10: A
B11: REMERA FANTECH XXL RED | C11: HX060 | D11: 13 | E11: 46230 | F11: 5 | G11: =(D11-(0)+0-(F11*Ventas!AE23*0.0000)) | I11: 10 | J11: =IF(G11>0,G11+I11,I11) | N11: 46275 | O11: 45 | P11: =(IF(G11>0,G11+I11,I11)-(O11*Ventas!AE23*1.0000)) | R11: 0 | S11: =IF(P11>0,P11+R11,R11) | W11: 46331 | X11: 56 | Y11: =(IF(P11>0,P11+R11,R11)-(X11*Ventas!AE23*1.0000)) | AA11: =(100*(Ventas!AE23*1.0000) - IF(Y11>0,Y11,0)) | AB11: =IF(AA11>0,AA11,0) | AC11: =IF(Y11>0,Y11+IF(AB11>0,AB11,0),AB11) | AE11: 3027 | AH11: A
B12: REMERA FANTECH XXXL RED | C12: HX061 | D12: 10 | E12: 46230 | F12: 5 | G12: =(D12-(0)+0-(F12*Ventas!AE24*0.0000)) | I12: 0 | J12: =IF(G12>0,G12+I12,I12) | N12: 46275 | O12: 45 | P12: =(IF(G12>0,G12+I12,I12)-(O12*Ventas!AE24*1.0000)) | R12: 0 | S12: =IF(P12>0,P12+R12,R12) | W12: 46331 | X12: 56 | Y12: =(IF(P12>0,P12+R12,R12)-(X12*Ventas!AE24*1.0000)) | AA12: =(100*(Ventas!AE24*1.0000) - IF(Y12>0,Y12,0)) | AB12: =IF(AA12>0,AA12,0) | AC12: =IF(Y12>0,Y12+IF(AB12>0,AB12,0),AB12) | AE12: 3027 | AH12: A
B13: REMERA FANTECH XXXXL RED | C13: HX062 | D13: 17 | E13: 46230 | F13: 5 | G13: =(D13-(0)+0-(F13*Ventas!AE25*0.0000)) | I13: 0 | J13: =IF(G13>0,G13+I13,I13) | N13: 46275 | O13: 45 | P13: =(IF(G13>0,G13+I13,I13)-(O13*Ventas!AE25*1.0000)) | R13: 0 | S13: =IF(P13>0,P13+R13,R13) | W13: 46331 | X13: 56 | Y13: =(IF(P13>0,P13+R13,R13)-(X13*Ventas!AE25*1.0000)) | AA13: =(100*(Ventas!AE25*1.0000) - IF(Y13>0,Y13,0)) | AB13: =IF(AA13>0,AA13,0) | AC13: =IF(Y13>0,Y13+IF(AB13>0,AB13,0),AB13) | AH13: A
B14: CAMPERA DE NYLON FANTECH XL | C14: HX063 | E14: 46230 | F14: 5 | G14: =(D14-(0)+0-(F14*Ventas!AE26*0.0000)) | I14: 0 | J14: =IF(G14>0,G14+I14,I14) | N14: 46275 | O14: 45 | P14: =(IF(G14>0,G14+I14,I14)-(O14*Ventas!AE26*1.0000)) | R14: 5 | S14: =IF(P14>0,P14+R14,R14) | W14: 46331 | X14: 56 | Y14: =(IF(P14>0,P14+R14,R14)-(X14*Ventas!AE26*1.0000)) | AA14: =(100*(Ventas!AE26*1.0000) - IF(Y14>0,Y14,0)) | AB14: =IF(AA14>0,AA14,0) | AC14: =IF(Y14>0,Y14+IF(AB14>0,AB14,0),AB14) | AH14: A
B15: REMERA FANTECH XXXL | C15: HX064 | E15: 46230 | F15: 5 | G15: =(D15-(0)+0-(F15*Ventas!AE27*0.0000)) | I15: 0 | J15: =IF(G15>0,G15+I15,I15) | N15: 46275 | O15: 45 | P15: =(IF(G15>0,G15+I15,I15)-(O15*Ventas!AE27*1.0000)) | R15: 0 | S15: =IF(P15>0,P15+R15,R15) | W15: 46331 | X15: 56 | Y15: =(IF(P15>0,P15+R15,R15)-(X15*Ventas!AE27*1.0000)) | AA15: =(100*(Ventas!AE27*1.0000) - IF(Y15>0,Y15,0)) | AB15: =IF(AA15>0,AA15,0) | AC15: =IF(Y15>0,Y15+IF(AB15>0,AB15,0),AB15) | AH15: A
B16: REMERA FANTECH XL | C16: HX065 | E16: 46230 | F16: 5 | G16: =(D16-(0)+0-(F16*Ventas!AE28*0.0000)) | I16: 0 | J16: =IF(G16>0,G16+I16,I16) | N16: 46275 | O16: 45 | P16: =(IF(G16>0,G16+I16,I16)-(O16*Ventas!AE28*1.0000)) | R16: 0 | S16: =IF(P16>0,P16+R16,R16) | W16: 46331 | X16: 56 | Y16: =(IF(P16>0,P16+R16,R16)-(X16*Ventas!AE28*1.0000)) | AA16: =(100*(Ventas!AE28*1.0000) - IF(Y16>0,Y16,0)) | AB16: =IF(AA16>0,AA16,0) | AC16: =IF(Y16>0,Y16+IF(AB16>0,AB16,0),AB16) | AH16: A
B17: REMERA FANTECH L | C17: HX066 | D17: 12 | E17: 46230 | F17: 5 | G17: =(D17-(0)+0-(F17*Ventas!AE29*0.0000)) | I17: 0 | J17: =IF(G17>0,G17+I17,I17) | N17: 46275 | O17: 45 | P17: =(IF(G17>0,G17+I17,I17)-(O17*Ventas!AE29*1.0000)) | R17: 0 | S17: =IF(P17>0,P17+R17,R17) | W17: 46331 | X17: 56 | Y17: =(IF(P17>0,P17+R17,R17)-(X17*Ventas!AE29*1.0000)) | AA17: =(100*(Ventas!AE29*1.0000) - IF(Y17>0,Y17,0)) | AB17: =IF(AA17>0,AA17,0) | AC17: =IF(Y17>0,Y17+IF(AB17>0,AB17,0),AB17) | AH17: A
B18: PARAGUAS NEGRA FANTECH | C18: HX070 | D18: 45 | E18: 46230 | F18: 5 | G18: =(D18-(0)+0-(F18*Ventas!AE31*0.0000)) | I18: 0 | J18: =IF(G18>0,G18+I18,I18) | N18: 46275 | O18: 45 | P18: =(IF(G18>0,G18+I18,I18)-(O18*Ventas!AE31*1.0000)) | R18: 0 | S18: =IF(P18>0,P18+R18,R18) | W18: 46331 | X18: 56 | Y18: =(IF(P18>0,P18+R18,R18)-(X18*Ventas!AE31*1.0000)) | AA18: =(100*(Ventas!AE31*1.0000) - IF(Y18>0,Y18,0)) | AB18: =IF(AA18>0,AA18,0) | AC18: =IF(Y18>0,Y18+IF(AB18>0,AB18,0),AB18) | AE18: 3010 | AH18: A
B19: CAMPERA DE NYLON FANTECH M | C19: HX075 | E19: 46230 | F19: 5 | G19: =(D19-(0)+0-(F19*Ventas!AE35*0.0000)) | I19: 0 | J19: =IF(G19>0,G19+I19,I19) | N19: 46275 | O19: 45 | P19: =(IF(G19>0,G19+I19,I19)-(O19*Ventas!AE35*1.0000)) | R19: 4 | S19: =IF(P19>0,P19+R19,R19) | W19: 46331 | X19: 56 | Y19: =(IF(P19>0,P19+R19,R19)-(X19*Ventas!AE35*1.0000)) | AA19: =(100*(Ventas!AE35*1.0000) - IF(Y19>0,Y19,0)) | AB19: =IF(AA19>0,AA19,0) | AC19: =IF(Y19>0,Y19+IF(AB19>0,AB19,0),AB19) | AH19: A
B20: LLAVERO FANTECH | C20: HX076 | E20: 46230 | F20: 5 | G20: =(D20-(0)+0-(F20*Ventas!AE2*0.0000)) | I20: 0 | J20: =IF(G20>0,G20+I20,I20) | N20: 46275 | O20: 45 | P20: =(IF(G20>0,G20+I20,I20)-(O20*Ventas!AE2*1.0000)) | R20: 0 | S20: =IF(P20>0,P20+R20,R20) | W20: 46331 | X20: 56 | Y20: =(IF(P20>0,P20+R20,R20)-(X20*Ventas!AE2*1.0000)) | AA20: =(100*(Ventas!AE2*1.0000) - IF(Y20>0,Y20,0)) | AB20: =IF(AA20>0,AA20,0) | AC20: =IF(Y20>0,Y20+IF(AB20>0,AB20,0),AB20) | AH20: A
B21: CINTA VELCRO ORGANIZ. DE CABLES FANTECH | C21: HX077 | E21: 46230 | F21: 5 | G21: =(D21-(0)+0-(F21*Ventas!AE3*0.0000)) | I21: 309 | J21: =IF(G21>0,G21+I21,I21) | N21: 46275 | O21: 45 | P21: =(IF(G21>0,G21+I21,I21)-(O21*Ventas!AE3*1.0000)) | R21: 0 | S21: =IF(P21>0,P21+R21,R21) | W21: 46331 | X21: 56 | Y21: =(IF(P21>0,P21+R21,R21)-(X21*Ventas!AE3*1.0000)) | AA21: =(100*(Ventas!AE3*1.0000) - IF(Y21>0,Y21,0)) | AB21: =IF(AA21>0,AA21,0) | AC21: =IF(Y21>0,Y21+IF(AB21>0,AB21,0),AB21) | AE21: 3027 | AH21: A
B22: MOUSEPAD SVEN MP25 FANTECH 25x21x2 | C22: I01135 | E22: 46230 | F22: 5 | G22: =(D22-(0)+0-(F22*Ventas!AE94*0.0000)) | H22: =(G22/(Ventas!AE94*0.0000)/0) | I22: 0 | J22: =IF(G22>0,G22+I22,I22) | L22: 112 | M22: 0.000641 | N22: 46275 | O22: 45 | P22: =(IF(G22>0,G22+I22,I22)-(O22*Ventas!AE94*1.0000)) | Q22: =(P22/(Ventas!AE94*1.0000)/0) | R22: 0 | S22: =IF(P22>0,P22+R22,R22) | U22: 112 | V22: 0.000641 | W22: 46331 | X22: 56 | Y22: =(IF(P22>0,P22+R22,R22)-(X22*Ventas!AE94*1.0000)) | Z22: =(Y22/(Ventas!AE94*1.0000)/0) | AA22: =(100*(Ventas!AE94*1.0000) - IF(Y22>0,Y22,0)) | AB22: =IF(AA22>0,AA22,0) | AC22: =IF(Y22>0,Y22+IF(AB22>0,AB22,0),AB22) | AD22: 0.8 | AE22: 3027 | AF22: =(AC22-(60*Ventas!AE94*1.0000)) | AG22: =(AF22/(Ventas!AE94*1.0000)/0) | AH22: A
B23: MOUSEPAD SVEN BLACK MP35 FANTECH 35x25x4 | C23: I01136 | D23: 38 | E23: 46230 | F23: 5 | G23: =(D23-(0)+0-(F23*Ventas!AE95*0.0000)) | H23: =(G23/(Ventas!AE95*0.0000)/0) | I23: 0 | J23: =IF(G23>0,G23+I23,I23) | L23: 60 | M23: 0.001249 | N23: 46275 | O23: 45 | P23: =(IF(G23>0,G23+I23,I23)-(O23*Ventas!AE95*1.0000)) | Q23: =(P23/(Ventas!AE95*1.0000)/0) | R23: 0 | S23: =IF(P23>0,P23+R23,R23) | U23: 60 | V23: 0.001249 | W23: 46331 | X23: 56 | Y23: =(IF(P23>0,P23+R23,R23)-(X23*Ventas!AE95*1.0000)) | Z23: =(Y23/(Ventas!AE95*1.0000)/0) | AA23: =(100*(Ventas!AE95*1.0000) - IF(Y23>0,Y23,0)) | AB23: =IF(AA23>0,AA23,0) | AC23: =IF(Y23>0,Y23+IF(AB23>0,AB23,0),AB23) | AD23: 1.9 | AE23: 3027 | AF23: =(AC23-(60*Ventas!AE95*1.0000)) | AG23: =(AF23/(Ventas!AE95*1.0000)/0) | AH23: A
B24: EXHIBIDOR FANTECH GRANDE | C24: I01250 | D24: 13 | E24: 46230 | F24: 5 | G24: =(D24-(0)+0-(F24*Ventas!AE128*1.3000)) | I24: 0 | J24: =IF(G24>0,G24+I24,I24) | N24: 46275 | O24: 45 | P24: =(IF(G24>0,G24+I24,I24)-(O24*Ventas!AE128*1.1889)) | R24: 0 | S24: =IF(P24>0,P24+R24,R24) | W24: 46331 | X24: 56 | Y24: =(IF(P24>0,P24+R24,R24)-(X24*Ventas!AE128*0.9464)) | AA24: =(100*(Ventas!AE128*1.3083) - IF(Y24>0,Y24,0)) | AB24: =IF(AA24>0,AA24,0) | AC24: =IF(Y24>0,Y24+IF(AB24>0,AB24,0),AB24) | AE24: 3027 | AH24: D
B25: TECLADO NUMERICO FTK-801 FANTECH - NEGRO | C25: I01134 | E25: 46230 | F25: 5 | G25: =(D25-(0)+0-(F25*Ventas!AE93*1.1900)) | I25: 0 | J25: =IF(G25>0,G25+I25,I25) | L25: 80 | M25: 0.000539 | N25: 46275 | O25: 45 | P25: =(IF(G25>0,G25+I25,I25)-(O25*Ventas!AE93*1.0169)) | R25: 0 | S25: =IF(P25>0,P25+R25,R25) | U25: 80 | V25: 0.000539 | W25: 46331 | X25: 56 | Y25: =(IF(P25>0,P25+R25,R25)-(X25*Ventas!AE93*0.9295)) | AA25: =(100*(Ventas!AE93*0.8733) - IF(Y25>0,Y25,0)) | AB25: =IF(AA25>0,AA25,0) | AC25: =IF(Y25>0,Y25+IF(AB25>0,AB25,0),AB25) | AD25: 2.2 | AE25: 3017 | AH25: A
B26: TECLADO Y MOUSE INAL. WK895 BK GOPOP FANTECH | C26: I01682 | E26: 46230 | F26: 5 | G26: =(D26-(0)+0-(F26*Ventas!AE157*1.1900)) | H26: =(G26/(Ventas!AE157*1.1900)/60) | I26: 0 | J26: =IF(G26>0,G26+I26,I26) | L26: 20 | M26: 0.00345 | N26: 46275 | O26: 45 | P26: =(IF(G26>0,G26+I26,I26)-(O26*Ventas!AE157*1.0169)) | Q26: =(P26/(Ventas!AE157*1.0169)/60) | R26: 20 | S26: =IF(P26>0,P26+R26,R26) | T26: 7.7 | U26: 20 | V26: 0.00345 | W26: 46331 | X26: 56 | Y26: =(IF(P26>0,P26+R26,R26)-(X26*Ventas!AE157*0.9295)) | Z26: =(Y26/(Ventas!AE157*0.9295)/60) | AA26: =(100*(Ventas!AE157*0.8733) - IF(Y26>0,Y26,0)) | AB26: =IF(AA26>0,AA26,0) | AC26: =IF(Y26>0,Y26+IF(AB26>0,AB26,0),AB26) | AD26: 7.7 | AE26: 3027 | AF26: =(AC26-(60*Ventas!AE157*0.8733)) | AG26: =(AF26/(Ventas!AE157*0.8733)/60) | AH26: A
B27: TECLADO Y MOUSE INAL. WK895 GREY GOPOP FANTECH | C27: I01683 | D27: 29 | E27: 46230 | F27: 5 | G27: =(D27-(0)+0-(F27*Ventas!AE158*1.1900)) | H27: =(G27/(Ventas!AE158*1.1900)/60) | I27: 0 | J27: =IF(G27>0,G27+I27,I27) | L27: 20 | M27: 0.00345 | N27: 46275 | O27: 45 | P27: =(IF(G27>0,G27+I27,I27)-(O27*Ventas!AE158*1.0169)) | Q27: =(P27/(Ventas!AE158*1.0169)/60) | R27: 0 | S27: =IF(P27>0,P27+R27,R27) | U27: 20 | V27: 0.00345 | W27: 46331 | X27: 56 | Y27: =(IF(P27>0,P27+R27,R27)-(X27*Ventas!AE158*0.9295)) | Z27: =(Y27/(Ventas!AE158*0.9295)/60) | AA27: =(100*(Ventas!AE158*0.8733) - IF(Y27>0,Y27,0)) | AB27: =IF(AA27>0,AA27,0) | AC27: =IF(Y27>0,Y27+IF(AB27>0,AB27,0),AB27) | AD27: 7.6 | AE27: 3010 | AF27: =(AC27-(60*Ventas!AE158*0.8733)) | AG27: =(AF27/(Ventas!AE158*0.8733)/60) | AH27: A
A28: 6977052252135 | B28: PARLANTE BT BS152 BK 5W NERABOX FANTECH | C28: I02455 | D28: 10 | E28: 46230 | F28: 5 | G28: =(D28-(0)+0-(F28*Ventas!AE272*1.1000)) | H28: =(G28/(Ventas!AE272*1.1000)/45) | I28: 50 | J28: =IF(G28>0,G28+I28,I28) | K28: 5.408 | L28: 50 | M28: 0.00058 | N28: 46275 | O28: 45 | P28: =(IF(G28>0,G28+I28,I28)-(O28*Ventas!AE272*0.9422)) | Q28: =(P28/(Ventas!AE272*0.9422)/45) | R28: 50 | S28: =IF(P28>0,P28+R28,R28) | T28: 5.4 | U28: 50 | V28: 0.00058 | W28: 46331 | X28: 56 | Y28: =(IF(P28>0,P28+R28,R28)-(X28*Ventas!AE272*0.8268)) | Z28: =(Y28/(Ventas!AE272*0.8268)/45) | AA28: =(100*(Ventas!AE272*1.9500) - IF(Y28>0,Y28,0)) | AB28: =IF(AA28>0,AA28,0) | AC28: =IF(Y28>0,Y28+IF(AB28>0,AB28,0),AB28) | AD28: 5.408 | AE28: 3027 | AF28: =(AC28-(60*Ventas!AE272*1.9500)) | AG28: =(AF28/(Ventas!AE272*1.9500)/45) | AH28: A
A29: 6977052253507 | B29: PARLANTE BT BS152 WH 5W NERABOX FANTECH | C29: I02456 | D29: 8 | E29: 46230 | F29: 5 | G29: =(D29-(0)+0-(F29*Ventas!AE273*1.1000)) | H29: =(G29/(Ventas!AE273*1.1000)/45) | I29: 50 | J29: =IF(G29>0,G29+I29,I29) | K29: 5.408 | L29: 50 | M29: 0.00058 | N29: 46275 | O29: 45 | P29: =(IF(G29>0,G29+I29,I29)-(O29*Ventas!AE273*0.9422)) | Q29: =(P29/(Ventas!AE273*0.9422)/45) | R29: 50 | S29: =IF(P29>0,P29+R29,R29) | T29: 5.4 | U29: 50 | V29: 0.00058 | W29: 46331 | X29: 56 | Y29: =(IF(P29>0,P29+R29,R29)-(X29*Ventas!AE273*0.8268)) | Z29: =(Y29/(Ventas!AE273*0.8268)/45) | AA29: =(100*(Ventas!AE273*1.9500) - IF(Y29>0,Y29,0)) | AB29: =IF(AA29>0,AA29,0) | AC29: =IF(Y29>0,Y29+IF(AB29>0,AB29,0),AB29) | AD29: 5.408 | AE29: 3027 | AF29: =(AC29-(60*Ventas!AE273*1.9500)) | AG29: =(AF29/(Ventas!AE273*1.9500)/45) | AH29: A
A30: 6977052253514 | B30: PARLANTE BT BS152 PINK 5W NERABOX FANTECH | C30: I02457 | D30: 21 | E30: 46230 | F30: 5 | G30: =(D30-(0)+0-(F30*Ventas!AE274*1.1000)) | H30: =(G30/(Ventas!AE274*1.1000)/45) | I30: 50 | J30: =IF(G30>0,G30+I30,I30) | K30: 5.408 | L30: 50 | M30: 0.00058 | N30: 46275 | O30: 45 | P30: =(IF(G30>0,G30+I30,I30)-(O30*Ventas!AE274*0.9422)) | Q30: =(P30/(Ventas!AE274*0.9422)/45) | R30: 50 | S30: =IF(P30>0,P30+R30,R30) | T30: 5.4 | U30: 50 | V30: 0.00058 | W30: 46331 | X30: 56 | Y30: =(IF(P30>0,P30+R30,R30)-(X30*Ventas!AE274*0.8268)) | Z30: =(Y30/(Ventas!AE274*0.8268)/45) | AA30: =(100*(Ventas!AE274*1.9500) - IF(Y30>0,Y30,0)) | AB30: =IF(AA30>0,AA30,0) | AC30: =IF(Y30>0,Y30+IF(AB30>0,AB30,0),AB30) | AD30: 5.408 | AE30: 3027 | AF30: =(AC30-(60*Ventas!AE274*1.9500)) | AG30: =(AF30/(Ventas!AE274*1.9500)/45) | AH30: A
A31: 6977052253521 | B31: PARLANTE BT BS152 PURP 5W NERABOX FANTECH | C31: I02458 | D31: 11 | E31: 46230 | F31: 5 | G31: =(D31-(0)+0-(F31*Ventas!AE275*1.1000)) | H31: =(G31/(Ventas!AE275*1.1000)/45) | I31: 50 | J31: =IF(G31>0,G31+I31,I31) | K31: 5.408 | L31: 50 | M31: 0.00058 | N31: 46275 | O31: 45 | P31: =(IF(G31>0,G31+I31,I31)-(O31*Ventas!AE275*0.9422)) | Q31: =(P31/(Ventas!AE275*0.9422)/45) | R31: 50 | S31: =IF(P31>0,P31+R31,R31) | T31: 5.4 | U31: 50 | V31: 0.00058 | W31: 46331 | X31: 56 | Y31: =(IF(P31>0,P31+R31,R31)-(X31*Ventas!AE275*0.8268)) | Z31: =(Y31/(Ventas!AE275*0.8268)/45) | AA31: =(100*(Ventas!AE275*1.9500) - IF(Y31>0,Y31,0)) | AB31: =IF(AA31>0,AA31,0) | AC31: =IF(Y31>0,Y31+IF(AB31>0,AB31,0),AB31) | AD31: 5.408 | AE31: 3027 | AF31: =(AC31-(60*Ventas!AE275*1.9500)) | AG31: =(AF31/(Ventas!AE275*1.9500)/45) | AH31: A
A32: 6977052253316 | B32: PARLANTE BT BS153 BK 5W NERABOX FANTECH | C32: I02459 | D32: 30 | E32: 46230 | F32: 5 | G32: =(D32-(0)+0-(F32*Ventas!AE276*1.1000)) | H32: =(G32/(Ventas!AE276*1.1000)/45) | I32: 50 | J32: =IF(G32>0,G32+I32,I32) | K32: 3.536 | L32: 50 | M32: 0.00048 | N32: 46275 | O32: 45 | P32: =(IF(G32>0,G32+I32,I32)-(O32*Ventas!AE276*0.9422)) | Q32: =(P32/(Ventas!AE276*0.9422)/45) | R32: 50 | S32: =IF(P32>0,P32+R32,R32) | T32: 3.5 | U32: 50 | V32: 0.00048 | W32: 46331 | X32: 56 | Y32: =(IF(P32>0,P32+R32,R32)-(X32*Ventas!AE276*0.8268)) | Z32: =(Y32/(Ventas!AE276*0.8268)/45) | AA32: =(100*(Ventas!AE276*1.9500) - IF(Y32>0,Y32,0)) | AB32: =IF(AA32>0,AA32,0) | AC32: =IF(Y32>0,Y32+IF(AB32>0,AB32,0),AB32) | AD32: 3.536 | AE32: 3027 | AF32: =(AC32-(60*Ventas!AE276*1.9500)) | AG32: =(AF32/(Ventas!AE276*1.9500)/45) | AH32: A
A33: 6977052253323 | B33: PARLANTE BT BS153 GREY 5W NERABOX FANTECH | C33: I02460 | D33: 22 | E33: 46230 | F33: 5 | G33: =(D33-(0)+0-(F33*Ventas!AE277*1.1000)) | H33: =(G33/(Ventas!AE277*1.1000)/45) | I33: 50 | J33: =IF(G33>0,G33+I33,I33) | K33: 3.536 | L33: 50 | M33: 0.00048 | N33: 46275 | O33: 45 | P33: =(IF(G33>0,G33+I33,I33)-(O33*Ventas!AE277*0.9422)) | Q33: =(P33/(Ventas!AE277*0.9422)/45) | R33: 50 | S33: =IF(P33>0,P33+R33,R33) | T33: 3.5 | U33: 50 | V33: 0.00048 | W33: 46331 | X33: 56 | Y33: =(IF(P33>0,P33+R33,R33)-(X33*Ventas!AE277*0.8268)) | Z33: =(Y33/(Ventas!AE277*0.8268)/45) | AA33: =(100*(Ventas!AE277*1.9500) - IF(Y33>0,Y33,0)) | AB33: =IF(AA33>0,AA33,0) | AC33: =IF(Y33>0,Y33+IF(AB33>0,AB33,0),AB33) | AD33: 3.536 | AE33: 3027 | AF33: =(AC33-(60*Ventas!AE277*1.9500)) | AG33: =(AF33/(Ventas!AE277*1.9500)/45) | AH33: A
A34: 6977052253330 | B34: PARLANTE BT BS154 BK 5W RGB NERABOX FANTECH | C34: I02461 | D34: 77 | E34: 46230 | F34: 5 | G34: =(D34-(0)+0-(F34*Ventas!AE278*1.1000)) | H34: =(G34/(Ventas!AE278*1.1000)/45) | I34: 40 | J34: =IF(G34>0,G34+I34,I34) | K34: 4.056 | L34: 40 | M34: 0.001625 | N34: 46275 | O34: 45 | P34: =(IF(G34>0,G34+I34,I34)-(O34*Ventas!AE278*0.9422)) | Q34: =(P34/(Ventas!AE278*0.9422)/45) | R34: 0 | S34: =IF(P34>0,P34+R34,R34) | U34: 40 | V34: 0.001625 | W34: 46331 | X34: 56 | Y34: =(IF(P34>0,P34+R34,R34)-(X34*Ventas!AE278*0.8268)) | Z34: =(Y34/(Ventas!AE278*0.8268)/45) | AA34: =(100*(Ventas!AE278*1.9500) - IF(Y34>0,Y34,0)) | AB34: =IF(AA34>0,AA34,0) | AC34: =IF(Y34>0,Y34+IF(AB34>0,AB34,0),AB34) | AD34: 4.056 | AE34: 3027 | AF34: =(AC34-(60*Ventas!AE278*1.9500)) | AG34: =(AF34/(Ventas!AE278*1.9500)/45) | AH34: A
A35: 6977052253347 | B35: PARLANTE BT BS154 GREY 5W RGB NERABOX FANTECH | C35: I02462 | D35: 46 | E35: 46230 | F35: 5 | G35: =(D35-(0)+0-(F35*Ventas!AE279*1.1000)) | H35: =(G35/(Ventas!AE279*1.1000)/45) | I35: 40 | J35: =IF(G35>0,G35+I35,I35) | K35: 4.056 | L35: 40 | M35: 0.001625 | N35: 46275 | O35: 45 | P35: =(IF(G35>0,G35+I35,I35)-(O35*Ventas!AE279*0.9422)) | Q35: =(P35/(Ventas!AE279*0.9422)/45) | R35: 40 | S35: =IF(P35>0,P35+R35,R35) | T35: 4.1 | U35: 40 | V35: 0.001625 | W35: 46331 | X35: 56 | Y35: =(IF(P35>0,P35+R35,R35)-(X35*Ventas!AE279*0.8268)) | Z35: =(Y35/(Ventas!AE279*0.8268)/45) | AA35: =(100*(Ventas!AE279*1.9500) - IF(Y35>0,Y35,0)) | AB35: =IF(AA35>0,AA35,0) | AC35: =IF(Y35>0,Y35+IF(AB35>0,AB35,0),AB35) | AD35: 4.056 | AE35: 3027 | AF35: =(AC35-(60*Ventas!AE279*1.9500)) | AG35: =(AF35/(Ventas!AE279*1.9500)/45) | AH35: A
A36: 6977052253361 | B36: PARLANTE BT BS157 BK 5W RGB NERABOX FANTECH | C36: I02463 | D36: 51 | E36: 46230 | F36: 5 | G36: =(D36-(0)+0-(F36*Ventas!AE280*1.1000)) | H36: =(G36/(Ventas!AE280*1.1000)/45) | I36: 0 | J36: =IF(G36>0,G36+I36,I36) | L36: 30 | M36: 0.001833 | N36: 46275 | O36: 45 | P36: =(IF(G36>0,G36+I36,I36)-(O36*Ventas!AE280*0.9422)) | Q36: =(P36/(Ventas!AE280*0.9422)/45) | R36: 0 | S36: =IF(P36>0,P36+R36,R36) | U36: 30 | V36: 0.001833 | W36: 46331 | X36: 56 | Y36: =(IF(P36>0,P36+R36,R36)-(X36*Ventas!AE280*0.8268)) | Z36: =(Y36/(Ventas!AE280*0.8268)/45) | AA36: =(100*(Ventas!AE280*1.9500) - IF(Y36>0,Y36,0)) | AB36: =IF(AA36>0,AA36,0) | AC36: =IF(Y36>0,Y36+IF(AB36>0,AB36,0),AB36) | AD36: 6.2852 | AE36: 3010 | AF36: =(AC36-(60*Ventas!AE280*1.9500)) | AG36: =(AF36/(Ventas!AE280*1.9500)/45) | AH36: A
A37: 6977052253378 | B37: PARLANTE BT BS157 GREY 5W RGB NERABOX FANTECH | C37: I02464 | D37: 52 | E37: 46230 | F37: 5 | G37: =(D37-(0)+0-(F37*Ventas!AE281*1.1000)) | H37: =(G37/(Ventas!AE281*1.1000)/45) | I37: 0 | J37: =IF(G37>0,G37+I37,I37) | L37: 30 | M37: 0.001833 | N37: 46275 | O37: 45 | P37: =(IF(G37>0,G37+I37,I37)-(O37*Ventas!AE281*0.9422)) | Q37: =(P37/(Ventas!AE281*0.9422)/45) | R37: 0 | S37: =IF(P37>0,P37+R37,R37) | U37: 30 | V37: 0.001833 | W37: 46331 | X37: 56 | Y37: =(IF(P37>0,P37+R37,R37)-(X37*Ventas!AE281*0.8268)) | Z37: =(Y37/(Ventas!AE281*0.8268)/45) | AA37: =(100*(Ventas!AE281*1.9500) - IF(Y37>0,Y37,0)) | AB37: =IF(AA37>0,AA37,0) | AC37: =IF(Y37>0,Y37+IF(AB37>0,AB37,0),AB37) | AD37: 6.2852 | AE37: 3010 | AF37: =(AC37-(60*Ventas!AE281*1.9500)) | AG37: =(AF37/(Ventas!AE281*1.9500)/45) | AH37: A
A38: 6977052253569 | B38: PARLANTE BT BS152 LUFFY ONE PIECE 5W FANTECH | C38: I02570 | D38: 92 | E38: 46230 | F38: 5 | G38: =(D38-(0)+0-(F38*Ventas!AE321*1.1000)) | H38: =(G38/(Ventas!AE321*1.1000)/45) | I38: 0 | J38: =IF(G38>0,G38+I38,I38) | L38: 50 | M38: 0.00058 | N38: 46275 | O38: 45 | P38: =(IF(G38>0,G38+I38,I38)-(O38*Ventas!AE321*0.9422)) | Q38: =(P38/(Ventas!AE321*0.9422)/45) | R38: 0 | S38: =IF(P38>0,P38+R38,R38) | U38: 50 | V38: 0.00058 | W38: 46331 | X38: 56 | Y38: =(IF(P38>0,P38+R38,R38)-(X38*Ventas!AE321*0.8268)) | Z38: =(Y38/(Ventas!AE321*0.8268)/45) | AA38: =(100*(Ventas!AE321*1.9500) - IF(Y38>0,Y38,0)) | AB38: =IF(AA38>0,AA38,0) | AC38: =IF(Y38>0,Y38+IF(AB38>0,AB38,0),AB38) | AD38: 5.9 | AE38: 3027 | AF38: =(AC38-(60*Ventas!AE321*1.9500)) | AG38: =(AF38/(Ventas!AE321*1.9500)/45) | AH38: A
A39: 6977052253583 | B39: PARLANTE BT BS152 ZORO ONE PIECE 5W FANTECH | C39: I02571 | D39: 42 | E39: 46230 | F39: 5 | G39: =(D39-(0)+0-(F39*Ventas!AE322*1.1000)) | H39: =(G39/(Ventas!AE322*1.1000)/45) | I39: 50 | J39: =IF(G39>0,G39+I39,I39) | K39: 5.9 | L39: 50 | M39: 0.00058 | N39: 46275 | O39: 45 | P39: =(IF(G39>0,G39+I39,I39)-(O39*Ventas!AE322*0.9422)) | Q39: =(P39/(Ventas!AE322*0.9422)/45) | R39: 0 | S39: =IF(P39>0,P39+R39,R39) | U39: 50 | V39: 0.00058 | W39: 46331 | X39: 56 | Y39: =(IF(P39>0,P39+R39,R39)-(X39*Ventas!AE322*0.8268)) | Z39: =(Y39/(Ventas!AE322*0.8268)/45) | AA39: =(100*(Ventas!AE322*1.9500) - IF(Y39>0,Y39,0)) | AB39: =IF(AA39>0,AA39,0) | AC39: =IF(Y39>0,Y39+IF(AB39>0,AB39,0),AB39) | AD39: 5.9 | AE39: 3027 | AF39: =(AC39-(60*Ventas!AE322*1.9500)) | AG39: =(AF39/(Ventas!AE322*1.9500)/45) | AH39: A
A40: 6977052253590 | B40: PARLANTE BT BS152 GEAR5 ONE PIECE 5W FANTECH | C40: I02572 | D40: 42 | E40: 46230 | F40: 5 | G40: =(D40-(0)+0-(F40*Ventas!AE323*1.1000)) | H40: =(G40/(Ventas!AE323*1.1000)/45) | I40: 50 | J40: =IF(G40>0,G40+I40,I40) | K40: 5.9 | L40: 50 | M40: 0.00058 | N40: 46275 | O40: 45 | P40: =(IF(G40>0,G40+I40,I40)-(O40*Ventas!AE323*0.9422)) | Q40: =(P40/(Ventas!AE323*0.9422)/45) | R40: 0 | S40: =IF(P40>0,P40+R40,R40) | U40: 50 | V40: 0.00058 | W40: 46331 | X40: 56 | Y40: =(IF(P40>0,P40+R40,R40)-(X40*Ventas!AE323*0.8268)) | Z40: =(Y40/(Ventas!AE323*0.8268)/45) | AA40: =(100*(Ventas!AE323*1.9500) - IF(Y40>0,Y40,0)) | AB40: =IF(AA40>0,AA40,0) | AC40: =IF(Y40>0,Y40+IF(AB40>0,AB40,0),AB40) | AD40: 5.9 | AE40: 3027 | AF40: =(AC40-(60*Ventas!AE323*1.9500)) | AG40: =(AF40/(Ventas!AE323*1.9500)/45) | AH40: A
A41: 6977052253576 | B41: PARLANTE BT BS152 NAMI ONE PIECE 5W FANTECH | C41: I02573 | D41: 45 | E41: 46230 | F41: 5 | G41: =(D41-(0)+0-(F41*Ventas!AE324*1.1000)) | H41: =(G41/(Ventas!AE324*1.1000)/45) | I41: 0 | J41: =IF(G41>0,G41+I41,I41) | L41: 50 | M41: 0.00058 | N41: 46275 | O41: 45 | P41: =(IF(G41>0,G41+I41,I41)-(O41*Ventas!AE324*0.9422)) | Q41: =(P41/(Ventas!AE324*0.9422)/45) | R41: 0 | S41: =IF(P41>0,P41+R41,R41) | U41: 50 | V41: 0.00058 | W41: 46331 | X41: 56 | Y41: =(IF(P41>0,P41+R41,R41)-(X41*Ventas!AE324*0.8268)) | Z41: =(Y41/(Ventas!AE324*0.8268)/45) | AA41: =(100*(Ventas!AE324*1.9500) - IF(Y41>0,Y41,0)) | AB41: =IF(AA41>0,AA41,0) | AC41: =IF(Y41>0,Y41+IF(AB41>0,AB41,0),AB41) | AD41: 5.9 | AE41: 3027 | AF41: =(AC41-(60*Ventas!AE324*1.9500)) | AG41: =(AF41/(Ventas!AE324*1.9500)/45) | AH41: A
...
