Workbook

Sheet Ventas
A1: Articulo | B1: Descripcion | C1: Codigos Barras | D1: Vta.Ago/25 | E1: Vta.Sep/25 | F1: Vta.Oct/25 | G1: Vta.Nov/25 | H1: Vta.Dic/25 | I1: Vta.Ene/26 | J1: Vta.Feb/26 | K1: Vta.Mar/26 | L1: Vta.Abr/26 | M1: Vta.May/26 | N1: Vta.Jun/26 | O1: Vta.Jul/26 | P1: Vta.Ago/26 | Q1: Ago/25 | R1: Sep/25 | S1: Oct/25 | T1: Nov/25 | U1: Dic/25 | V1: Ene/26 | W1: Feb/26 | X1: Mar/26 | Y1: Abr/26 | Z1: May/26 | AA1: Jun/26 | AB1: Jul/26 | AC1: Ago/26 | AD1: Rotacion DesEstac. | AE1: Rot. Manual | AF1: Estado Art.
A2: I01231 | B2: PARLANTE BLUETOOTH BL14 BK 6W FONENG | Q2: 0 | R2: 0 | S2: 0 | T2: 0 | U2: 0 | V2: 0 | W2: 0 | X2: 0 | Y2: 0 | Z2: 0 | AA2: 0 | AB2: 0 | AC2: 0 | AF2: D
A3: I01232 | B3: PARLANTE BARRA BL12 BT 10W FONENG | F3: 6 | G3: 1 | J3: 2 | K3: 2 | L3: 2 | M3: 2 | N3: 3 | O3: 4 | Q3: 0 | R3: 0 | S3: 0.2727 | T3: 0 | U3: 0 | V3: 0 | W3: 0.119 | X3: 0.0645 | Y3: 0.0784 | Z3: 0.0645 | AA3: 0.1053 | AB3: 0.1173 | AC3: 0 | AD3: 0.061 | AE3: 0.061 | AF3: A
A4: I01235 | B4: PARLANTE BLUETOOTH FONENG BL10 LONG STANDBY RED | Q4: 0 | R4: 0 | S4: 0 | T4: 0 | U4: 0 | V4: 0 | W4: 0 | X4: 0 | Y4: 0 | Z4: 0 | AA4: 0 | AB4: 0 | AC4: 0 | AF4: A
A5: I01397 | B5: PARLANTE BT BL15 8W FULL RGB FONENG | J5: 3 | N5: 1 | Q5: 0 | R5: 0 | S5: 0 | T5: 0 | U5: 0 | V5: 0 | W5: 0.1786 | X5: 0 | Y5: 0 | Z5: 0 | AA5: 0.0351 | AB5: 0 | AC5: 0 | AD5: 0.0178 | AE5: 0.0178 | AF5: A
A6: HX017 | B6: BOLSAS FONENG 388X282MM | Q6: 0 | R6: 0 | S6: 0 | T6: 0 | U6: 0 | V6: 0 | W6: 0 | X6: 0 | Y6: 0 | Z6: 0 | AA6: 0 | AB6: 0 | AC6: 0 | AF6: D
A7: HX018 | B7: EXHIBIDOR FONENG W1 1.8MX0.6M METAL | Q7: 0 | R7: 0 | S7: 0 | T7: 0 | U7: 0 | V7: 0 | W7: 0 | X7: 0 | Y7: 0 | Z7: 0 | AA7: 0 | AB7: 0 | AC7: 0 | AF7: A
A8: HX019 | B8: EXHIBIDOR FONENG W2 2.2MX1MX0.3M | Q8: 0 | R8: 0 | S8: 0 | T8: 0 | U8: 0 | V8: 0 | W8: 0 | X8: 0 | Y8: 0 | Z8: 0 | AA8: 0 | AB8: 0 | AC8: 0 | AF8: D
A9: HX020 | B9: EXHIBIDOR FONENG F1 2.25MX1MX0.3M | Q9: 0 | R9: 0 | S9: 0 | T9: 0 | U9: 0 | V9: 0 | W9: 0 | X9: 0 | Y9: 0 | Z9: 0 | AA9: 0 | AB9: 0 | AC9: 0 | AF9: D
A10: HX023 | B10: EXHIBIDOR FONENG W3 1.39MX0.6MX0.21M | Q10: 0 | R10: 0 | S10: 0 | T10: 0 | U10: 0 | V10: 0 | W10: 0 | X10: 0 | Y10: 0 | Z10: 0 | AA10: 0 | AB10: 0 | AC10: 0 | AF10: D
A11: HX025 | B11: EXHIBIDOR FONENG F1B 2.25MX0.6MX0.3M | Q11: 0 | R11: 0 | S11: 0 | T11: 0 | U11: 0 | V11: 0 | W11: 0 | X11: 0 | Y11: 0 | Z11: 0 | AA11: 0 | AB11: 0 | AC11: 0 | AF11: D
A12: I001397 | B12: NO USAR | Q12: 0 | R12: 0 | S12: 0 | T12: 0 | U12: 0 | V12: 0 | W12: 0 | X12: 0 | Y12: 0 | Z12: 0 | AA12: 0 | AB12: 0 | AC12: 0 | AF12: A
A13: I01216 | B13: AURICULARES T29 BLACK HEAVY BASS FONENG | Q13: 0 | R13: 0 | S13: 0 | T13: 0 | U13: 0 | V13: 0 | W13: 0 | X13: 0 | Y13: 0 | Z13: 0 | AA13: 0 | AB13: 0 | AC13: 0 | AF13: D
A14: I01217 | B14: AURICULARES T57 BK FONENG | Q14: 0 | R14: 0 | S14: 0 | T14: 0 | U14: 0 | V14: 0 | W14: 0 | X14: 0 | Y14: 0 | Z14: 0 | AA14: 0 | AB14: 0 | AC14: 0 | AF14: A
A15: I01218 | B15: AURICULARES T42 RED METAL FONENG | F15: 2 | K15: -1 | Q15: 0 | R15: 0 | S15: 0 | T15: 0 | U15: 0 | V15: 0 | W15: 0 | X15: 0 | Y15: 0 | Z15: 0 | AA15: 0 | AB15: 0 | AC15: 0 | AF15: D
A16: I01219 | B16: AURICULARES TIPO-C T15 FONENG | E16: 59 | F16: 55 | G16: 86 | H16: 42 | I16: 1 | J16: 1 | K16: 54 | L16: 66 | Q16: 0 | R16: 3.0102 | S16: 1.7742 | T16: 2.1078 | U16: 2.7451 | V16: 0 | W16: 0 | X16: 2.4545 | Y16: 3.022 | Z16: 0 | AA16: 0 | AB16: 0 | AC16: 0 | AD16: 1.941 | AE16: 1.941 | AF16: D
A17: I01220 | B17: AURICULARES iPHONE T28 BT FONENG | D17: 40 | E17: 45 | F17: 19 | G17: 36 | H17: 93 | I17: 32 | J17: 7 | K17: 38 | L17: 30 | M17: 36 | N17: 40 | O17: 54 | Q17: 1.2903 | R17: 2.1429 | S17: 0.6129 | T17: 0.8824 | U17: 1.7647 | V17: 1.7204 | W17: 0.4167 | X17: 1.2258 | Y17: 1.1905 | Z17: 1.1613 | AA17: 1.4815 | AB17: 1.34 | AC17: 0 | AD17: 1.2691 | AE17: 1.2691 | AF17: A
A18: I01233 | B18: AURICULAR DIADEMA BLUETOOTH FONENG BL50 BLACK | Q18: 0 | R18: 0 | S18: 0 | T18: 0 | U18: 0 | V18: 0 | W18: 0 | X18: 0 | Y18: 0 | Z18: 0 | AA18: 0 | AB18: 0 | AC18: 0 | AF18: A
A19: I01234 | B19: AURICULAR BLUETOOTH FONENG BL32 BLACK SILICONA | Q19: 0 | R19: 0 | S19: 0 | T19: 0 | U19: 0 | V19: 0 | W19: 0 | X19: 0 | Y19: 0 | Z19: 0 | AA19: 0 | AB19: 0 | AC19: 0 | AF19: A
A20: I01239 | B20: AURICULARES TIPO-C T61 FONENG BLANCO | D20: 77 | E20: 69 | F20: 23 | G20: 40 | H20: 129 | I20: 48 | J20: 108 | K20: 74 | L20: 56 | N20: 1 | Q20: 2.4839 | R20: 3.2857 | S20: 0.7419 | T20: 1.8382 | U20: 2.7101 | V20: 2.5806 | W20: 6.4286 | X20: 2.3871 | Y20: 4.1667 | Z20: 0 | AA20: 0 | AB20: 0 | AC20: 0 | AD20: 2.9846 | AE20: 2.9846 | AF20: A
A21: I01252 | B21: POWER BANK P51 BK 22.5W 10.000mAh FONENG | Q21: 0 | R21: 0 | S21: 0 | T21: 0 | U21: 0 | V21: 0 | W21: 0 | X21: 0 | Y21: 0 | Z21: 0 | AA21: 0 | AB21: 0 | AC21: 0 | AF21: A
A22: I01253 | B22: POWER BANK P51 WHITE 22.5W 10.000mAh FONENG | Q22: 0 | R22: 0 | S22: 0 | T22: 0 | U22: 0 | V22: 0 | W22: 0 | X22: 0 | Y22: 0 | Z22: 0 | AA22: 0 | AB22: 0 | AC22: 0 | AF22: A
A23: I01254 | B23: POWER BANK P52 BK 20.000mAh 22.5W FONENG | Q23: 0 | R23: 0 | S23: 0 | T23: 0 | U23: 0 | V23: 0 | W23: 0 | X23: 0 | Y23: 0 | Z23: 0 | AA23: 0 | AB23: 0 | AC23: 0 | AF23: A
A24: I01255 | B24: POWER BANK P52 WHITE 20.000mAh 22.5W FONENG | Q24: 0 | R24: 0 | S24: 0 | T24: 0 | U24: 0 | V24: 0 | W24: 0 | X24: 0 | Y24: 0 | Z24: 0 | AA24: 0 | AB24: 0 | AC24: 0 | AF24: A
A25: I01285 | B25: AURICULARES CABL. T63 PURPLE METAL FONENG | D25: 3 | E25: 9 | F25: 4 | H25: 5 | I25: 1 | J25: 12 | L25: 2 | N25: 7 | O25: 8 | Q25: 0.0968 | R25: 0.4286 | S25: 0.129 | T25: 0 | U25: 0.0949 | V25: 0.0538 | W25: 0.7143 | X25: 0 | Y25: 0.0794 | Z25: 0 | AA25: 0.2593 | AB25: 0.1985 | AC25: 0 | AD25: 0.1712 | AE25: 0.1712 | AF25: D
A26: I01286 | B26: AURICULARES CABL. T63 GRAY METAL FONENG | D26: 3 | E26: 12 | F26: 7 | G26: 13 | H26: 10 | I26: 12 | Q26: 0.0968 | R26: 0.5714 | S26: 0.2258 | T26: 0.3186 | U26: 0.1898 | V26: 3.3333 | W26: 0 | X26: 0 | Y26: 0 | Z26: 0 | AA26: 0 | AB26: 0 | AC26: 0 | AD26: 0.2805 | AE26: 0.2805 | AF26: D
A27: I01287 | B27: AURICULARES CABL. T63 BLUE METAL FONENG | D27: 5 | E27: 27 | F27: 5 | G27: 11 | H27: 7 | I27: 4 | J27: 12 | K27: 11 | L27: 14 | M27: 12 | N27: 10 | O27: 29 | Q27: 0.1613 | R27: 1.2857 | S27: 0.1613 | T27: 0.2696 | U27: 0.1328 | V27: 0.2151 | W27: 0.7143 | X27: 0.3548 | Y27: 0.5556 | Z27: 0.3871 | AA27: 0.3704 | AB27: 0.7196 | AC27: 0 | AD27: 0.444 | AE27: 0.444 | AF27: D
A28: I01288 | B28: AURICULARES T42 BLACK METAL FONENG | Q28: 0 | R28: 0 | S28: 0 | T28: 0 | U28: 0 | V28: 0 | W28: 0 | X28: 0 | Y28: 0 | Z28: 0 | AA28: 0 | AB28: 0 | AC28: 0 | AF28: D
A29: I01289 | B29: AURICULARES T29 WHITE HEAVY BASS FONENG | Q29: 0 | R29: 0 | S29: 0 | T29: 0 | U29: 0 | V29: 0 | W29: 0 | X29: 0 | Y29: 0 | Z29: 0 | AA29: 0 | AB29: 0 | AC29: 0 | AF29: D
A30: I01290 | B30: KIT AURICULARES T46 WHITE 20PCS FONENG | D30: 3 | E30: 9 | F30: 12 | G30: 10 | H30: 4 | I30: 4 | J30: 2 | K30: 6 | L30: 3 | M30: 2 | O30: 1 | Q30: 0.0968 | R30: 0.4286 | S30: 0.3871 | T30: 0.2451 | U30: 0.0759 | V30: 0.2151 | W30: 0.119 | X30: 0.1935 | Y30: 0.1374 | Z30: 0 | AA30: 0 | AB30: 0 | AC30: 0 | AD30: 0.2201 | AE30: 0.2201 | AF30: D
A31: I01291 | B31: SINTONIZADOR CARG. AUTO BC01 2 USB 2.1A FONENG | Q31: 0 | R31: 0 | S31: 0 | T31: 0 | U31: 0 | V31: 0 | W31: 0 | X31: 0 | Y31: 0 | Z31: 0 | AA31: 0 | AB31: 0 | AC31: 0 | AF31: D
A32: I01342 | B32: AURICULARES T46 WHITE FONENG | D32: 9 | E32: 4 | G32: 2 | H32: 2 | I32: 2 | K32: 1 | L32: 4 | M32: 1 | N32: 3 | Q32: 0 | R32: 0 | S32: 0 | T32: 0 | U32: 0 | V32: 0 | W32: 0 | X32: 0 | Y32: 0 | Z32: 0 | AA32: 0 | AB32: 0 | AC32: 0 | AF32: D
A33: I01387 | B33: AURICULARES T36 TIPO-C DIGITAL COMP FONENG | Q33: 0 | R33: 0 | S33: 0 | T33: 0 | U33: 0 | V33: 0 | W33: 0 | X33: 0 | Y33: 0 | Z33: 0 | AA33: 0 | AB33: 0 | AC33: 0 | AF33: A
A34: I01388 | B34: AURICULARES CABL. T59 BLACK IN-EAR FONENG | G34: 1 | M34: -1 | O34: 1 | Q34: 0 | R34: 0 | S34: 0 | T34: 0 | U34: 0 | V34: 0 | W34: 0 | X34: 0 | Y34: 0 | Z34: 0 | AA34: 0 | AB34: 0 | AC34: 0 | AF34: D
A35: I01389 | B35: AURICULARES CABL. T59 WHITE IN-EAR FONENG | Q35: 0 | R35: 0 | S35: 0 | T35: 0 | U35: 0 | V35: 0 | W35: 0 | X35: 0 | Y35: 0 | Z35: 0 | AA35: 0 | AB35: 0 | AC35: 0 | AF35: D
A36: I01399 | B36: REMERA FONENG M | Q36: 0 | R36: 0 | S36: 0 | T36: 0 | U36: 0 | V36: 0 | W36: 0 | X36: 0 | Y36: 0 | Z36: 0 | AA36: 0 | AB36: 0 | AC36: 0 | AF36: A
A37: I01400 | B37: REMERA FONENG L | Q37: 0 | R37: 0 | S37: 0 | T37: 0 | U37: 0 | V37: 0 | W37: 0 | X37: 0 | Y37: 0 | Z37: 0 | AA37: 0 | AB37: 0 | AC37: 0 | AF37: A
A38: I01401 | B38: REMERA FONENG XL | Q38: 0 | R38: 0 | S38: 0 | T38: 0 | U38: 0 | V38: 0 | W38: 0 | X38: 0 | Y38: 0 | Z38: 0 | AA38: 0 | AB38: 0 | AC38: 0 | AF38: A
A39: I01402 | B39: REMERA FONENG 2XL | Q39: 0 | R39: 0 | S39: 0 | T39: 0 | U39: 0 | V39: 0 | W39: 0 | X39: 0 | Y39: 0 | Z39: 0 | AA39: 0 | AB39: 0 | AC39: 0 | AF39: A
A40: I01481 | B40: NO USAR--CAR TIP-C EU 46 3 A FON--NO USAR | Q40: 0 | R40: 0 | S40: 0 | T40: 0 | U40: 0 | V40: 0 | W40: 0 | X40: 0 | Y40: 0 | Z40: 0 | AA40: 0 | AB40: 0 | AC40: 0 | AF40: A
...

Sheet Compras
A1: Fecha Proxima Importacion | B1: 46331 | D1: Dias Pedido | E1: 120 | G1: Dias Duracion | H1: 60 | J1: Relacion Venta Marcas | K1: 1 | L1: 1 | M1: 1
E3: I M P O R T A C I O N - 598 | N3: I M P O R T A C I O N - 600 | W3: S T O C K A L 05/11/2026 | AF3: S T O C K A L 04/01/2027
A4: Codigos Barras | B4: Descripcion | C4: Articulo.1 | D4: Stock Act.1 | E4: Arribo | F4: Dias Arribo. | G4: Quiebre Stk.1 | H4: % Proteccion.1 | I4: Pedidos.1 | J4: Stk.Arribo.1 | K4: FOB Arribo.1 | L4: UnidxEnv | M4: Volumen | N4: Arribo | O4: Dias Arribo. | P4: Quiebre Stk.1 | Q4: % Proteccion.1 | R4: Pedidos.1 | S4: Stk.Arribo.1 | T4: FOB Arribo.1 | U4: UnidxEnv | V4: Volumen | W4: Arribo Prox. | X4: Dias Arribo | Y4: Quiebre Stk.1 | Z4: % Proteccion.1 | AA4: Pedir Artic.1 | AB4: Confirmado Art.1 | AC4: Stk.Acumulado.1 | AD4: FOB U$S Art.1 | AE4: Prov. Cpa. Art.1 | AF4: Stk.Final.1 | AG4: % Proteccion.1 | AH4: Estado Art.1
B5: BOLSAS FONENG 388X282MM | C5: HX017 | E5: 46238 | F5: 1 | G5: =(D5-(0)+0-(F5*Ventas!AE6*0)) -> 0 | I5: 0 | J5: =IF(G5>0,G5+I5,I5) -> 0 | N5: 46275 | O5: 37 | P5: =(IF(G5>0,G5+I5,I5)-(O5*Ventas!AE6*1)) -> 0 | R5: 0 | S5: =IF(P5>0,P5+R5,R5) -> 0 | W5: 46331 | X5: 56 | Y5: =(IF(P5>0,P5+R5,R5)-(X5*Ventas!AE6*1)) -> 0 | AA5: =(120*(Ventas!AE6*1) - IF(Y5>0,Y5,0)) -> 0 | AB5: =IF(AA5>0,AA5,0) -> 0 | AC5: =IF(Y5>0,Y5+IF(AB5>0,AB5,0),AB5) -> 0 | AD5: 0.02 | AE5: 3017 | AH5: D
B6: EXHIBIDOR FONENG W1 1.8MX0.6M METAL | C6: HX018 | D6: 41 | E6: 46238 | F6: 1 | G6: =(D6-(0)+0-(F6*Ventas!AE7*0)) -> 41 | I6: 0 | J6: =IF(G6>0,G6+I6,I6) -> 41 | L6: 2 | M6: 0.084 | N6: 46275 | O6: 37 | P6: =(IF(G6>0,G6+I6,I6)-(O6*Ventas!AE7*1)) -> 41 | R6: 0 | S6: =IF(P6>0,P6+R6,R6) -> 41 | U6: 2 | V6: 0.084 | W6: 46331 | X6: 56 | Y6: =(IF(P6>0,P6+R6,R6)-(X6*Ventas!AE7*1)) -> 41 | AA6: =(120*(Ventas!AE7*1) - IF(Y6>0,Y6,0)) -> -41 | AB6: =IF(AA6>0,AA6,0) -> 0 | AC6: =IF(Y6>0,Y6+IF(AB6>0,AB6,0),AB6) -> 41 | AD6: 16.9 | AE6: 3010 | AH6: A
B7: EXHIBIDOR FONENG W2 2.2MX1MX0.3M | C7: HX019 | D7: 21 | E7: 46238 | F7: 1 | G7: =(D7-(0)+0-(F7*Ventas!AE8*0)) -> 21 | I7: 0 | J7: =IF(G7>0,G7+I7,I7) -> 21 | L7: 1 | M7: 0.088 | N7: 46275 | O7: 37 | P7: =(IF(G7>0,G7+I7,I7)-(O7*Ventas!AE8*1)) -> 21 | R7: 0 | S7: =IF(P7>0,P7+R7,R7) -> 21 | U7: 1 | V7: 0.088 | W7: 46331 | X7: 56 | Y7: =(IF(P7>0,P7+R7,R7)-(X7*Ventas!AE8*1)) -> 21 | AA7: =(120*(Ventas!AE8*1) - IF(Y7>0,Y7,0)) -> -21 | AB7: =IF(AA7>0,AA7,0) -> 0 | AC7: =IF(Y7>0,Y7+IF(AB7>0,AB7,0),AB7) -> 21 | AD7: 31.65 | AE7: 3027 | AH7: D
B8: EXHIBIDOR FONENG F1 2.25MX1MX0.3M | C8: HX020 | D8: 17 | E8: 46238 | F8: 1 | G8: =(D8-(0)+0-(F8*Ventas!AE9*0)) -> 17 | I8: 0 | J8: =IF(G8>0,G8+I8,I8) -> 17 | L8: 1 | M8: 0.22 | N8: 46275 | O8: 37 | P8: =(IF(G8>0,G8+I8,I8)-(O8*Ventas!AE9*1)) -> 17 | R8: 0 | S8: =IF(P8>0,P8+R8,R8) -> 17 | U8: 1 | V8: 0.22 | W8: 46331 | X8: 56 | Y8: =(IF(P8>0,P8+R8,R8)-(X8*Ventas!AE9*1)) -> 17 | AA8: =(120*(Ventas!AE9*1) - IF(Y8>0,Y8,0)) -> -17 | AB8: =IF(AA8>0,AA8,0) -> 0 | AC8: =IF(Y8>0,Y8+IF(AB8>0,AB8,0),AB8) -> 17 | AE8: 3025 | AH8: D
B9: EXHIBIDOR FONENG W3 1.39MX0.6MX0.21M | C9: HX023 | E9: 46238 | F9: 1 | G9: =(D9-(0)+0-(F9*Ventas!AE10*0)) -> 0 | I9: 0 | J9: =IF(G9>0,G9+I9,I9) -> 0 | N9: 46275 | O9: 37 | P9: =(IF(G9>0,G9+I9,I9)-(O9*Ventas!AE10*1)) -> 0 | R9: 0 | S9: =IF(P9>0,P9+R9,R9) -> 0 | W9: 46331 | X9: 56 | Y9: =(IF(P9>0,P9+R9,R9)-(X9*Ventas!AE10*1)) -> 0 | AA9: =(120*(Ventas!AE10*1) - IF(Y9>0,Y9,0)) -> 0 | AB9: =IF(AA9>0,AA9,0) -> 0 | AC9: =IF(Y9>0,Y9+IF(AB9>0,AB9,0),AB9) -> 0 | AD9: 12.21 | AE9: 3017 | AH9: D
B10: EXHIBIDOR FONENG F1B 2.25MX0.6MX0.3M | C10: HX025 | E10: 46238 | F10: 1 | G10: =(D10-(0)+0-(F10*Ventas!AE11*0)) -> 0 | I10: 0 | J10: =IF(G10>0,G10+I10,I10) -> 0 | N10: 46275 | O10: 37 | P10: =(IF(G10>0,G10+I10,I10)-(O10*Ventas!AE11*1)) -> 0 | R10: 0 | S10: =IF(P10>0,P10+R10,R10) -> 0 | W10: 46331 | X10: 56 | Y10: =(IF(P10>0,P10+R10,R10)-(X10*Ventas!AE11*1)) -> 0 | AA10: =(120*(Ventas!AE11*1) - IF(Y10>0,Y10,0)) -> 0 | AB10: =IF(AA10>0,AA10,0) -> 0 | AC10: =IF(Y10>0,Y10+IF(AB10>0,AB10,0),AB10) -> 0 | AE10: 3025 | AH10: D
B11: REMERA FONENG M | C11: I01399 | E11: 46238 | F11: 1 | G11: =(D11-(0)+0-(F11*Ventas!AE36*0)) -> 0 | I11: 0 | J11: =IF(G11>0,G11+I11,I11) -> 0 | N11: 46275 | O11: 37 | P11: =(IF(G11>0,G11+I11,I11)-(O11*Ventas!AE36*1)) -> 0 | R11: 0 | S11: =IF(P11>0,P11+R11,R11) -> 0 | W11: 46331 | X11: 56 | Y11: =(IF(P11>0,P11+R11,R11)-(X11*Ventas!AE36*1)) -> 0 | AA11: =(120*(Ventas!AE36*1) - IF(Y11>0,Y11,0)) -> 0 | AB11: =IF(AA11>0,AA11,0) -> 0 | AC11: =IF(Y11>0,Y11+IF(AB11>0,AB11,0),AB11) -> 0 | AH11: A
B12: REMERA FONENG L | C12: I01400 | E12: 46238 | F12: 1 | G12: =(D12-(0)+0-(F12*Ventas!AE37*0)) -> 0 | I12: 0 | J12: =IF(G12>0,G12+I12,I12) -> 0 | N12: 46275 | O12: 37 | P12: =(IF(G12>0,G12+I12,I12)-(O12*Ventas!AE37*1)) -> 0 | R12: 0 | S12: =IF(P12>0,P12+R12,R12) -> 0 | W12: 46331 | X12: 56 | Y12: =(IF(P12>0,P12+R12,R12)-(X12*Ventas!AE37*1)) -> 0 | AA12: =(120*(Ventas!AE37*1) - IF(Y12>0,Y12,0)) -> 0 | AB12: =IF(AA12>0,AA12,0) -> 0 | AC12: =IF(Y12>0,Y12+IF(AB12>0,AB12,0),AB12) -> 0 | AD12: 4.44 | AE12: 3017 | AH12: A
B13: REMERA FONENG XL | C13: I01401 | D13: 15 | E13: 46238 | F13: 1 | G13: =(D13-(0)+0-(F13*Ventas!AE38*0)) -> 15 | I13: 0 | J13: =IF(G13>0,G13+I13,I13) -> 15 | N13: 46275 | O13: 37 | P13: =(IF(G13>0,G13+I13,I13)-(O13*Ventas!AE38*1)) -> 15 | R13: 0 | S13: =IF(P13>0,P13+R13,R13) -> 15 | W13: 46331 | X13: 56 | Y13: =(IF(P13>0,P13+R13,R13)-(X13*Ventas!AE38*1)) -> 15 | AA13: =(120*(Ventas!AE38*1) - IF(Y13>0,Y13,0)) -> -15 | AB13: =IF(AA13>0,AA13,0) -> 0 | AC13: =IF(Y13>0,Y13+IF(AB13>0,AB13,0),AB13) -> 15 | AD13: 0.1 | AE13: 3010 | AH13: A
B14: REMERA FONENG 2XL | C14: I01402 | D14: 6 | E14: 46238 | F14: 1 | G14: =(D14-(0)+0-(F14*Ventas!AE39*0)) -> 6 | I14: 0 | J14: =IF(G14>0,G14+I14,I14) -> 6 | N14: 46275 | O14: 37 | P14: =(IF(G14>0,G14+I14,I14)-(O14*Ventas!AE39*1)) -> 6 | R14: 0 | S14: =IF(P14>0,P14+R14,R14) -> 6 | W14: 46331 | X14: 56 | Y14: =(IF(P14>0,P14+R14,R14)-(X14*Ventas!AE39*1)) -> 6 | AA14: =(120*(Ventas!AE39*1) - IF(Y14>0,Y14,0)) -> -6 | AB14: =IF(AA14>0,AA14,0) -> 0 | AC14: =IF(Y14>0,Y14+IF(AB14>0,AB14,0),AB14) -> 6 | AD14: 0.1 | AE14: 3010 | AH14: A
B15: NO USAR | C15: I001397 | E15: 46238 | F15: 1 | G15: =(D15-(0)+0-(F15*Ventas!AE12*1)) -> 0 | I15: 0 | J15: =IF(G15>0,G15+I15,I15) -> 0 | N15: 46275 | O15: 37 | P15: =(IF(G15>0,G15+I15,I15)-(O15*Ventas!AE12*0.9189)) -> 0 | R15: 0 | S15: =IF(P15>0,P15+R15,R15) -> 0 | W15: 46331 | X15: 56 | Y15: =(IF(P15>0,P15+R15,R15)-(X15*Ventas!AE12*0.8268)) -> 0 | AA15: =(120*(Ventas!AE12*1.95) - IF(Y15>0,Y15,0)) -> 0 | AB15: =IF(AA15>0,AA15,0) -> 0 | AC15: =IF(Y15>0,Y15+IF(AB15>0,AB15,0),AB15) -> 0 | AH15: A
B16: AURICULAR DIADEMA BLUETOOTH FONENG BL50 BLACK | C16: I01233 | E16: 46238 | F16: 1 | G16: =(D16-(0)+0-(F16*Ventas!AE18*1)) -> 0 | I16: 0 | J16: =IF(G16>0,G16+I16,I16) -> 0 | L16: 7 | M16: 0.004286 | N16: 46275 | O16: 37 | P16: =(IF(G16>0,G16+I16,I16)-(O16*Ventas!AE18*0.9189)) -> 0 | R16: 0 | S16: =IF(P16>0,P16+R16,R16) -> 0 | U16: 7 | V16: 0.004286 | W16: 46331 | X16: 56 | Y16: =(IF(P16>0,P16+R16,R16)-(X16*Ventas!AE18*0.8268)) -> 0 | AA16: =(120*(Ventas!AE18*1.95) - IF(Y16>0,Y16,0)) -> 0 | AB16: =IF(AA16>0,AA16,0) -> 0 | AC16: =IF(Y16>0,Y16+IF(AB16>0,AB16,0),AB16) -> 0 | AD16: 9.34 | AE16: 3025 | AH16: A
B17: PARLANTE BLUETOOTH FONENG BL10 LONG STANDBY RED | C17: I01235 | E17: 46238 | F17: 1 | G17: =(D17-(0)+0-(F17*Ventas!AE4*1)) -> 0 | I17: 0 | J17: =IF(G17>0,G17+I17,I17) -> 0 | L17: 44 | M17: 0.000847 | N17: 46275 | O17: 37 | P17: =(IF(G17>0,G17+I17,I17)-(O17*Ventas!AE4*0.9189)) -> 0 | R17: 0 | S17: =IF(P17>0,P17+R17,R17) -> 0 | U17: 44 | V17: 0.000847 | W17: 46331 | X17: 56 | Y17: =(IF(P17>0,P17+R17,R17)-(X17*Ventas!AE4*0.8268)) -> 0 | AA17: =(120*(Ventas!AE4*1.95) - IF(Y17>0,Y17,0)) -> 0 | AB17: =IF(AA17>0,AA17,0) -> 0 | AC17: =IF(Y17>0,Y17+IF(AB17>0,AB17,0),AB17) -> 0 | AD17: 4.43 | AE17: 3025 | AH17: A
B18: CABLE TIPO-C X63/XS01 2.1A 1MT FONENG | C18: I01214 | D18: 995 | E18: 46238 | F18: 1 | G18: =(D18-(0)+0-(F18*Ventas!AE56*1)) -> 985.3691 | H18: =(G18/(Ventas!AE56*1)/60) -> 1.7052216 | I18: 0 | J18: =IF(G18>0,G18+I18,I18) -> 985.3691 | L18: 120 | M18: 0.000331 | N18: 46275 | O18: 37 | P18: =(IF(G18>0,G18+I18,I18)-(O18*Ventas!AE56*1)) -> 629.0258 | Q18: =(P18/(Ventas!AE56*1)/60) -> 1.0885549 | R18: 600 | S18: =IF(P18>0,P18+R18,R18) -> 1229.0258 | T18: 0.38 | U18: 120 | V18: 0.000331 | W18: 46331 | X18: 56 | Y18: =(IF(P18>0,P18+R18,R18)-(X18*Ventas!AE56*1)) -> 689.6954 | Z18: =(Y18/(Ventas!AE56*1)/60) -> 1.1935461 | AA18: =(120*(Ventas!AE56*1) - IF(Y18>0,Y18,0)) -> 466.0126 | AB18: =IF(AA18>0,AA18,0) -> 466.0126 | AC18: =IF(Y18>0,Y18+IF(AB18>0,AB18,0),AB18) -> 1155.708 | AD18: 0.2833 | AE18: 3010 | AF18: =(AC18-(60*Ventas!AE56*1)) -> 577.854 | AG18: =(AF18/(Ventas!AE56*1)/60) -> 1 | AH18: A
B19: CABLE IPHONE X30 1MT MAGNETIC/LED FONENG | C19: I01215 | D19: 119 | E19: 46238 | F19: 1 | G19: =(D19-(0)+0-(F19*Ventas!AE57*1)) -> 118.9084 | H19: =(G19/(Ventas!AE57*1)/60) -> 21.635444 | I19: 0 | J19: =IF(G19>0,G19+I19,I19) -> 118.9084 | L19: 84 | M19: 0.000402 | N19: 46275 | O19: 37 | P19: =(IF(G19>0,G19+I19,I19)-(O19*Ventas!AE57*1)) -> 115.5192 | Q19: =(P19/(Ventas!AE57*1)/60) -> 21.018777 | R19: 0 | S19: =IF(P19>0,P19+R19,R19) -> 115.5192 | U19: 84 | V19: 0.000402 | W19: 46331 | X19: 56 | Y19: =(IF(P19>0,P19+R19,R19)-(X19*Ventas!AE57*1)) -> 110.3896 | Z19: =(Y19/(Ventas!AE57*1)/60) -> 20.085444 | AA19: =(120*(Ventas!AE57*1) - IF(Y19>0,Y19,0)) -> -99.3976 | AB19: =IF(AA19>0,AA19,0) -> 0 | AC19: =IF(Y19>0,Y19+IF(AB19>0,AB19,0),AB19) -> 110.3896 | AD19: 0.9604 | AE19: 3025 | AF19: =(AC19-(60*Ventas!AE57*1)) -> 104.8936 | AG19: =(AF19/(Ventas!AE57*1)/60) -> 19.085444 | AH19: D
B20: CABLE TIPO-C EU27 3A FONENG | C20: I01225 | E20: 46238 | F20: 1 | G20: =(D20-(0)+0-(F20*Ventas!AE58*1)) -> 0 | I20: 0 | J20: =IF(G20>0,G20+I20,I20) -> 0 | L20: 52 | M20: 0.000649 | N20: 46275 | O20: 37 | P20: =(IF(G20>0,G20+I20,I20)-(O20*Ventas!AE58*1)) -> 0 | R20: 0 | S20: =IF(P20>0,P20+R20,R20) -> 0 | U20: 52 | V20: 0.000649 | W20: 46331 | X20: 56 | Y20: =(IF(P20>0,P20+R20,R20)-(X20*Ventas!AE58*1)) -> 0 | AA20: =(120*(Ventas!AE58*1) - IF(Y20>0,Y20,0)) -> 0 | AB20: =IF(AA20>0,AA20,0) -> 0 | AC20: =IF(Y20>0,Y20+IF(AB20>0,AB20,0),AB20) -> 0 | AD20: 2.69 | AE20: 3025 | AH20: A
B21: CABLE TIPO-C EU28 2.4A FONENG | C21: I01226 | E21: 46238 | F21: 1 | G21: =(D21-(0)+0-(F21*Ventas!AE59*1)) -> 0 | I21: 0 | J21: =IF(G21>0,G21+I21,I21) -> 0 | L21: 52 | M21: 0.000577 | N21: 46275 | O21: 37 | P21: =(IF(G21>0,G21+I21,I21)-(O21*Ventas!AE59*1)) -> 0 | R21: 0 | S21: =IF(P21>0,P21+R21,R21) -> 0 | U21: 52 | V21: 0.000577 | W21: 46331 | X21: 56 | Y21: =(IF(P21>0,P21+R21,R21)-(X21*Ventas!AE59*1)) -> 0 | AA21: =(120*(Ventas!AE59*1) - IF(Y21>0,Y21,0)) -> 0 | AB21: =IF(AA21>0,AA21,0) -> 0 | AC21: =IF(Y21>0,Y21+IF(AB21>0,AB21,0),AB21) -> 0 | AD21: 1.42 | AE21: 3025 | AH21: A
B22: CABLE TIPO-C X69 3A GOMA FONENG | C22: I01228 | E22: 46238 | F22: 1 | G22: =(D22-(0)+0-(F22*Ventas!AE60*1)) -> 0 | I22: 0 | J22: =IF(G22>0,G22+I22,I22) -> 0 | L22: 60 | M22: 0.000433 | N22: 46275 | O22: 37 | P22: =(IF(G22>0,G22+I22,I22)-(O22*Ventas!AE60*1)) -> 0 | R22: 0 | S22: =IF(P22>0,P22+R22,R22) -> 0 | U22: 60 | V22: 0.000433 | W22: 46331 | X22: 56 | Y22: =(IF(P22>0,P22+R22,R22)-(X22*Ventas!AE60*1)) -> 0 | AA22: =(120*(Ventas!AE60*1) - IF(Y22>0,Y22,0)) -> 0 | AB22: =IF(AA22>0,AA22,0) -> 0 | AC22: =IF(Y22>0,Y22+IF(AB22>0,AB22,0),AB22) -> 0 | AD22: 0.87 | AE22: 3025 | AH22: A
B23: CABLE IPHONE X69 3A GOMA FONENG | C23: I01229 | E23: 46238 | F23: 1 | G23: =(D23-(0)+0-(F23*Ventas!AE61*1)) -> 0 | I23: 0 | J23: =IF(G23>0,G23+I23,I23) -> 0 | L23: 60 | M23: 0.000433 | N23: 46275 | O23: 37 | P23: =(IF(G23>0,G23+I23,I23)-(O23*Ventas!AE61*1)) -> 0 | R23: 0 | S23: =IF(P23>0,P23+R23,R23) -> 0 | U23: 60 | V23: 0.000433 | W23: 46331 | X23: 56 | Y23: =(IF(P23>0,P23+R23,R23)-(X23*Ventas!AE61*1)) -> 0 | AA23: =(120*(Ventas!AE61*1) - IF(Y23>0,Y23,0)) -> 0 | AB23: =IF(AA23>0,AA23,0) -> 0 | AC23: =IF(Y23>0,Y23+IF(AB23>0,AB23,0),AB23) -> 0 | AD23: 0.87 | AE23: 3025 | AH23: A
B24: CABLE IPHONE X77 FONENG | C24: I01238 | E24: 46238 | F24: 1 | G24: =(D24-(0)+0-(F24*Ventas!AE62*1)) -> 0 | I24: 0 | J24: =IF(G24>0,G24+I24,I24) -> 0 | L24: 60 | M24: 0.000472 | N24: 46275 | O24: 37 | P24: =(IF(G24>0,G24+I24,I24)-(O24*Ventas!AE62*1)) -> 0 | R24: 0 | S24: =IF(P24>0,P24+R24,R24) -> 0 | U24: 60 | V24: 0.000472 | W24: 46331 | X24: 56 | Y24: =(IF(P24>0,P24+R24,R24)-(X24*Ventas!AE62*1)) -> 0 | AA24: =(120*(Ventas!AE62*1) - IF(Y24>0,Y24,0)) -> 0 | AB24: =IF(AA24>0,AA24,0) -> 0 | AC24: =IF(Y24>0,Y24+IF(AB24>0,AB24,0),AB24) -> 0 | AD24: 0.46 | AE24: 3025 | AH24: A
B25: BOTELLON 30 CABLES XS06 TIPO-C 1M 2.4A FONENG | C25: I01261 | E25: 46238 | F25: 1 | G25: =(D25-(0)+0-(F25*Ventas!AE63*1)) -> -0.1965 | H25: =(G25/(Ventas!AE63*1)/60) -> -0.016666667 | I25: 36 | J25: =IF(G25>0,G25+I25,I25) -> 36 | K25: 10.51 | L25: 1 | M25: 0.000331 | N25: 46275 | O25: 37 | P25: =(IF(G25>0,G25+I25,I25)-(O25*Ventas!AE63*1)) -> 28.7295 | Q25: =(P25/(Ventas!AE63*1)/60) -> 2.4367684 | R25: 30 | S25: =IF(P25>0,P25+R25,R25) -> 58.7295 | T25: 10.61 | U25: 1 | V25: 0.000331 | W25: 46331 | X25: 56 | Y25: =(IF(P25>0,P25+R25,R25)-(X25*Ventas!AE63*1)) -> 47.7255 | Z25: =(Y25/(Ventas!AE63*1)/60) -> 4.0479644 | AA25: =(120*(Ventas!AE63*1) - IF(Y25>0,Y25,0)) -> -24.1455 | AB25: =IF(AA25>0,AA25,0) -> 0 | AC25: =IF(Y25>0,Y25+IF(AB25>0,AB25,0),AB25) -> 47.7255 | AD25: 10.51 | AE25: 3025 | AF25: =(AC25-(60*Ventas!AE63*1)) -> 35.9355 | AG25: =(AF25/(Ventas!AE63*1)/60) -> 3.0479644 | AH25: A
B26: BOTELLON 30 CABLES XS06 IPHONE 1M 2.4A FONENG | C26: I01262 | D26: 4 | E26: 46238 | F26: 1 | G26: =(D26-(0)+0-(F26*Ventas!AE64*1)) -> 3.8266 | H26: =(G26/(Ventas!AE64*1)/60) -> 0.36780085 | I26: 0 | J26: =IF(G26>0,G26+I26,I26) -> 3.8266 | L26: 1 | M26: 0.000331 | N26: 46275 | O26: 37 | P26: =(IF(G26>0,G26+I26,I26)-(O26*Ventas!AE64*1)) -> -2.5892 | Q26: =(P26/(Ventas!AE64*1)/60) -> -0.24886582 | R26: 30 | S26: =IF(P26>0,P26+R26,R26) -> 30 | T26: 10.61 | U26: 1 | V26: 0.000331 | W26: 46331 | X26: 56 | Y26: =(IF(P26>0,P26+R26,R26)-(X26*Ventas!AE64*1)) -> 20.2896 | Z26: =(Y26/(Ventas!AE64*1)/60) -> 1.950173 | AA26: =(120*(Ventas!AE64*1) - IF(Y26>0,Y26,0)) -> 0.5184 | AB26: =IF(AA26>0,AA26,0) -> 0.5184 | AC26: =IF(Y26>0,Y26+IF(AB26>0,AB26,0),AB26) -> 20.808 | AD26: 10.36 | AE26: 3027 | AF26: =(AC26-(60*Ventas!AE64*1)) -> 10.404 | AG26: =(AF26/(Ventas!AE64*1)/60) -> 1 | AH26: A
B27: CABLE TIPO-C 90° X70 3A 1MT TRENZADO FONENG | C27: I01263 | E27: 46238 | F27: 1 | G27: =(D27-(0)+0-(F27*Ventas!AE65*1)) -> 0 | I27: 0 | J27: =IF(G27>0,G27+I27,I27) -> 0 | L27: 60 | M27: 0.000472 | N27: 46275 | O27: 37 | P27: =(IF(G27>0,G27+I27,I27)-(O27*Ventas!AE65*1)) -> 0 | R27: 0 | S27: =IF(P27>0,P27+R27,R27) -> 0 | U27: 60 | V27: 0.000472 | W27: 46331 | X27: 56 | Y27: =(IF(P27>0,P27+R27,R27)-(X27*Ventas!AE65*1)) -> 0 | AA27: =(120*(Ventas!AE65*1) - IF(Y27>0,Y27,0)) -> 0 | AB27: =IF(AA27>0,AA27,0) -> 0 | AC27: =IF(Y27>0,Y27+IF(AB27>0,AB27,0),AB27) -> 0 | AD27: 0.67 | AE27: 3010 | AH27: D
B28: CABLE IPHONE 90° X70 3A 1MT TRENZADO FONENG | C28: I01264 | D28: 57 | E28: 46238 | F28: 1 | G28: =(D28-(0)+0-(F28*Ventas!AE66*1)) -> 56.8292 | H28: =(G28/(Ventas!AE66*1)/60) -> 5.5453942 | I28: 0 | J28: =IF(G28>0,G28+I28,I28) -> 56.8292 | L28: 60 | M28: 0.000472 | N28: 46275 | O28: 37 | P28: =(IF(G28>0,G28+I28,I28)-(O28*Ventas!AE66*1)) -> 50.5096 | Q28: =(P28/(Ventas!AE66*1)/60) -> 4.9287276 | R28: 0 | S28: =IF(P28>0,P28+R28,R28) -> 50.5096 | U28: 60 | V28: 0.000472 | W28: 46331 | X28: 56 | Y28: =(IF(P28>0,P28+R28,R28)-(X28*Ventas!AE66*1)) -> 40.9448 | Z28: =(Y28/(Ventas!AE66*1)/60) -> 3.9953942 | AA28: =(120*(Ventas!AE66*1) - IF(Y28>0,Y28,0)) -> -20.4488 | AB28: =IF(AA28>0,AA28,0) -> 0 | AC28: =IF(Y28>0,Y28+IF(AB28>0,AB28,0),AB28) -> 40.9448 | AD28: 0.68 | AE28: 3010 | AF28: =(AC28-(60*Ventas!AE66*1)) -> 30.6968 | AG28: =(AF28/(Ventas!AE66*1)/60) -> 2.9953942 | AH28: D
B29: CABLE TIPO-C X66 3A 1MT FONENG | C29: I01265 | D29: 81 | E29: 46238 | F29: 1 | G29: =(D29-(0)+0-(F29*Ventas!AE67*1)) -> 75.3325 | H29: =(G29/(Ventas!AE67*1)/60) -> 0.2215336 | I29: 480 | J29: =IF(G29>0,G29+I29,I29) -> 555.3325 | K29: 0.57 | L29: 120 | M29: 0.000281 | N29: 46275 | O29: 37 | P29: =(IF(G29>0,G29+I29,I29)-(O29*Ventas!AE67*1)) -> 345.635 | Q29: =(P29/(Ventas!AE67*1)/60) -> 1.0164241 | R29: 0 | S29: =IF(P29>0,P29+R29,R29) -> 345.635 | U29: 120 | V29: 0.000281 | W29: 46331 | X29: 56 | Y29: =(IF(P29>0,P29+R29,R29)-(X29*Ventas!AE67*1)) -> 28.255 | Z29: =(Y29/(Ventas!AE67*1)/60) -> 0.083090722 | AA29: =(120*(Ventas!AE67*1) - IF(Y29>0,Y29,0)) -> 651.845 | AB29: =IF(AA29>0,AA29,0) -> 651.845 | AC29: =IF(Y29>0,Y29+IF(AB29>0,AB29,0),AB29) -> 680.1 | AD29: 0.57 | AE29: 3025 | AF29: =(AC29-(60*Ventas!AE67*1)) -> 340.05 | AG29: =(AF29/(Ventas!AE67*1)/60) -> 1 | AH29: A
B30: CABLE IPHONE X66 2.4A 1MT FONENG | C30: I01266 | D30: 204 | E30: 46238 | F30: 1 | G30: =(D30-(0)+0-(F30*Ventas!AE68*1)) -> 199.5187 | H30: =(G30/(Ventas!AE68*1)/60) -> 0.74204174 | I30: 360 | J30: =IF(G30>0,G30+I30,I30) -> 559.5187 | K30: 0.57 | L30: 120 | M30: 0.000281 | N30: 46275 | O30: 37 | P30: =(IF(G30>0,G30+I30,I30)-(O30*Ventas!AE68*1)) -> 393.7106 | Q30: =(P30/(Ventas!AE68*1)/60) -> 1.4642723 | R30: 0 | S30: =IF(P30>0,P30+R30,R30) -> 393.7106 | U30: 120 | V30: 0.000281 | W30: 46331 | X30: 56 | Y30: =(IF(P30>0,P30+R30,R30)-(X30*Ventas!AE68*1)) -> 142.7578 | Z30: =(Y30/(Ventas!AE68*1)/60) -> 0.53093894 | AA30: =(120*(Ventas!AE68*1) - IF(Y30>0,Y30,0)) -> 394.9982 | AB30: =IF(AA30>0,AA30,0) -> 394.9982 | AC30: =IF(Y30>0,Y30+IF(AB30>0,AB30,0),AB30) -> 537.756 | AD30: 0.57 | AE30: 3025 | AF30: =(AC30-(60*Ventas!AE68*1)) -> 268.878 | AG30: =(AF30/(Ventas!AE68*1)/60) -> 1 | AH30: A
B31: CABLE TIPO-C X66 3A -2MT- FONENG | C31: I01267 | D31: 152 | E31: 46238 | F31: 1 | G31: =(D31-(0)+0-(F31*Ventas!AE69*1)) -> 149.1617 | H31: =(G31/(Ventas!AE69*1)/60) -> 0.87588639 | I31: 240 | J31: =IF(G31>0,G31+I31,I31) -> 389.1617 | K31: 0.83 | L31: 80 | M31: 0.00034 | N31: 46275 | O31: 37 | P31: =(IF(G31>0,G31+I31,I31)-(O31*Ventas!AE69*1)) -> 284.1446 | Q31: =(P31/(Ventas!AE69*1)/60) -> 1.668514 | R31: 0 | S31: =IF(P31>0,P31+R31,R31) -> 284.1446 | U31: 80 | V31: 0.00034 | W31: 46331 | X31: 56 | Y31: =(IF(P31>0,P31+R31,R31)-(X31*Ventas!AE69*1)) -> 125.1998 | Z31: =(Y31/(Ventas!AE69*1)/60) -> 0.73518068 | AA31: =(120*(Ventas!AE69*1) - IF(Y31>0,Y31,0)) -> 215.3962 | AB31: =IF(AA31>0,AA31,0) -> 215.3962 | AC31: =IF(Y31>0,Y31+IF(AB31>0,AB31,0),AB31) -> 340.596 | AD31: 0.83 | AE31: 3025 | AF31: =(AC31-(60*Ventas!AE69*1)) -> 170.298 | AG31: =(AF31/(Ventas!AE69*1)/60) -> 1 | AH31: A
B32: CABLE IPHONE X66 2.4A -2MT- FONENG | C32: I01268 | D32: 148 | E32: 46238 | F32: 1 | G32: =(D32-(0)+0-(F32*Ventas!AE70*1)) -> 146.5153 | H32: =(G32/(Ventas!AE70*1)/60) -> 1.644724 | I32: 120 | J32: =IF(G32>0,G32+I32,I32) -> 266.5153 | K32: 0.83 | L32: 80 | M32: 0.00034 | N32: 46275 | O32: 37 | P32: =(IF(G32>0,G32+I32,I32)-(O32*Ventas!AE70*1)) -> 211.5814 | Q32: =(P32/(Ventas!AE70*1)/60) -> 2.3751308 | R32: 0 | S32: =IF(P32>0,P32+R32,R32) -> 211.5814 | U32: 80 | V32: 0.00034 | W32: 46331 | X32: 56 | Y32: =(IF(P32>0,P32+R32,R32)-(X32*Ventas!AE70*1)) -> 128.4382 | Z32: =(Y32/(Ventas!AE70*1)/60) -> 1.4417974 | AA32: =(120*(Ventas!AE70*1) - IF(Y32>0,Y32,0)) -> 49.7258 | AB32: =IF(AA32>0,AA32,0) -> 49.7258 | AC32: =IF(Y32>0,Y32+IF(AB32>0,AB32,0),AB32) -> 178.164 | AD32: 0.83 | AE32: 3025 | AF32: =(AC32-(60*Ventas!AE70*1)) -> 89.082 | AG32: =(AF32/(Ventas!AE70*1)/60) -> 1 | AH32: A
B33: CABLE MICRO X63/XS01 2.1A 1MT FONENG | C33: I01269 | D33: 1300 | E33: 46238 | F33: 1 | G33: =(D33-(0)+0-(F33*Ventas!AE71*1)) -> 1295.7384 | H33: =(G33/(Ventas!AE71*1)/60) -> 5.0674958 | I33: 0 | J33: =IF(G33>0,G33+I33,I33) -> 1295.7384 | L33: 120 | M33: 0.000331 | N33: 46275 | O33: 37 | P33: =(IF(G33>0,G33+I33,I33)-(O33*Ventas!AE71*1)) -> 1138.0592 | Q33: =(P33/(Ventas!AE71*1)/60) -> 4.4508291 | R33: 0 | S33: =IF(P33>0,P33+R33,R33) -> 1138.0592 | U33: 120 | V33: 0.000331 | W33: 46331 | X33: 56 | Y33: =(IF(P33>0,P33+R33,R33)-(X33*Ventas!AE71*1)) -> 899.4096 | Z33: =(Y33/(Ventas!AE71*1)/60) -> 3.5174958 | AA33: =(120*(Ventas!AE71*1) - IF(Y33>0,Y33,0)) -> -388.0176 | AB33: =IF(AA33>0,AA33,0) -> 0 | AC33: =IF(Y33>0,Y33+IF(AB33>0,AB33,0),AB33) -> 899.4096 | AD33: 0.2167 | AE33: 3010 | AF33: =(AC33-(60*Ventas!AE71*1)) -> 643.7136 | AG33: =(AF33/(Ventas!AE71*1)/60) -> 2.5174958 | AH33: A
B34: CABLE IPHONE X63/XS01 2.1A 1MT FONENG | C34: I01270 | D34: 2117 | E34: 46238 | F34: 1 | G34: =(D34-(0)+0-(F34*Ventas!AE72*1)) -> 2109.1764 | H34: =(G34/(Ventas!AE72*1)/60) -> 4.4931924 | I34: 0 | J34: =IF(G34>0,G34+I34,I34) -> 2109.1764 | L34: 120 | M34: 0.000331 | N34: 46275 | O34: 37 | P34: =(IF(G34>0,G34+I34,I34)-(O34*Ventas!AE72*1)) -> 1819.7032 | Q34: =(P34/(Ventas!AE72*1)/60) -> 3.8765257 | R34: 0 | S34: =IF(P34>0,P34+R34,R34) -> 1819.7032 | U34: 120 | V34: 0.000331 | W34: 46331 | X34: 56 | Y34: =(IF(P34>0,P34+R34,R34)-(X34*Ventas!AE72*1)) -> 1381.5816 | Z34: =(Y34/(Ventas!AE72*1)/60) -> 2.9431924 | AA34: =(120*(Ventas!AE72*1) - IF(Y34>0,Y34,0)) -> -442.7496 | AB34: =IF(AA34>0,AA34,0) -> 0 | AC34: =IF(Y34>0,Y34+IF(AB34>0,AB34,0),AB34) -> 1381.5816 | AD34: 0.2833 | AE34: 3010 | AF34: =(AC34-(60*Ventas!AE72*1)) -> 912.1656 | AG34: =(AF34/(Ventas!AE72*1)/60) -> 1.9431924 | AH34: A
B35: CABLE 3 EN 1 X36 2.4A 1.2MT TIPO-C/IPH/MIC FONENG | C35: I01271 | E35: 46238 | F35: 1 | G35: =(D35-(0)+0-(F35*Ventas!AE73*1)) -> -0.632 | H35: =(G35/(Ventas!AE73*1)/60) -> -0.016666667 | I35: 0 | J35: =IF(G35>0,G35+I35,I35) -> 0 | L35: 60 | M35: 0.000472 | N35: 46275 | O35: 37 | P35: =(IF(G35>0,G35+I35,I35)-(O35*Ventas!AE73*1)) -> -23.384 | Q35: =(P35/(Ventas!AE73*1)/60) -> -0.61666667 | R35: 0 | S35: =IF(P35>0,P35+R35,R35) -> 0 | U35: 60 | V35: 0.000472 | W35: 46331 | X35: 56 | Y35: =(IF(P35>0,P35+R35,R35)-(X35*Ventas!AE73*1)) -> -35.392 | Z35: =(Y35/(Ventas!AE73*1)/60) -> -0.93333333 | AA35: =(120*(Ventas!AE73*1) - IF(Y35>0,Y35,0)) -> 75.84 | AB35: =IF(AA35>0,AA35,0) -> 75.84 | AC35: =IF(Y35>0,Y35+IF(AB35>0,AB35,0),AB35) -> 75.84 | AD35: 1.02 | AE35: 3010 | AF35: =(AC35-(60*Ventas!AE73*1)) -> 37.92 | AG35: =(AF35/(Ventas!AE73*1)/60) -> 1 | AH35: D
B36: CABLE TIPO-C X79 METAL/RGB 3A 66W 1MT FONENG | C36: I01272 | E36: 46238 | F36: 1 | G36: =(D36-(0)+0-(F36*Ventas!AE74*1)) -> -1.5241 | H36: =(G36/(Ventas!AE74*1)/60) -> -0.016666667 | I36: 252 | J36: =IF(G36>0,G36+I36,I36) -> 252 | K36: 1.2 | L36: 84 | M36: 0.000402 | N36: 46275 | O36: 37 | P36: =(IF(G36>0,G36+I36,I36)-(O36*Ventas!AE74*1)) -> 195.6083 | Q36: =(P36/(Ventas!AE74*1)/60) -> 2.139058 | R36: 0 | S36: =IF(P36>0,P36+R36,R36) -> 195.6083 | U36: 84 | V36: 0.000402 | W36: 46331 | X36: 56 | Y36: =(IF(P36>0,P36+R36,R36)-(X36*Ventas!AE74*1)) -> 110.2587 | Z36: =(Y36/(Ventas!AE74*1)/60) -> 1.2057247 | AA36: =(120*(Ventas!AE74*1) - IF(Y36>0,Y36,0)) -> 72.6333 | AB36: =IF(AA36>0,AA36,0) -> 72.6333 | AC36: =IF(Y36>0,Y36+IF(AB36>0,AB36,0),AB36) -> 182.892 | AD36: 1.2 | AE36: 3025 | AF36: =(AC36-(60*Ventas!AE74*1)) -> 91.446 | AG36: =(AF36/(Ventas!AE74*1)/60) -> 1 | AH36: A
B37: CABLE IPHONE X79 METAL/RGB 3A 1MT FONENG SUPERFAST | C37: I01273 | E37: 46238 | F37: 1 | G37: =(D37-(0)+0-(F37*Ventas!AE75*1)) -> -0.6826 | H37: =(G37/(Ventas!AE75*1)/60) -> -0.016666667 | I37: 0 | J37: =IF(G37>0,G37+I37,I37) -> 0 | L37: 84 | M37: 0.000402 | N37: 46275 | O37: 37 | P37: =(IF(G37>0,G37+I37,I37)-(O37*Ventas!AE75*1)) -> -25.2562 | Q37: =(P37/(Ventas!AE75*1)/60) -> -0.61666667 | R37: 0 | S37: =IF(P37>0,P37+R37,R37) -> 0 | U37: 84 | V37: 0.000402 | W37: 46331 | X37: 56 | Y37: =(IF(P37>0,P37+R37,R37)-(X37*Ventas!AE75*1)) -> -38.2256 | Z37: =(Y37/(Ventas!AE75*1)/60) -> -0.93333333 | AA37: =(120*(Ventas!AE75*1) - IF(Y37>0,Y37,0)) -> 81.912 | AB37: =IF(AA37>0,AA37,0) -> 81.912 | AC37: =IF(Y37>0,Y37+IF(AB37>0,AB37,0),AB37) -> 81.912 | AD37: 0.95 | AE37: 3010 | AF37: =(AC37-(60*Ventas!AE75*1)) -> 40.956 | AG37: =(AF37/(Ventas!AE75*1)/60) -> 1 | AH37: A
B38: CABLE TIPO-C X15 WHI 2.4A 1.2MT TRENZ FONENG | C38: I01274 | E38: 46238 | F38: 1 | G38: =(D38-(0)+0-(F38*Ventas!AE76*1)) -> 0 | I38: 0 | J38: =IF(G38>0,G38+I38,I38) -> 0 | L38: 60 | M38: 0.000472 | N38: 46275 | O38: 37 | P38: =(IF(G38>0,G38+I38,I38)-(O38*Ventas!AE76*1)) -> 0 | R38: 0 | S38: =IF(P38>0,P38+R38,R38) -> 0 | U38: 60 | V38: 0.000472 | W38: 46331 | X38: 56 | Y38: =(IF(P38>0,P38+R38,R38)-(X38*Ventas!AE76*1)) -> 0 | AA38: =(120*(Ventas!AE76*1) - IF(Y38>0,Y38,0)) -> 0 | AB38: =IF(AA38>0,AA38,0) -> 0 | AC38: =IF(Y38>0,Y38+IF(AB38>0,AB38,0),AB38) -> 0 | AD38: 0.69 | AE38: 3017 | AH38: D
B39: CABLE TIPO-C X15 BK 2.4A 1.2MT TRENZ FONENG | C39: I01275 | E39: 46238 | F39: 1 | G39: =(D39-(0)+0-(F39*Ventas!AE77*1)) -> 0 | I39: 0 | J39: =IF(G39>0,G39+I39,I39) -> 0 | L39: 60 | M39: 0.000472 | N39: 46275 | O39: 37 | P39: =(IF(G39>0,G39+I39,I39)-(O39*Ventas!AE77*1)) -> 0 | R39: 0 | S39: =IF(P39>0,P39+R39,R39) -> 0 | U39: 60 | V39: 0.000472 | W39: 46331 | X39: 56 | Y39: =(IF(P39>0,P39+R39,R39)-(X39*Ventas!AE77*1)) -> 0 | AA39: =(120*(Ventas!AE77*1) - IF(Y39>0,Y39,0)) -> 0 | AB39: =IF(AA39>0,AA39,0) -> 0 | AC39: =IF(Y39>0,Y39+IF(AB39>0,AB39,0),AB39) -> 0 | AD39: 0.59 | AE39: 3010 | AH39: D
B40: CABLE IPHONE X15 WHI 2.4A 1.2MT TRENZ FONENG | C40: I01276 | E40: 46238 | F40: 1 | G40: =(D40-(0)+0-(F40*Ventas!AE78*1)) -> 0 | I40: 0 | J40: =IF(G40>0,G40+I40,I40) -> 0 | L40: 60 | M40: 0.000472 | N40: 46275 | O40: 37 | P40: =(IF(G40>0,G40+I40,I40)-(O40*Ventas!AE78*1)) -> 0 | R40: 0 | S40: =IF(P40>0,P40+R40,R40) -> 0 | U40: 60 | V40: 0.000472 | W40: 46331 | X40: 56 | Y40: =(IF(P40>0,P40+R40,R40)-(X40*Ventas!AE78*1)) -> 0 | AA40: =(120*(Ventas!AE78*1) - IF(Y40>0,Y40,0)) -> 0 | AB40: =IF(AA40>0,AA40,0) -> 0 | AC40: =IF(Y40>0,Y40+IF(AB40>0,AB40,0),AB40) -> 0 | AD40: 0.73 | AE40: 3010 | AH40: D
B41: CABLE IPHONE X15 BK 2.4A 1.2MT TRENZ FONENG | C41: I01277 | E41: 46238 | F41: 1 | G41: =(D41-(0)+0-(F41*Ventas!AE79*1)) -> 0 | I41: 0 | J41: =IF(G41>0,G41+I41,I41) -> 0 | L41: 60 | M41: 0.000472 | N41: 46275 | O41: 37 | P41: =(IF(G41>0,G41+I41,I41)-(O41*Ventas!AE79*1)) -> 0 | R41: 0 | S41: =IF(P41>0,P41+R41,R41) -> 0 | U41: 60 | V41: 0.000472 | W41: 46331 | X41: 56 | Y41: =(IF(P41>0,P41+R41,R41)-(X41*Ventas!AE79*1)) -> 0 | AA41: =(120*(Ventas!AE79*1) - IF(Y41>0,Y41,0)) -> 0 | AB41: =IF(AA41>0,AA41,0) -> 0 | AC41: =IF(Y41>0,Y41+IF(AB41>0,AB41,0),AB41) -> 0 | AD41: 0.69 | AE41: 3017 | AH41: D
...
