Workbook

Sheet Ventas
A1: Articulo | B1: Descripcion | C1: Codigos Barras | D1: Vta.Jul/25 | E1: Vta.Ago/25 | F1: Vta.Sep/25 | G1: Vta.Oct/25 | H1: Vta.Nov/25 | I1: Vta.Dic/25 | J1: Vta.Ene/26 | K1: Vta.Feb/26 | L1: Vta.Mar/26 | M1: Vta.Abr/26 | N1: Vta.May/26 | O1: Vta.Jun/26 | P1: Vta.Jul/26 | Q1: Jul/25 | R1: Ago/25 | S1: Sep/25 | T1: Oct/25 | U1: Nov/25 | V1: Dic/25 | W1: Ene/26 | X1: Feb/26 | Y1: Mar/26 | Z1: Abr/26 | AA1: May/26 | AB1: Jun/26 | AC1: Jul/26 | AD1: Rotacion DesEstac. | AE1: Rot. Manual | AF1: Estado Art.
A2: C00159 | B2: TONER SAMSUNG CPT ML1610/2010/4521/X3117 3K Univ. | C2: 5358125120017 | D2: 2 | E2: 3 | F2: 7 | G2: 4 | H2: 5 | J2: 6 | K2: 2 | L2: 5 | M2: 9 | N2: 4 | O2: 2 | P2: 2 | Q2: 0.0645 | R2: 0.0968 | S2: 0.2029 | T2: 0.129 | U2: 0.1667 | V2: 0 | W2: 0.2419 | X2: 0.084 | Y2: 0.1466 | Z2: 0.3333 | AA2: 0.1229 | AB2: 0.058 | AC2: 0.0645 | AD2: 0.1372 | AE2: 0.1372 | AF2: A
A3: C00160 | B3: TONER HP Q2612A / CANON FX9 / FX10 2K CPT | C3: 5350125120257 | D3: 20 | E3: 16 | F3: 24 | G3: 13 | H3: 9 | I3: 13 | J3: 13 | K3: 8 | L3: 31 | M3: 14 | N3: 25 | O3: 29 | P3: 20 | Q3: 0.6452 | R3: 0.5161 | S3: 0.6957 | T3: 0.4194 | U3: 0.3 | V3: 0.4194 | W3: 0.5242 | X3: 0.3361 | Y3: 0.9091 | Z3: 0.5185 | AA3: 0.768 | AB3: 0.8406 | AC3: 0.6452 | AD3: 0.5744 | AE3: 0.5744 | AF3: A
A4: C00163 | B4: TONER LEXMARK E120 - 12018SL CPT 2K | C4: 5357125120133 | Q4: 0 | R4: 0 | S4: 0 | T4: 0 | U4: 0 | V4: 0 | W4: 0 | X4: 0 | Y4: 0 | Z4: 0 | AA4: 0 | AB4: 0 | AC4: 0 | AF4: A
A5: C00164 | B5: TONER HP Q5949A / Q7553A 3K CPT | C5: 5350125120127 | D5: 1 | E5: 1 | G5: 1 | I5: 1 | J5: 1 | K5: 2 | M5: 3 | P5: 7 | Q5: 0.0323 | R5: 0.0323 | S5: 0 | T5: 0.0323 | U5: 0 | V5: 0.0323 | W5: 0.0403 | X5: 0.084 | Y5: 0 | Z5: 0.1111 | AA5: 0 | AB5: 0 | AC5: 0.3043 | AD5: 0.0304 | AE5: 0.0304 | AF5: A
A6: C00165 | B6: TONER HP C4092A/CANON EP-22 CPT 2.5K | C6: 5350125120059 | E6: 2 | F6: 1 | P6: 1 | Q6: 0 | R6: 0.2 | S6: 0 | T6: 0 | U6: 0 | V6: 0 | W6: 0 | X6: 0 | Y6: 0 | Z6: 0 | AA6: 0 | AB6: 0 | AC6: 1 | AF6: A
A7: C00166 | B7: TONER HP Q7553A 3K CPT | C7: 5350125120400 | Q7: 0 | R7: 0 | S7: 0 | T7: 0 | U7: 0 | V7: 0 | W7: 0 | X7: 0 | Y7: 0 | Z7: 0 | AA7: 0 | AB7: 0 | AC7: 0 | AF7: D
A8: C00174 | B8: TONER XEROX 106R01271 BK 6110 CPT 2.0k | C8: 5352125120022 | Q8: 0 | R8: 0 | S8: 0 | T8: 0 | U8: 0 | V8: 0 | W8: 0 | X8: 0 | Y8: 0 | Z8: 0 | AA8: 0 | AB8: 0 | AC8: 0 | AF8: A
A9: C00175 | B9: TONER XEROX 106R01272 CY 6110 CPT 1.0k | C9: 5352125120039 | N9: 2 | O9: -2 | Q9: 0 | R9: 0 | S9: 0 | T9: 0 | U9: 0 | V9: 0 | W9: 0 | X9: 0 | Y9: 0 | Z9: 0 | AA9: 0.1465 | AB9: -0.0915 | AC9: 0 | AF9: A
A10: C00176 | B10: TONER XEROX 106R01273 MG 6110 CPT 1.0K | C10: 5352125120046 | Q10: 0 | R10: 0 | S10: 0 | T10: 0 | U10: 0 | V10: 0 | W10: 0 | X10: 0 | Y10: 0 | Z10: 0 | AA10: 0 | AB10: 0 | AC10: 0 | AF10: A
A11: C00177 | B11: TONER XEROX 106R01274 YE 6110 CPT 1.0K | C11: 5352125120053 | Q11: 0 | R11: 0 | S11: 0 | T11: 0 | U11: 0 | V11: 0 | W11: 0 | X11: 0 | Y11: 0 | Z11: 0 | AA11: 0 | AB11: 0 | AC11: 0 | AF11: A
A12: C00178 | B12: TONER BROTHER TN-360/TN-2115/2125 CPT 2.6K | C12: 5353137120017 | D12: 14 | E12: 8 | F12: 6 | G12: 6 | H12: 15 | I12: 17 | K12: 6 | L12: 9 | M12: 6 | N12: 1 | O12: 13 | P12: 5 | Q12: 0.4516 | R12: 0.2581 | S12: 0.1739 | T12: 0.1935 | U12: 0.5 | V12: 0.5484 | W12: 0 | X12: 0.2521 | Y12: 0.2639 | Z12: 0.2222 | AA12: 0.0307 | AB12: 0.3768 | AC12: 0.1613 | AD12: 0.2726 | AE12: 0.2726 | AF12: A
A13: C00179 | B13: TONER BROTHER TN-580/TN-650 CPT 8K | C13: 5353125120029 | D13: 12 | E13: 2 | F13: 2 | G13: 21 | H13: 4 | I13: 5 | J13: 4 | K13: 2 | L13: 3 | M13: 13 | N13: 14 | O13: 7 | P13: 2 | Q13: 0.3871 | R13: 0.0645 | S13: 0.058 | T13: 0.6774 | U13: 0.1333 | V13: 0.1613 | W13: 0.1613 | X13: 0.084 | Y13: 0.088 | Z13: 0.4815 | AA13: 0.4301 | AB13: 0.2029 | AC13: 0.0645 | AD13: 0.2441 | AE13: 0.2441 | AF13: A
A14: C00181 | B14: TONER OKIDATA 2500/ 2520 - CPT 2.2K | Q14: 0 | R14: 0 | S14: 0 | T14: 0 | U14: 0 | V14: 0 | W14: 0 | X14: 0 | Y14: 0 | Z14: 0 | AA14: 0 | AB14: 0 | AC14: 0 | AF14: D
A15: C00182 | B15: TONER OKIDATA 6300 - CPT 10K | C15: 5352125120060 | Q15: 0 | R15: 0 | S15: 0 | T15: 0 | U15: 0 | V15: 0 | W15: 0 | X15: 0 | Y15: 0 | Z15: 0 | AA15: 0 | AB15: 0 | AC15: 0 | AF15: A
A16: C00183 | B16: TONER XEROX 3140 / 3160 108R00909 2.5k CPT | C16: 5352137120065 | D16: 1 | E16: 5 | F16: 2 | G16: 5 | H16: 1 | I16: 1 | K16: 1 | L16: 2 | M16: 5 | N16: 2 | O16: 7 | P16: 1 | Q16: 0.0323 | R16: 0.1613 | S16: 0.058 | T16: 0.1613 | U16: 0.0333 | V16: 0.0323 | W16: 0 | X16: 0.042 | Y16: 0.0587 | Z16: 0.1852 | AA16: 0.0614 | AB16: 0.2029 | AC16: 0.0323 | AD16: 0.0857 | AE16: 0.0857 | AF16: A
A17: C00184 | B17: TONER SAMSUNG MLT-104S - CPT 1665/3200/3205 1.5K | C17: 5358125120055 | D17: 65 | E17: 75 | F17: 55 | G17: 33 | H17: 69 | I17: 38 | J17: 40 | K17: 40 | L17: 43 | M17: 72 | N17: 45 | O17: 64 | P17: 22 | Q17: 2.0968 | R17: 2.4194 | S17: 1.5942 | T17: 1.0645 | U17: 2.3 | V17: 1.2258 | W17: 1.6129 | X17: 1.6807 | Y17: 1.261 | Z17: 2.6667 | AA17: 1.3825 | AB17: 1.8551 | AC17: 0.7097 | AD17: 1.7633 | AE17: 1.7633 | AF17: A
A18: C00185 | B18: TONER KYOCERA TK-112/TK-110 CPT 6K | C18: 5361125120017 | Q18: 0 | R18: 0 | S18: 0 | T18: 0 | U18: 0 | V18: 0 | W18: 0 | X18: 0 | Y18: 0 | Z18: 0 | AA18: 0 | AB18: 0 | AC18: 0 | AF18: A
A19: C00186 | B19: TONER CANON FX9 CPT 2K | C19: 5358125120062 | Q19: 0 | R19: 0 | S19: 0 | T19: 0 | U19: 0 | V19: 0 | W19: 0 | X19: 0 | Y19: 0 | Z19: 0 | AA19: 0 | AB19: 0 | AC19: 0 | AF19: D
A20: C00187 | B20: TONER SAMSUNG 105L 2,5K CPT | C20: 5359137120019 | D20: 15 | E20: 6 | F20: 15 | G20: 6 | H20: 8 | I20: 3 | J20: 8 | K20: 3 | L20: 12 | M20: 5 | N20: 14 | O20: 28 | P20: 6 | Q20: 0.4839 | R20: 0.1935 | S20: 0.4348 | T20: 0.1935 | U20: 0.2667 | V20: 0.0968 | W20: 0.3226 | X20: 0.1261 | Y20: 0.3519 | Z20: 0.1852 | AA20: 0.4301 | AB20: 0.8116 | AC20: 0.1935 | AD20: 0.3247 | AE20: 0.3247 | AF20: A
A21: C00188 | B21: TONER HP CE278A 2.1K CPT | C21: 5350137120535 | Q21: 0 | R21: 0 | S21: 0 | T21: 0 | U21: 0 | V21: 0 | W21: 0 | X21: 0 | Y21: 0 | Z21: 0 | AA21: 0 | AB21: 0 | AC21: 0 | AF21: A
A22: C00189 | B22: TONER HP CE255X CPT 12.5K | C22: 5350137120528 | E22: 1 | F22: 3 | I22: 1 | M22: 3 | O22: 10 | P22: 2 | Q22: 0 | R22: 0.0323 | S22: 0.087 | T22: 0 | U22: 0 | V22: 0.0323 | W22: 0 | X22: 0 | Y22: 0 | Z22: 0.1111 | AA22: 0 | AB22: 4.3478 | AC22: 2 | AD22: 0.0239 | AE22: 0.0239 | AF22: A
A23: C00190 | B23: TONER BROTHER TN-450/2250 CPT 2.5K | C23: 5353125120036 | D23: 48 | E23: 45 | F23: 93 | G23: 50 | H23: 29 | I23: 243 | J23: 46 | K23: -44 | L23: 74 | M23: 75 | N23: 49 | O23: 57 | P23: 18 | Q23: 1.5484 | R23: 1.4516 | S23: 2.6957 | T23: 1.6129 | U23: 0.9667 | V23: 7.8387 | W23: 1.8548 | X23: -1.8487 | Y23: 2.1701 | Z23: 2.7778 | AA23: 1.5054 | AB23: 1.6522 | AC23: 0.5806 | AD23: 2.0188 | AE23: 2.0188 | AF23: A
A24: C00191 | B24: TONER BROTHER TN-650 CPT 8K | Q24: 0 | R24: 0 | S24: 0 | T24: 0 | U24: 0 | V24: 0 | W24: 0 | X24: 0 | Y24: 0 | Z24: 0 | AA24: 0 | AB24: 0 | AC24: 0 | AF24: D
A25: C00192 | B25: TONER SAMSUNG CLP-409 BK CPT 1.5K | C25: 5358137120104 | Q25: 0 | R25: 0 | S25: 0 | T25: 0 | U25: 0 | V25: 0 | W25: 0 | X25: 0 | Y25: 0 | Z25: 0 | AA25: 0 | AB25: 0 | AC25: 0 | AF25: D
A26: C00193 | B26: TONER SAMSUNG CLP-409 CY CPT 1.0K | C26: 5358137120111 | Q26: 0 | R26: 0 | S26: 0 | T26: 0 | U26: 0 | V26: 0 | W26: 0 | X26: 0 | Y26: 0 | Z26: 0 | AA26: 0 | AB26: 0 | AC26: 0 | AF26: D
A27: C00194 | B27: TONER SAMSUNG CLP-409 MG CPT 1.0K | C27: 5358137120128 | Q27: 0 | R27: 0 | S27: 0 | T27: 0 | U27: 0 | V27: 0 | W27: 0 | X27: 0 | Y27: 0 | Z27: 0 | AA27: 0 | AB27: 0 | AC27: 0 | AF27: D
A28: C00195 | B28: TONER SAMSUNG CLP-409 YE CPT 1.0K | C28: 5358137120135 | Q28: 0 | R28: 0 | S28: 0 | T28: 0 | U28: 0 | V28: 0 | W28: 0 | X28: 0 | Y28: 0 | Z28: 0 | AA28: 0 | AB28: 0 | AC28: 0 | AF28: D
A29: C00196 | B29: TONER SAMSUNG CLT-407/409S BK CPT 1.5K | C29: 5358137120142 | Q29: 0 | R29: 0 | S29: 0 | T29: 0 | U29: 0 | V29: 0 | W29: 0 | X29: 0 | Y29: 0 | Z29: 0 | AA29: 0 | AB29: 0 | AC29: 0 | AF29: A
A30: C00197 | B30: TONER SAMSUNG CLT-407/409S CY CPT 1.0K | C30: 5358137120159 | Q30: 0 | R30: 0 | S30: 0 | T30: 0 | U30: 0 | V30: 0 | W30: 0 | X30: 0 | Y30: 0 | Z30: 0 | AA30: 0 | AB30: 0 | AC30: 0 | AF30: A
A31: C00198 | B31: TONER SAMSUNG CLT-407/409S MG CPT 1.0K | C31: 5358137120166 | Q31: 0 | R31: 0 | S31: 0 | T31: 0 | U31: 0 | V31: 0 | W31: 0 | X31: 0 | Y31: 0 | Z31: 0 | AA31: 0 | AB31: 0 | AC31: 0 | AF31: A
A32: C00199 | B32: TONER SAMSUNG CLT-407/409S YE CPT 1.0K | C32: 5358137120173 | Q32: 0 | R32: 0 | S32: 0 | T32: 0 | U32: 0 | V32: 0 | W32: 0 | X32: 0 | Y32: 0 | Z32: 0 | AA32: 0 | AB32: 0 | AC32: 0 | AF32: A
A33: C00200 | B33: TONER HP CB540A (128A) /CE320A/CF210X BK 2.2K CPT | C33: 5350137120566 | D33: 3 | E33: 2 | F33: 1 | G33: 1 | H33: 1 | I33: 2 | K33: 2 | L33: 1 | Q33: 0.0968 | R33: 0.1176 | S33: 0 | T33: 0.0625 | U33: 0.0333 | V33: 0.0645 | W33: 0 | X33: 0.084 | Y33: 0.0293 | Z33: 0 | AA33: 0 | AB33: 0 | AC33: 0 | AD33: 0.0342 | AE33: 0.0342 | AF33: A
A34: C00201 | B34: TONER HP CB541A (128A) /CE321A/CF211A CY 1.4K CPT | C34: 5350137120573 | D34: 3 | E34: 4 | F34: 1 | G34: 1 | H34: 1 | K34: 2 | O34: 1 | Q34: 0.0968 | R34: 0.129 | S34: 0.029 | T34: 0.0323 | U34: 0.0333 | V34: 0 | W34: 0 | X34: 0.084 | Y34: 0 | Z34: 0 | AA34: 0 | AB34: 0.029 | AC34: 0 | AD34: 0.0361 | AE34: 0.0361 | AF34: A
A35: C00202 | B35: TONER HP CB542A (128A) /CE322A/CF212A YE 1.4K CPT | C35: 5350137120580 | D35: 5 | E35: 1 | G35: 1 | H35: 1 | K35: 1 | L35: 1 | O35: 1 | Q35: 0.4545 | R35: 0.0323 | S35: 0 | T35: 0.0323 | U35: 0.0333 | V35: 0 | W35: 0 | X35: 0.042 | Y35: 0.0293 | Z35: 0 | AA35: 0 | AB35: 0.029 | AC35: 0 | AD35: 0.018 | AE35: 0.018 | AF35: A
A36: C00203 | B36: TONER HP CB543A (128A) /CE323A/CF213A MG 1.4K CPT | C36: 5350137120597 | D36: 1 | E36: 1 | G36: 1 | H36: 1 | K36: 2 | L36: 1 | Q36: 0.0323 | R36: 0.0323 | S36: 0 | T36: 0.0323 | U36: 0.0333 | V36: 0 | W36: 0 | X36: 0.084 | Y36: 0.0293 | Z36: 0 | AA36: 0 | AB36: 0 | AC36: 0 | AD36: 0.0203 | AE36: 0.0203 | AF36: A
A37: C00204 | B37: TONER SAMSUNG D101/ML-2165 1.5K | C37: 5358137120180 | D37: 227 | E37: 163 | F37: 165 | G37: 124 | H37: 91 | I37: 114 | J37: 197 | K37: 111 | L37: 202 | M37: 145 | N37: 171 | O37: 170 | P37: 116 | Q37: 7.3226 | R37: 5.2581 | S37: 4.7826 | T37: 4 | U37: 3.0333 | V37: 3.6774 | W37: 7.9435 | X37: 4.6639 | Y37: 5.9238 | Z37: 5.3704 | AA37: 5.2535 | AB37: 4.9275 | AC37: 3.7419 | AD37: 5.1797 | AE37: 5.1797 | AF37: A
A38: C00205 | B38: TONER XEROX 3010/3040 CPT 2.2K 106R02182 | C38: 5352137120089 | F38: 3 | I38: 6 | L38: 1 | Q38: 0 | R38: 0 | S38: 0.087 | T38: 0 | U38: 0 | V38: 0.1935 | W38: 0 | X38: 0 | Y38: 0.0293 | Z38: 0 | AA38: 0 | AB38: 0 | AC38: 0 | AD38: 0.0258 | AE38: 0.0258 | AF38: A
A39: C00206 | B39: TONER BROTHER TN-750/3385/3380/3340 CPT 8K | C39: 5353137120055 | D39: 13 | E39: 7 | F39: 57 | G39: 5 | H39: 6 | I39: 13 | J39: 7 | K39: 31 | L39: -30 | M39: 25 | N39: 7 | O39: 17 | P39: 14 | Q39: 0.4194 | R39: 0.2258 | S39: 1.6522 | T39: 0.2941 | U39: 0.2 | V39: 0.4194 | W39: 0.2823 | X39: 1.3025 | Y39: -0.8798 | Z39: 0.9259 | AA39: 0.2151 | AB39: 0.4928 | AC39: 0.4516 | AD39: 0.4778 | AE39: 0.4778 | AF39: A
A40: C00207 | B40: TONER SAMSUNG ML2850 5.0K | C40: 5358137120197 | D40: 1 | E40: 18 | F40: 11 | G40: 13 | I40: 2 | J40: 2 | K40: 6 | L40: 4 | M40: 3 | N40: 1 | O40: 2 | P40: 2 | Q40: 0.0323 | R40: 0.5806 | S40: 0.3188 | T40: 0.4194 | U40: 0 | V40: 0.0645 | W40: 0.0806 | X40: 0.2521 | Y40: 0.1173 | Z40: 0.1111 | AA40: 0.0307 | AB40: 0.058 | AC40: 0.0645 | AD40: 0.1721 | AE40: 0.1721 | AF40: A
...

Sheet Compras
A1: Fecha Proxima Importacion | B1: 46313 | D1: Dias Pedido | E1: 180 | G1: Dias Duracion | H1: 90 | J1: Relacion Venta Marcas | K1: 7 | L1: 1
I3: S T O C K A L 18/10/2026 | AH3: S T O C K A L 16/01/2027
A4: Codigos Barras | B4: Descripcion | C4: Articulo.1 | D4: Articulo.2 | E4: Articulo.3 | F4: Stock Act.1 | G4: Stock Act.2 | H4: Stock Act.3 | I4: Arribo Prox. | J4: Dias Arribo | K4: Quiebre Stk.1 | L4: % Proteccion.1 | M4: Quiebre Stk.2 | N4: % Proteccion.2 | O4: Quiebre Stk.3 | P4: % Proteccion.3 | Q4: Suma Tot. Quiebre | R4: Pond. %Protecc. | S4: Pedir Artic.1 | T4: Confirmado Art.1 | U4: Pedir Artic.2 | V4: Confirmado Art.2 | W4: Pedir Artic.3 | X4: Confirmado Art.3 | Y4: Stk.Acumulado.1 | Z4: Stk.Acumulado.2 | AA4: Stk.Acumulado.3 | AB4: FOB U$S Art.1 | AC4: Prov. Cpa. Art.1 | AD4: FOB U$S Art.2 | AE4: Prov. Cpa. Art.2 | AF4: FOB U$S Art.3 | AG4: Prov. Cpa. Art.3 | AH4: Stk.Final.1 | AI4: % Proteccion.1 | AJ4: Stk.Final.2 | AK4: % Proteccion.2 | AL4: Stk.Final.3 | AM4: % Proteccion.3 | AN4: Suma Tot. Stk.Final | AO4: Pond. %Protecc. | AP4: Estado Art.1
A5: 5358125120017 | B5: TONER SAMSUNG CPT ML1610/2010/4521/X3117 3K Univ. | C5: C00159 | D5: E00159 | F5: 25 | I5: 46313 | J5: 81 | K5: =(F5-(0)+0-(J5*Ventas!AE2*1.0556)) | L5: =(K5/(Ventas!AE2*1.0556)/80) | M5: =(G5-(0)+0-(J5*Ventas!AE497*1.0556)) | N5: =(M5/(Ventas!AE497*1.0556)/85) | O5: =(H5+0) | Q5: =(K5+M5+O5) | R5: =(((L5*7)+(N5*1)+(P5*0))/8) | S5: =(180*(Ventas!AE2*0.9644) - IF(K5>0,K5,0)) | T5: =IF(S5>0,S5,0) | U5: =(180*(Ventas!AE497*0.9644) - IF(M5>0,M5,0)) | V5: =IF(U5>0,U5,0) | Y5: =IF(K5>0,K5+IF(T5>0,T5,0),T5) | Z5: =IF(M5>0,M5+IF(V5>0,V5,0),V5) | AB5: 4.25 | AC5: 3016 | AD5: 4.0598 | AH5: =(Y5-(90*Ventas!AE2*0.9644)) | AI5: =(AH5/(Ventas!AE2*0.9644)/80) | AJ5: =(Z5-(90*Ventas!AE497*0.9644)) | AK5: =(AJ5/(Ventas!AE497*0.9644)/85) | AN5: =(IF(AH5>0,AH5,0)+IF(AJ5>0,AJ5,0)+IF(AL5>0,AL5,0)) | AO5: =(((AI5*7)+(AK5*1)+(AM5*1))/8) | AP5: A
A6: 5350125120257 | B6: TONER HP Q2612A / CANON FX9 / FX10 2K CPT | C6: C00160 | D6: E00160 | F6: 44 | G6: 22 | I6: 46313 | J6: 81 | K6: =(F6-(0)+0-(J6*Ventas!AE3*1.0556)) | L6: =(K6/(Ventas!AE3*1.0556)/80) | M6: =(G6-(0)+0-(J6*Ventas!AE498*1.0556)) | N6: =(M6/(Ventas!AE498*1.0556)/85) | O6: =(H6+0) | Q6: =(K6+M6+O6) | R6: =(((L6*7)+(N6*1)+(P6*0))/8) | S6: =(180*(Ventas!AE3*0.9644) - IF(K6>0,K6,0)) | T6: =IF(S6>0,S6,0) | U6: =(180*(Ventas!AE498*0.9644) - IF(M6>0,M6,0)) | V6: =IF(U6>0,U6,0) | Y6: =IF(K6>0,K6+IF(T6>0,T6,0),T6) | Z6: =IF(M6>0,M6+IF(V6>0,V6,0),V6) | AB6: 2.3 | AC6: 3016 | AD6: 2.3 | AH6: =(Y6-(90*Ventas!AE3*0.9644)) | AI6: =(AH6/(Ventas!AE3*0.9644)/80) | AJ6: =(Z6-(90*Ventas!AE498*0.9644)) | AK6: =(AJ6/(Ventas!AE498*0.9644)/85) | AN6: =(IF(AH6>0,AH6,0)+IF(AJ6>0,AJ6,0)+IF(AL6>0,AL6,0)) | AO6: =(((AI6*7)+(AK6*1)+(AM6*1))/8) | AP6: A
A7: 5357125120133 | B7: TONER LEXMARK E120 - 12018SL CPT 2K | C7: C00163 | D7: E00163 | F7: 9 | I7: 46313 | J7: 81 | K7: =(F7-(0)+0-(J7*Ventas!AE4*1.0556)) | M7: =(G7-(0)+0-(J7*Ventas!AE499*1.0556)) | O7: =(H7+0) | Q7: =(K7+M7+O7) | R7: =(((L7*7)+(N7*1)+(P7*0))/8) | S7: =(180*(Ventas!AE4*0.9644) - IF(K7>0,K7,0)) | T7: =IF(S7>0,S7,0) | U7: =(180*(Ventas!AE499*0.9644) - IF(M7>0,M7,0)) | V7: =IF(U7>0,U7,0) | Y7: =IF(K7>0,K7+IF(T7>0,T7,0),T7) | Z7: =IF(M7>0,M7+IF(V7>0,V7,0),V7) | AB7: 7.4265 | AC7: 3016 | AD7: 5.96 | AN7: =(IF(AH7>0,AH7,0)+IF(AJ7>0,AJ7,0)+IF(AL7>0,AL7,0)) | AO7: =(((AI7*7)+(AK7*1)+(AM7*1))/8) | AP7: A
A8: 5350125120127 | B8: TONER HP Q5949A / Q7553A 3K CPT | C8: C00164 | F8: 1 | I8: 46313 | J8: 81 | K8: =(F8-(0)+0-(J8*Ventas!AE5*1.0556)) | L8: =(K8/(Ventas!AE5*1.0556)/80) | M8: =(G8+0) | O8: =(H8+0) | Q8: =(K8+M8+O8) | R8: =(((L8*7)+(N8*1)+(P8*0))/8) | S8: =(180*(Ventas!AE5*0.9644) - IF(K8>0,K8,0)) | T8: =IF(S8>0,S8,0) | Y8: =IF(K8>0,K8+IF(T8>0,T8,0),T8) | AB8: 3.479 | AC8: 3016 | AH8: =(Y8-(90*Ventas!AE5*0.9644)) | AI8: =(AH8/(Ventas!AE5*0.9644)/80) | AN8: =(IF(AH8>0,AH8,0)+IF(AJ8>0,AJ8,0)+IF(AL8>0,AL8,0)) | AO8: =(((AI8*7)+(AK8*1)+(AM8*1))/8) | AP8: A
A9: 5350125120059 | B9: TONER HP C4092A/CANON EP-22 CPT 2.5K | C9: C00165 | D9: E00165 | I9: 46313 | J9: 81 | K9: =(F9-(0)+0-(J9*Ventas!AE6*1.0556)) | M9: =(G9-(0)+0-(J9*Ventas!AE500*1.0556)) | O9: =(H9+0) | Q9: =(K9+M9+O9) | R9: =(((L9*7)+(N9*1)+(P9*0))/8) | S9: =(180*(Ventas!AE6*0.9644) - IF(K9>0,K9,0)) | T9: =IF(S9>0,S9,0) | U9: =(180*(Ventas!AE500*0.9644) - IF(M9>0,M9,0)) | V9: =IF(U9>0,U9,0) | Y9: =IF(K9>0,K9+IF(T9>0,T9,0),T9) | Z9: =IF(M9>0,M9+IF(V9>0,V9,0),V9) | AB9: 5.445 | AC9: 3022 | AD9: 4.56 | AN9: =(IF(AH9>0,AH9,0)+IF(AJ9>0,AJ9,0)+IF(AL9>0,AL9,0)) | AO9: =(((AI9*7)+(AK9*1)+(AM9*1))/8) | AP9: A
A10: 5350125120400 | B10: TONER HP Q7553A 3K CPT | C10: C00166 | I10: 46313 | J10: 81 | K10: =(F10-(0)+0-(J10*Ventas!AE7*1.0556)) | M10: =(G10+0) | O10: =(H10+0) | Q10: =(K10+M10+O10) | R10: =(((L10*7)+(N10*1)+(P10*0))/8) | S10: =(180*(Ventas!AE7*0.9644) - IF(K10>0,K10,0)) | T10: =IF(S10>0,S10,0) | Y10: =IF(K10>0,K10+IF(T10>0,T10,0),T10) | AB10: 10.5 | AC10: 3002 | AN10: =(IF(AH10>0,AH10,0)+IF(AJ10>0,AJ10,0)+IF(AL10>0,AL10,0)) | AO10: =(((AI10*7)+(AK10*1)+(AM10*1))/8) | AP10: D
A11: 5352125120022 | B11: TONER XEROX 106R01271 BK 6110 CPT 2.0k | C11: C00174 | I11: 46313 | J11: 81 | K11: =(F11-(0)+0-(J11*Ventas!AE8*1.0556)) | M11: =(G11+0) | O11: =(H11+0) | Q11: =(K11+M11+O11) | R11: =(((L11*7)+(N11*1)+(P11*0))/8) | S11: =(180*(Ventas!AE8*0.9644) - IF(K11>0,K11,0)) | T11: =IF(S11>0,S11,0) | Y11: =IF(K11>0,K11+IF(T11>0,T11,0),T11) | AB11: 2.65 | AC11: 2998 | AN11: =(IF(AH11>0,AH11,0)+IF(AJ11>0,AJ11,0)+IF(AL11>0,AL11,0)) | AO11: =(((AI11*7)+(AK11*1)+(AM11*1))/8) | AP11: A
A12: 5352125120039 | B12: TONER XEROX 106R01272 CY 6110 CPT 1.0k | C12: C00175 | F12: 3 | I12: 46313 | J12: 81 | K12: =(F12-(0)+0-(J12*Ventas!AE9*1.0556)) | M12: =(G12+0) | O12: =(H12+0) | Q12: =(K12+M12+O12) | R12: =(((L12*7)+(N12*1)+(P12*0))/8) | S12: =(180*(Ventas!AE9*0.9644) - IF(K12>0,K12,0)) | T12: =IF(S12>0,S12,0) | Y12: =IF(K12>0,K12+IF(T12>0,T12,0),T12) | AB12: 2.65 | AC12: 2998 | AN12: =(IF(AH12>0,AH12,0)+IF(AJ12>0,AJ12,0)+IF(AL12>0,AL12,0)) | AO12: =(((AI12*7)+(AK12*1)+(AM12*1))/8) | AP12: A
A13: 5352125120046 | B13: TONER XEROX 106R01273 MG 6110 CPT 1.0K | C13: C00176 | F13: 3 | I13: 46313 | J13: 81 | K13: =(F13-(0)+0-(J13*Ventas!AE10*1.0556)) | M13: =(G13+0) | O13: =(H13+0) | Q13: =(K13+M13+O13) | R13: =(((L13*7)+(N13*1)+(P13*0))/8) | S13: =(180*(Ventas!AE10*0.9644) - IF(K13>0,K13,0)) | T13: =IF(S13>0,S13,0) | Y13: =IF(K13>0,K13+IF(T13>0,T13,0),T13) | AB13: 2.65 | AC13: 2998 | AN13: =(IF(AH13>0,AH13,0)+IF(AJ13>0,AJ13,0)+IF(AL13>0,AL13,0)) | AO13: =(((AI13*7)+(AK13*1)+(AM13*1))/8) | AP13: A
A14: 5352125120053 | B14: TONER XEROX 106R01274 YE 6110 CPT 1.0K | C14: C00177 | F14: 1 | I14: 46313 | J14: 81 | K14: =(F14-(0)+0-(J14*Ventas!AE11*1.0556)) | M14: =(G14+0) | O14: =(H14+0) | Q14: =(K14+M14+O14) | R14: =(((L14*7)+(N14*1)+(P14*0))/8) | S14: =(180*(Ventas!AE11*0.9644) - IF(K14>0,K14,0)) | T14: =IF(S14>0,S14,0) | Y14: =IF(K14>0,K14+IF(T14>0,T14,0),T14) | AB14: 2.65 | AC14: 2998 | AN14: =(IF(AH14>0,AH14,0)+IF(AJ14>0,AJ14,0)+IF(AL14>0,AL14,0)) | AO14: =(((AI14*7)+(AK14*1)+(AM14*1))/8) | AP14: A
A15: 5353137120017 | B15: TONER BROTHER TN-360/TN-2115/2125 CPT 2.6K | C15: C00178 | D15: E00178 | F15: 69 | I15: 46313 | J15: 81 | K15: =(F15-(0)+0-(J15*Ventas!AE12*1.0556)) | L15: =(K15/(Ventas!AE12*1.0556)/80) | M15: =(G15-(0)+0-(J15*Ventas!AE501*1.0556)) | O15: =(H15+0) | Q15: =(K15+M15+O15) | R15: =(((L15*7)+(N15*1)+(P15*0))/8) | S15: =(180*(Ventas!AE12*0.9644) - IF(K15>0,K15,0)) | T15: =IF(S15>0,S15,0) | U15: =(180*(Ventas!AE501*0.9644) - IF(M15>0,M15,0)) | V15: =IF(U15>0,U15,0) | Y15: =IF(K15>0,K15+IF(T15>0,T15,0),T15) | Z15: =IF(M15>0,M15+IF(V15>0,V15,0),V15) | AB15: 2.75 | AC15: 3016 | AD15: 2.7788 | AH15: =(Y15-(90*Ventas!AE12*0.9644)) | AI15: =(AH15/(Ventas!AE12*0.9644)/80) | AN15: =(IF(AH15>0,AH15,0)+IF(AJ15>0,AJ15,0)+IF(AL15>0,AL15,0)) | AO15: =(((AI15*7)+(AK15*1)+(AM15*1))/8) | AP15: A
A16: 5353125120029 | B16: TONER BROTHER TN-580/TN-650 CPT 8K | C16: C00179 | F16: 57 | I16: 46313 | J16: 81 | K16: =(F16-(0)+0-(J16*Ventas!AE13*1.0556)) | L16: =(K16/(Ventas!AE13*1.0556)/80) | M16: =(G16+0) | O16: =(H16+0) | Q16: =(K16+M16+O16) | R16: =(((L16*7)+(N16*1)+(P16*0))/8) | S16: =(180*(Ventas!AE13*0.9644) - IF(K16>0,K16,0)) | T16: =IF(S16>0,S16,0) | Y16: =IF(K16>0,K16+IF(T16>0,T16,0),T16) | AB16: 3.3 | AC16: 3016 | AH16: =(Y16-(90*Ventas!AE13*0.9644)) | AI16: =(AH16/(Ventas!AE13*0.9644)/80) | AN16: =(IF(AH16>0,AH16,0)+IF(AJ16>0,AJ16,0)+IF(AL16>0,AL16,0)) | AO16: =(((AI16*7)+(AK16*1)+(AM16*1))/8) | AP16: A
B17: TONER OKIDATA 2500/ 2520 - CPT 2.2K | C17: C00181 | I17: 46313 | J17: 81 | K17: =(F17-(0)+0-(J17*Ventas!AE14*1.0556)) | M17: =(G17+0) | O17: =(H17+0) | Q17: =(K17+M17+O17) | R17: =(((L17*7)+(N17*1)+(P17*0))/8) | S17: =(180*(Ventas!AE14*0.9644) - IF(K17>0,K17,0)) | T17: =IF(S17>0,S17,0) | Y17: =IF(K17>0,K17+IF(T17>0,T17,0),T17) | AN17: =(IF(AH17>0,AH17,0)+IF(AJ17>0,AJ17,0)+IF(AL17>0,AL17,0)) | AO17: =(((AI17*7)+(AK17*1)+(AM17*1))/8) | AP17: D
A18: 5352125120060 | B18: TONER OKIDATA 6300 - CPT 10K | C18: C00182 | I18: 46313 | J18: 81 | K18: =(F18-(0)+0-(J18*Ventas!AE15*1.0556)) | M18: =(G18+0) | O18: =(H18+0) | Q18: =(K18+M18+O18) | R18: =(((L18*7)+(N18*1)+(P18*0))/8) | S18: =(180*(Ventas!AE15*0.9644) - IF(K18>0,K18,0)) | T18: =IF(S18>0,S18,0) | Y18: =IF(K18>0,K18+IF(T18>0,T18,0),T18) | AN18: =(IF(AH18>0,AH18,0)+IF(AJ18>0,AJ18,0)+IF(AL18>0,AL18,0)) | AO18: =(((AI18*7)+(AK18*1)+(AM18*1))/8) | AP18: A
A19: 5352137120065 | B19: TONER XEROX 3140 / 3160 108R00909 2.5k CPT | C19: C00183 | D19: E00183 | F19: 42 | I19: 46313 | J19: 81 | K19: =(F19-(0)+0-(J19*Ventas!AE16*1.0556)) | L19: =(K19/(Ventas!AE16*1.0556)/80) | M19: =(G19-(0)+0-(J19*Ventas!AE502*1.0556)) | O19: =(H19+0) | Q19: =(K19+M19+O19) | R19: =(((L19*7)+(N19*1)+(P19*0))/8) | S19: =(180*(Ventas!AE16*0.9644) - IF(K19>0,K19,0)) | T19: =IF(S19>0,S19,0) | U19: =(180*(Ventas!AE502*0.9644) - IF(M19>0,M19,0)) | V19: =IF(U19>0,U19,0) | Y19: =IF(K19>0,K19+IF(T19>0,T19,0),T19) | Z19: =IF(M19>0,M19+IF(V19>0,V19,0),V19) | AB19: 4.31 | AC19: 3016 | AH19: =(Y19-(90*Ventas!AE16*0.9644)) | AI19: =(AH19/(Ventas!AE16*0.9644)/80) | AN19: =(IF(AH19>0,AH19,0)+IF(AJ19>0,AJ19,0)+IF(AL19>0,AL19,0)) | AO19: =(((AI19*7)+(AK19*1)+(AM19*1))/8) | AP19: A
A20: 5361125120017 | B20: TONER KYOCERA TK-112/TK-110 CPT 6K | C20: C00185 | I20: 46313 | J20: 81 | K20: =(F20-(0)+0-(J20*Ventas!AE18*1.0556)) | M20: =(G20+0) | O20: =(H20+0) | Q20: =(K20+M20+O20) | R20: =(((L20*7)+(N20*1)+(P20*0))/8) | S20: =(180*(Ventas!AE18*0.9644) - IF(K20>0,K20,0)) | T20: =IF(S20>0,S20,0) | Y20: =IF(K20>0,K20+IF(T20>0,T20,0),T20) | AB20: 2.79 | AC20: 3022 | AN20: =(IF(AH20>0,AH20,0)+IF(AJ20>0,AJ20,0)+IF(AL20>0,AL20,0)) | AO20: =(((AI20*7)+(AK20*1)+(AM20*1))/8) | AP20: A
A21: 5358125120062 | B21: TONER CANON FX9 CPT 2K | C21: C00186 | I21: 46313 | J21: 81 | K21: =(F21-(0)+0-(J21*Ventas!AE19*1.0556)) | M21: =(G21+0) | O21: =(H21+0) | Q21: =(K21+M21+O21) | R21: =(((L21*7)+(N21*1)+(P21*0))/8) | S21: =(180*(Ventas!AE19*0.9644) - IF(K21>0,K21,0)) | T21: =IF(S21>0,S21,0) | Y21: =IF(K21>0,K21+IF(T21>0,T21,0),T21) | AB21: 7.3 | AC21: 3011 | AN21: =(IF(AH21>0,AH21,0)+IF(AJ21>0,AJ21,0)+IF(AL21>0,AL21,0)) | AO21: =(((AI21*7)+(AK21*1)+(AM21*1))/8) | AP21: D
A22: 5359137120019 | B22: TONER SAMSUNG 105L 2,5K CPT | C22: C00187 | D22: E00187 | F22: 19 | G22: 12 | I22: 46313 | J22: 81 | K22: =(F22-(0)+0-(J22*Ventas!AE20*1.0556)) | L22: =(K22/(Ventas!AE20*1.0556)/80) | M22: =(G22-(0)+0-(J22*Ventas!AE504*1.0556)) | N22: =(M22/(Ventas!AE504*1.0556)/85) | O22: =(H22+0) | Q22: =(K22+M22+O22) | R22: =(((L22*7)+(N22*1)+(P22*0))/8) | S22: =(180*(Ventas!AE20*0.9644) - IF(K22>0,K22,0)) | T22: =IF(S22>0,S22,0) | U22: =(180*(Ventas!AE504*0.9644) - IF(M22>0,M22,0)) | V22: =IF(U22>0,U22,0) | Y22: =IF(K22>0,K22+IF(T22>0,T22,0),T22) | Z22: =IF(M22>0,M22+IF(V22>0,V22,0),V22) | AB22: 4.3 | AC22: 3016 | AD22: 4.3 | AH22: =(Y22-(90*Ventas!AE20*0.9644)) | AI22: =(AH22/(Ventas!AE20*0.9644)/80) | AJ22: =(Z22-(90*Ventas!AE504*0.9644)) | AK22: =(AJ22/(Ventas!AE504*0.9644)/85) | AN22: =(IF(AH22>0,AH22,0)+IF(AJ22>0,AJ22,0)+IF(AL22>0,AL22,0)) | AO22: =(((AI22*7)+(AK22*1)+(AM22*1))/8) | AP22: A
A23: 5350137120535 | B23: TONER HP CE278A 2.1K CPT | C23: C00188 | I23: 46313 | J23: 81 | K23: =(F23-(0)+0-(J23*Ventas!AE21*1.0556)) | M23: =(G23+0) | O23: =(H23+0) | Q23: =(K23+M23+O23) | R23: =(((L23*7)+(N23*1)+(P23*0))/8) | S23: =(180*(Ventas!AE21*0.9644) - IF(K23>0,K23,0)) | T23: =IF(S23>0,S23,0) | Y23: =IF(K23>0,K23+IF(T23>0,T23,0),T23) | AB23: 3 | AC23: 3013 | AN23: =(IF(AH23>0,AH23,0)+IF(AJ23>0,AJ23,0)+IF(AL23>0,AL23,0)) | AO23: =(((AI23*7)+(AK23*1)+(AM23*1))/8) | AP23: A
A24: 5350137120528 | B24: TONER HP CE255X CPT 12.5K | C24: C00189 | F24: 1 | I24: 46313 | J24: 81 | K24: =(F24-(0)+0-(J24*Ventas!AE22*1.0556)) | L24: =(K24/(Ventas!AE22*1.0556)/80) | M24: =(G24+0) | O24: =(H24+0) | Q24: =(K24+M24+O24) | R24: =(((L24*7)+(N24*1)+(P24*0))/8) | S24: =(180*(Ventas!AE22*0.9644) - IF(K24>0,K24,0)) | T24: =IF(S24>0,S24,0) | Y24: =IF(K24>0,K24+IF(T24>0,T24,0),T24) | AB24: 7.1 | AC24: 3016 | AH24: =(Y24-(90*Ventas!AE22*0.9644)) | AI24: =(AH24/(Ventas!AE22*0.9644)/80) | AN24: =(IF(AH24>0,AH24,0)+IF(AJ24>0,AJ24,0)+IF(AL24>0,AL24,0)) | AO24: =(((AI24*7)+(AK24*1)+(AM24*1))/8) | AP24: A
B25: TONER BROTHER TN-650 CPT 8K | C25: C00191 | I25: 46313 | J25: 81 | K25: =(F25-(0)+0-(J25*Ventas!AE24*1.0556)) | M25: =(G25+0) | O25: =(H25+0) | Q25: =(K25+M25+O25) | R25: =(((L25*7)+(N25*1)+(P25*0))/8) | S25: =(180*(Ventas!AE24*0.9644) - IF(K25>0,K25,0)) | T25: =IF(S25>0,S25,0) | Y25: =IF(K25>0,K25+IF(T25>0,T25,0),T25) | AB25: 6.55 | AC25: 2998 | AN25: =(IF(AH25>0,AH25,0)+IF(AJ25>0,AJ25,0)+IF(AL25>0,AL25,0)) | AO25: =(((AI25*7)+(AK25*1)+(AM25*1))/8) | AP25: D
A26: 5358137120104 | B26: TONER SAMSUNG CLP-409 BK CPT 1.5K | C26: C00192 | F26: 1 | I26: 46313 | J26: 81 | K26: =(F26-(0)+0-(J26*Ventas!AE25*1.0556)) | M26: =(G26+0) | O26: =(H26+0) | Q26: =(K26+M26+O26) | R26: =(((L26*7)+(N26*1)+(P26*0))/8) | S26: =(180*(Ventas!AE25*0.9644) - IF(K26>0,K26,0)) | T26: =IF(S26>0,S26,0) | Y26: =IF(K26>0,K26+IF(T26>0,T26,0),T26) | AB26: 13.8 | AC26: 3011 | AN26: =(IF(AH26>0,AH26,0)+IF(AJ26>0,AJ26,0)+IF(AL26>0,AL26,0)) | AO26: =(((AI26*7)+(AK26*1)+(AM26*1))/8) | AP26: D
A27: 5358137120111 | B27: TONER SAMSUNG CLP-409 CY CPT 1.0K | C27: C00193 | I27: 46313 | J27: 81 | K27: =(F27-(0)+0-(J27*Ventas!AE26*1.0556)) | M27: =(G27+0) | O27: =(H27+0) | Q27: =(K27+M27+O27) | R27: =(((L27*7)+(N27*1)+(P27*0))/8) | S27: =(180*(Ventas!AE26*0.9644) - IF(K27>0,K27,0)) | T27: =IF(S27>0,S27,0) | Y27: =IF(K27>0,K27+IF(T27>0,T27,0),T27) | AB27: 14.6 | AC27: 3002 | AN27: =(IF(AH27>0,AH27,0)+IF(AJ27>0,AJ27,0)+IF(AL27>0,AL27,0)) | AO27: =(((AI27*7)+(AK27*1)+(AM27*1))/8) | AP27: D
A28: 5358137120128 | B28: TONER SAMSUNG CLP-409 MG CPT 1.0K | C28: C00194 | I28: 46313 | J28: 81 | K28: =(F28-(0)+0-(J28*Ventas!AE27*1.0556)) | M28: =(G28+0) | O28: =(H28+0) | Q28: =(K28+M28+O28) | R28: =(((L28*7)+(N28*1)+(P28*0))/8) | S28: =(180*(Ventas!AE27*0.9644) - IF(K28>0,K28,0)) | T28: =IF(S28>0,S28,0) | Y28: =IF(K28>0,K28+IF(T28>0,T28,0),T28) | AB28: 14.6 | AC28: 3002 | AN28: =(IF(AH28>0,AH28,0)+IF(AJ28>0,AJ28,0)+IF(AL28>0,AL28,0)) | AO28: =(((AI28*7)+(AK28*1)+(AM28*1))/8) | AP28: D
A29: 5358137120135 | B29: TONER SAMSUNG CLP-409 YE CPT 1.0K | C29: C00195 | I29: 46313 | J29: 81 | K29: =(F29-(0)+0-(J29*Ventas!AE28*1.0556)) | M29: =(G29+0) | O29: =(H29+0) | Q29: =(K29+M29+O29) | R29: =(((L29*7)+(N29*1)+(P29*0))/8) | S29: =(180*(Ventas!AE28*0.9644) - IF(K29>0,K29,0)) | T29: =IF(S29>0,S29,0) | Y29: =IF(K29>0,K29+IF(T29>0,T29,0),T29) | AB29: 14.5 | AC29: 3011 | AN29: =(IF(AH29>0,AH29,0)+IF(AJ29>0,AJ29,0)+IF(AL29>0,AL29,0)) | AO29: =(((AI29*7)+(AK29*1)+(AM29*1))/8) | AP29: D
A30: 5358137120142 | B30: TONER SAMSUNG CLT-407/409S BK CPT 1.5K | C30: C00196 | I30: 46313 | J30: 81 | K30: =(F30-(0)+0-(J30*Ventas!AE29*1.0556)) | M30: =(G30+0) | O30: =(H30+0) | Q30: =(K30+M30+O30) | R30: =(((L30*7)+(N30*1)+(P30*0))/8) | S30: =(180*(Ventas!AE29*0.9644) - IF(K30>0,K30,0)) | T30: =IF(S30>0,S30,0) | Y30: =IF(K30>0,K30+IF(T30>0,T30,0),T30) | AB30: 7 | AC30: 2998 | AN30: =(IF(AH30>0,AH30,0)+IF(AJ30>0,AJ30,0)+IF(AL30>0,AL30,0)) | AO30: =(((AI30*7)+(AK30*1)+(AM30*1))/8) | AP30: A
A31: 5358137120159 | B31: TONER SAMSUNG CLT-407/409S CY CPT 1.0K | C31: C00197 | I31: 46313 | J31: 81 | K31: =(F31-(0)+0-(J31*Ventas!AE30*1.0556)) | M31: =(G31+0) | O31: =(H31+0) | Q31: =(K31+M31+O31) | R31: =(((L31*7)+(N31*1)+(P31*0))/8) | S31: =(180*(Ventas!AE30*0.9644) - IF(K31>0,K31,0)) | T31: =IF(S31>0,S31,0) | Y31: =IF(K31>0,K31+IF(T31>0,T31,0),T31) | AB31: 7.4 | AC31: 2998 | AN31: =(IF(AH31>0,AH31,0)+IF(AJ31>0,AJ31,0)+IF(AL31>0,AL31,0)) | AO31: =(((AI31*7)+(AK31*1)+(AM31*1))/8) | AP31: A
A32: 5358137120166 | B32: TONER SAMSUNG CLT-407/409S MG CPT 1.0K | C32: C00198 | I32: 46313 | J32: 81 | K32: =(F32-(0)+0-(J32*Ventas!AE31*1.0556)) | M32: =(G32+0) | O32: =(H32+0) | Q32: =(K32+M32+O32) | R32: =(((L32*7)+(N32*1)+(P32*0))/8) | S32: =(180*(Ventas!AE31*0.9644) - IF(K32>0,K32,0)) | T32: =IF(S32>0,S32,0) | Y32: =IF(K32>0,K32+IF(T32>0,T32,0),T32) | AB32: 7.4 | AC32: 2998 | AN32: =(IF(AH32>0,AH32,0)+IF(AJ32>0,AJ32,0)+IF(AL32>0,AL32,0)) | AO32: =(((AI32*7)+(AK32*1)+(AM32*1))/8) | AP32: A
A33: 5358137120173 | B33: TONER SAMSUNG CLT-407/409S YE CPT 1.0K | C33: C00199 | I33: 46313 | J33: 81 | K33: =(F33-(0)+0-(J33*Ventas!AE32*1.0556)) | M33: =(G33+0) | O33: =(H33+0) | Q33: =(K33+M33+O33) | R33: =(((L33*7)+(N33*1)+(P33*0))/8) | S33: =(180*(Ventas!AE32*0.9644) - IF(K33>0,K33,0)) | T33: =IF(S33>0,S33,0) | Y33: =IF(K33>0,K33+IF(T33>0,T33,0),T33) | AB33: 6.1 | AC33: 3013 | AN33: =(IF(AH33>0,AH33,0)+IF(AJ33>0,AJ33,0)+IF(AL33>0,AL33,0)) | AO33: =(((AI33*7)+(AK33*1)+(AM33*1))/8) | AP33: A
A34: 5350137120566 | B34: TONER HP CB540A (128A) /CE320A/CF210X BK 2.2K CPT | C34: C00200 | F34: 24 | I34: 46313 | J34: 81 | K34: =(F34-(0)+0-(J34*Ventas!AE33*1.0556)) | L34: =(K34/(Ventas!AE33*1.0556)/80) | M34: =(G34+0) | O34: =(H34+0) | Q34: =(K34+M34+O34) | R34: =(((L34*7)+(N34*1)+(P34*0))/8) | S34: =(180*(Ventas!AE33*0.9644) - IF(K34>0,K34,0)) | T34: =IF(S34>0,S34,0) | Y34: =IF(K34>0,K34+IF(T34>0,T34,0),T34) | AB34: 3.6 | AC34: 3016 | AH34: =(Y34-(90*Ventas!AE33*0.9644)) | AI34: =(AH34/(Ventas!AE33*0.9644)/80) | AN34: =(IF(AH34>0,AH34,0)+IF(AJ34>0,AJ34,0)+IF(AL34>0,AL34,0)) | AO34: =(((AI34*7)+(AK34*1)+(AM34*1))/8) | AP34: A
A35: 5350137120573 | B35: TONER HP CB541A (128A) /CE321A/CF211A CY 1.4K CPT | C35: C00201 | F35: 30 | I35: 46313 | J35: 81 | K35: =(F35-(0)+0-(J35*Ventas!AE34*1.0556)) | L35: =(K35/(Ventas!AE34*1.0556)/80) | M35: =(G35+0) | O35: =(H35+0) | Q35: =(K35+M35+O35) | R35: =(((L35*7)+(N35*1)+(P35*0))/8) | S35: =(180*(Ventas!AE34*0.9644) - IF(K35>0,K35,0)) | T35: =IF(S35>0,S35,0) | Y35: =IF(K35>0,K35+IF(T35>0,T35,0),T35) | AB35: 3.6 | AC35: 3016 | AH35: =(Y35-(90*Ventas!AE34*0.9644)) | AI35: =(AH35/(Ventas!AE34*0.9644)/80) | AN35: =(IF(AH35>0,AH35,0)+IF(AJ35>0,AJ35,0)+IF(AL35>0,AL35,0)) | AO35: =(((AI35*7)+(AK35*1)+(AM35*1))/8) | AP35: A
A36: 5350137120580 | B36: TONER HP CB542A (128A) /CE322A/CF212A YE 1.4K CPT | C36: C00202 | F36: 26 | I36: 46313 | J36: 81 | K36: =(F36-(0)+0-(J36*Ventas!AE35*1.0556)) | L36: =(K36/(Ventas!AE35*1.0556)/80) | M36: =(G36+0) | O36: =(H36+0) | Q36: =(K36+M36+O36) | R36: =(((L36*7)+(N36*1)+(P36*0))/8) | S36: =(180*(Ventas!AE35*0.9644) - IF(K36>0,K36,0)) | T36: =IF(S36>0,S36,0) | Y36: =IF(K36>0,K36+IF(T36>0,T36,0),T36) | AB36: 3.6 | AC36: 3016 | AH36: =(Y36-(90*Ventas!AE35*0.9644)) | AI36: =(AH36/(Ventas!AE35*0.9644)/80) | AN36: =(IF(AH36>0,AH36,0)+IF(AJ36>0,AJ36,0)+IF(AL36>0,AL36,0)) | AO36: =(((AI36*7)+(AK36*1)+(AM36*1))/8) | AP36: A
A37: 5350137120597 | B37: TONER HP CB543A (128A) /CE323A/CF213A MG 1.4K CPT | C37: C00203 | F37: 19 | I37: 46313 | J37: 81 | K37: =(F37-(0)+0-(J37*Ventas!AE36*1.0556)) | L37: =(K37/(Ventas!AE36*1.0556)/80) | M37: =(G37+0) | O37: =(H37+0) | Q37: =(K37+M37+O37) | R37: =(((L37*7)+(N37*1)+(P37*0))/8) | S37: =(180*(Ventas!AE36*0.9644) - IF(K37>0,K37,0)) | T37: =IF(S37>0,S37,0) | Y37: =IF(K37>0,K37+IF(T37>0,T37,0),T37) | AB37: 3.6 | AC37: 3016 | AH37: =(Y37-(90*Ventas!AE36*0.9644)) | AI37: =(AH37/(Ventas!AE36*0.9644)/80) | AN37: =(IF(AH37>0,AH37,0)+IF(AJ37>0,AJ37,0)+IF(AL37>0,AL37,0)) | AO37: =(((AI37*7)+(AK37*1)+(AM37*1))/8) | AP37: A
A38: 5352137120089 | B38: TONER XEROX 3010/3040 CPT 2.2K 106R02182 | C38: C00205 | F38: 43 | I38: 46313 | J38: 81 | K38: =(F38-(0)+0-(J38*Ventas!AE38*1.0556)) | L38: =(K38/(Ventas!AE38*1.0556)/80) | M38: =(G38+0) | O38: =(H38+0) | Q38: =(K38+M38+O38) | R38: =(((L38*7)+(N38*1)+(P38*0))/8) | S38: =(180*(Ventas!AE38*0.9644) - IF(K38>0,K38,0)) | T38: =IF(S38>0,S38,0) | Y38: =IF(K38>0,K38+IF(T38>0,T38,0),T38) | AB38: 2 | AC38: 3016 | AH38: =(Y38-(90*Ventas!AE38*0.9644)) | AI38: =(AH38/(Ventas!AE38*0.9644)/80) | AN38: =(IF(AH38>0,AH38,0)+IF(AJ38>0,AJ38,0)+IF(AL38>0,AL38,0)) | AO38: =(((AI38*7)+(AK38*1)+(AM38*1))/8) | AP38: A
A39: 5353137120055 | B39: TONER BROTHER TN-750/3385/3380/3340 CPT 8K | C39: C00206 | D39: E00206 | F39: 131 | I39: 46313 | J39: 81 | K39: =(F39-(0)+0-(J39*Ventas!AE39*1.0556)) | L39: =(K39/(Ventas!AE39*1.0556)/80) | M39: =(G39-(0)+0-(J39*Ventas!AE507*1.0556)) | O39: =(H39+0) | Q39: =(K39+M39+O39) | R39: =(((L39*7)+(N39*1)+(P39*0))/8) | S39: =(180*(Ventas!AE39*0.9644) - IF(K39>0,K39,0)) | T39: =IF(S39>0,S39,0) | U39: =(180*(Ventas!AE507*0.9644) - IF(M39>0,M39,0)) | V39: =IF(U39>0,U39,0) | Y39: =IF(K39>0,K39+IF(T39>0,T39,0),T39) | Z39: =IF(M39>0,M39+IF(V39>0,V39,0),V39) | AB39: 3.55 | AC39: 3016 | AD39: 4.03 | AH39: =(Y39-(90*Ventas!AE39*0.9644)) | AI39: =(AH39/(Ventas!AE39*0.9644)/80) | AN39: =(IF(AH39>0,AH39,0)+IF(AJ39>0,AJ39,0)+IF(AL39>0,AL39,0)) | AO39: =(((AI39*7)+(AK39*1)+(AM39*1))/8) | AP39: A
A40: 5358137120197 | B40: TONER SAMSUNG ML2850 5.0K | C40: C00207 | D40: E00207 | F40: 26 | I40: 46313 | J40: 81 | K40: =(F40-(0)+0-(J40*Ventas!AE40*1.0556)) | L40: =(K40/(Ventas!AE40*1.0556)/80) | M40: =(G40-(0)+0-(J40*Ventas!AE508*1.0556)) | O40: =(H40+0) | Q40: =(K40+M40+O40) | R40: =(((L40*7)+(N40*1)+(P40*0))/8) | S40: =(180*(Ventas!AE40*0.9644) - IF(K40>0,K40,0)) | T40: =IF(S40>0,S40,0) | U40: =(180*(Ventas!AE508*0.9644) - IF(M40>0,M40,0)) | V40: =IF(U40>0,U40,0) | Y40: =IF(K40>0,K40+IF(T40>0,T40,0),T40) | Z40: =IF(M40>0,M40+IF(V40>0,V40,0),V40) | AB40: 6 | AC40: 3016 | AH40: =(Y40-(90*Ventas!AE40*0.9644)) | AI40: =(AH40/(Ventas!AE40*0.9644)/80) | AN40: =(IF(AH40>0,AH40,0)+IF(AJ40>0,AJ40,0)+IF(AL40>0,AL40,0)) | AO40: =(((AI40*7)+(AK40*1)+(AM40*1))/8) | AP40: A
A41: 5350137120610 | B41: TAMBOR BROTHER DR-360 CPT 12K | C41: C00263 | F41: 21 | I41: 46313 | J41: 81 | K41: =(F41-(0)+0-(J41*Ventas!AE41*1.0556)) | L41: =(K41/(Ventas!AE41*1.0556)/80) | M41: =(G41+0) | O41: =(H41+0) | Q41: =(K41+M41+O41) | R41: =(((L41*7)+(N41*1)+(P41*0))/8) | S41: =(180*(Ventas!AE41*0.9644) - IF(K41>0,K41,0)) | T41: =IF(S41>0,S41,0) | Y41: =IF(K41>0,K41+IF(T41>0,T41,0),T41) | AB41: 3.5 | AC41: 3016 | AH41: =(Y41-(90*Ventas!AE41*0.9644)) | AI41: =(AH41/(Ventas!AE41*0.9644)/80) | AN41: =(IF(AH41>0,AH41,0)+IF(AJ41>0,AJ41,0)+IF(AL41>0,AL41,0)) | AO41: =(((AI41*7)+(AK41*1)+(AM41*1))/8) | AP41: A
...
