Workbook

Sheet Ventas
A1: Articulo | B1: Descripcion | C1: Codigos Barras | D1: Vta.Jul/25 | E1: Vta.Ago/25 | F1: Vta.Sep/25 | G1: Vta.Oct/25 | H1: Vta.Nov/25 | I1: Vta.Dic/25 | J1: Vta.Ene/26 | K1: Vta.Feb/26 | L1: Vta.Mar/26 | M1: Vta.Abr/26 | N1: Vta.May/26 | O1: Vta.Jun/26 | P1: Vta.Jul/26 | Q1: Jul/25 | R1: Ago/25 | S1: Sep/25 | T1: Oct/25 | U1: Nov/25 | V1: Dic/25 | W1: Ene/26 | X1: Feb/26 | Y1: Mar/26 | Z1: Abr/26 | AA1: May/26 | AB1: Jun/26 | AC1: Jul/26 | AD1: Rotacion DesEstac. | AE1: Rot. Manual | AF1: Estado Art. | AG1: SIN STOCK | AH1: SIN STOCK | AI1: TOT STK | AJ1: C/STK | AK1: VTA | AL1: DDSTK
A2: C00159 | B2: TONER SAMSUNG CPT ML1610/2010/4521/X3117 3K Univ. | C2: 5358125120017 | D2: 2 | E2: 3 | F2: 7 | G2: 4 | H2: 5 | J2: 6 | K2: 2 | L2: 5 | M2: 9 | N2: 4 | O2: 2 | Q2: 0.0645 | R2: 0.0968 | S2: 0.2029 | T2: 0.129 | U2: 0.1667 | V2: 0 | W2: 0.2419 | X2: 0.084 | Y2: 0.1466 | Z2: 0.3333 | AA2: 0.1229 | AB2: 0.058 | AC2: 0 | AD2: 0.1372 | AE2: =AVERAGE(V2:AB2) -> 0.14095714 | AF2: A | AG2: {=DIASQUIEBRE(Q2:AB2)} -> 0 | AH2: {=DiasMesesGris(Q2:AB2)} -> 0 | AI2: =AG2+AH2 -> 0 | AJ2: =360-AI2 -> 360 | AK2: =SUM(D2:O2) -> 49 | AL2: =IFERROR(AK2/AJ2,0) -> 0.13611111
A3: C00160 | B3: TONER HP Q2612A / CANON FX9 / FX10 2K CPT | C3: 5350125120257 | D3: 20 | E3: 16 | F3: 24 | G3: 13 | H3: 9 | I3: 13 | J3: 13 | K3: 8 | L3: 31 | M3: 14 | N3: 25 | O3: 29 | Q3: 0.6452 | R3: 0.5161 | S3: 0.6957 | T3: 0.4194 | U3: 0.3 | V3: 0.4194 | W3: 0.5242 | X3: 0.3361 | Y3: 0.9091 | Z3: 0.5185 | AA3: 0.768 | AB3: 0.8406 | AC3: 0 | AD3: 0.5744 | AE3: =AVERAGE(V3:AB3) -> 0.61655714 | AF3: A | AG3: {=DIASQUIEBRE(Q3:AB3)} -> 0 | AH3: {=DiasMesesGris(Q3:AB3)} -> 0 | AI3: =AG3+AH3 -> 0 | AJ3: =360-AI3 -> 360 | AK3: =SUM(D3:O3) -> 215 | AL3: =IFERROR(AK3/AJ3,0) -> 0.59722222
A4: C00163 | B4: TONER LEXMARK E120 - 12018SL CPT 2K | C4: 5357125120133 | Q4: 0 | R4: 0 | S4: 0 | T4: 0 | U4: 0 | V4: 0 | W4: 0 | X4: 0 | Y4: 0 | Z4: 0 | AA4: 0 | AB4: 0 | AC4: 0 | AE4: =AVERAGE(V4:AB4) -> 0 | AF4: A | AG4: {=DIASQUIEBRE(Q4:AB4)} -> 0 | AH4: {=DiasMesesGris(Q4:AB4)} -> 0 | AI4: =AG4+AH4 -> 0 | AJ4: =360-AI4 -> 360 | AK4: =SUM(D4:O4) -> 0 | AL4: =IFERROR(AK4/AJ4,0) -> 0
A5: C00164 | B5: TONER HP Q5949A / Q7553A 3K CPT | C5: 5350125120127 | D5: 1 | E5: 1 | G5: 1 | I5: 1 | J5: 1 | K5: 2 | M5: 3 | Q5: 0.0323 | R5: 0.0323 | S5: 0 | T5: 0.0323 | U5: 0 | V5: 0.0323 | W5: 0.0403 | X5: 0.084 | Y5: 0 | Z5: 0.1111 | AA5: 0 | AB5: 0 | AC5: 0 | AD5: 0.0304 | AE5: =AVERAGE(V5:AB5) -> 0.038242857 | AF5: A | AG5: {=DIASQUIEBRE(Q5:AB5)} -> 0 | AH5: {=DiasMesesGris(Q5:AB5)} -> 0 | AI5: =AG5+AH5 -> 0 | AJ5: =360-AI5 -> 360 | AK5: =SUM(D5:O5) -> 10 | AL5: =IFERROR(AK5/AJ5,0) -> 0.027777778
A6: C00165 | B6: TONER HP C4092A/CANON EP-22 CPT 2.5K | C6: 5350125120059 | E6: 2 | F6: 1 | Q6: 0 | R6: =E6/30 -> 0.066666667 | S6: 0 | T6: 0 | U6: 0 | V6: 0 | W6: 0 | X6: 0 | Y6: 0 | Z6: 0 | AA6: 0 | AB6: 0 | AC6: 0 | AE6: =AVERAGE(V6:AB6) -> 0 | AF6: A | AG6: {=DIASQUIEBRE(Q6:AB6)} -> 21 | AH6: {=DiasMesesGris(Q6:AB6)} -> 300 | AI6: =AG6+AH6 -> 321 | AJ6: =360-AI6 -> 39 | AK6: =SUM(D6:O6) -> 3 | AL6: =IFERROR(AK6/AJ6,0) -> 0.076923077
A7: C00166 | B7: TONER HP Q7553A 3K CPT | C7: 5350125120400 | Q7: 0 | R7: 0 | S7: 0 | T7: 0 | U7: 0 | V7: 0 | W7: 0 | X7: 0 | Y7: 0 | Z7: 0 | AA7: 0 | AB7: 0 | AC7: 0 | AE7: =AVERAGE(V7:AB7) -> 0 | AF7: D | AG7: {=DIASQUIEBRE(Q7:AB7)} -> 0 | AH7: {=DiasMesesGris(Q7:AB7)} -> 360 | AI7: =AG7+AH7 -> 360 | AJ7: =360-AI7 -> 0 | AK7: =SUM(D7:O7) -> 0 | AL7: =IFERROR(AK7/AJ7,0) -> 0
A8: C00174 | B8: TONER XEROX 106R01271 BK 6110 CPT 2.0k | C8: 5352125120022 | Q8: 0 | R8: 0 | S8: 0 | T8: 0 | U8: 0 | V8: 0 | W8: 0 | X8: 0 | Y8: 0 | Z8: 0 | AA8: 0 | AB8: 0 | AC8: 0 | AE8: =AVERAGE(V8:AB8) -> 0 | AF8: A | AG8: {=DIASQUIEBRE(Q8:AB8)} -> 0 | AH8: {=DiasMesesGris(Q8:AB8)} -> 360 | AI8: =AG8+AH8 -> 360 | AJ8: =360-AI8 -> 0 | AK8: =SUM(D8:O8) -> 0 | AL8: =IFERROR(AK8/AJ8,0) -> 0
A9: C00175 | B9: TONER XEROX 106R01272 CY 6110 CPT 1.0k | C9: 5352125120039 | N9: 2 | O9: -2 | Q9: 0 | R9: 0 | S9: 0 | T9: =G9/30 -> 0 | U9: 0 | V9: 0 | W9: 0 | X9: 0 | Y9: 0 | Z9: 0 | AA9: =N9/30 -> 0.066666667 | AB9: =O9/30 -> -0.066666667 | AC9: 0 | AE9: =AVERAGE(V9:AB9) -> 0 | AF9: A | AG9: {=DIASQUIEBRE(Q9:AB9)} -> 56 | AH9: {=DiasMesesGris(Q9:AB9)} -> 0 | AI9: =AG9+AH9 -> 56 | AJ9: =360-AI9 -> 304 | AK9: =SUM(D9:O9) -> 0 | AL9: =IFERROR(AK9/AJ9,0) -> 0
A10: C00176 | B10: TONER XEROX 106R01273 MG 6110 CPT 1.0K | C10: 5352125120046 | Q10: 0 | R10: 0 | S10: 0 | T10: 0 | U10: 0 | V10: 0 | W10: 0 | X10: 0 | Y10: 0 | Z10: 0 | AA10: 0 | AB10: 0 | AC10: 0 | AE10: =AVERAGE(V10:AB10) -> 0 | AF10: A | AG10: {=DIASQUIEBRE(Q10:AB10)} -> 0 | AH10: {=DiasMesesGris(Q10:AB10)} -> 0 | AI10: =AG10+AH10 -> 0 | AJ10: =360-AI10 -> 360 | AK10: =SUM(D10:O10) -> 0 | AL10: =IFERROR(AK10/AJ10,0) -> 0
A11: C00177 | B11: TONER XEROX 106R01274 YE 6110 CPT 1.0K | C11: 5352125120053 | Q11: 0 | R11: 0 | S11: 0 | T11: 0 | U11: 0 | V11: 0 | W11: 0 | X11: 0 | Y11: 0 | Z11: 0 | AA11: 0 | AB11: 0 | AC11: 0 | AE11: =AVERAGE(V11:AB11) -> 0 | AF11: A | AG11: {=DIASQUIEBRE(Q11:AB11)} -> 0 | AH11: {=DiasMesesGris(Q11:AB11)} -> 360 | AI11: =AG11+AH11 -> 360 | AJ11: =360-AI11 -> 0 | AK11: =SUM(D11:O11) -> 0 | AL11: =IFERROR(AK11/AJ11,0) -> 0
A12: C00178 | B12: TONER BROTHER TN-360/TN-2115/2125 CPT 2.6K | C12: 5353137120017 | D12: 14 | E12: 8 | F12: 6 | G12: 6 | H12: 15 | I12: 17 | K12: 6 | L12: 9 | M12: 6 | N12: 1 | O12: 13 | Q12: 0.4516 | R12: 0.2581 | S12: 0.1739 | T12: 0.1935 | U12: 0.5 | V12: 0.5484 | W12: 0 | X12: 0.2521 | Y12: 0.2639 | Z12: 0.2222 | AA12: 0.0307 | AB12: 0.3768 | AC12: 0 | AD12: 0.2726 | AE12: =AVERAGE(V12:AB12) -> 0.24201429 | AF12: A | AG12: {=DIASQUIEBRE(Q12:AB12)} -> 0 | AH12: {=DiasMesesGris(Q12:AB12)} -> 0 | AI12: =AG12+AH12 -> 0 | AJ12: =360-AI12 -> 360 | AK12: =SUM(D12:O12) -> 101 | AL12: =IFERROR(AK12/AJ12,0) -> 0.28055556
A13: C00179 | B13: TONER BROTHER TN-580/TN-650 CPT 8K | C13: 5353125120029 | D13: 12 | E13: 2 | F13: 2 | G13: 21 | H13: 4 | I13: 5 | J13: 4 | K13: 2 | L13: 3 | M13: 13 | N13: 14 | O13: 7 | Q13: 0.3871 | R13: 0.0645 | S13: 0.058 | T13: 0.6774 | U13: 0.1333 | V13: 0.1613 | W13: 0.1613 | X13: 0.084 | Y13: 0.088 | Z13: 0.4815 | AA13: 0.4301 | AB13: 0.2029 | AC13: 0 | AD13: 0.2441 | AE13: =AVERAGE(V13:AB13) -> 0.22987143 | AF13: A | AG13: {=DIASQUIEBRE(Q13:AB13)} -> 0 | AH13: {=DiasMesesGris(Q13:AB13)} -> 0 | AI13: =AG13+AH13 -> 0 | AJ13: =360-AI13 -> 360 | AK13: =SUM(D13:O13) -> 89 | AL13: =IFERROR(AK13/AJ13,0) -> 0.24722222
A14: C00181 | B14: TONER OKIDATA 2500/ 2520 - CPT 2.2K | Q14: 0 | R14: 0 | S14: 0 | T14: 0 | U14: 0 | V14: 0 | W14: 0 | X14: 0 | Y14: 0 | Z14: 0 | AA14: 0 | AB14: 0 | AC14: 0 | AE14: =AVERAGE(V14:AB14) -> 0 | AF14: D | AG14: {=DIASQUIEBRE(Q14:AB14)} -> 0 | AH14: {=DiasMesesGris(Q14:AB14)} -> 360 | AI14: =AG14+AH14 -> 360 | AJ14: =360-AI14 -> 0 | AK14: =SUM(D14:O14) -> 0 | AL14: =IFERROR(AK14/AJ14,0) -> 0
A15: C00182 | B15: TONER OKIDATA 6300 - CPT 10K | C15: 5352125120060 | Q15: 0 | R15: 0 | S15: 0 | T15: 0 | U15: 0 | V15: 0 | W15: 0 | X15: 0 | Y15: 0 | Z15: 0 | AA15: 0 | AB15: 0 | AC15: 0 | AE15: =AVERAGE(V15:AB15) -> 0 | AF15: A | AG15: {=DIASQUIEBRE(Q15:AB15)} -> 0 | AH15: {=DiasMesesGris(Q15:AB15)} -> 360 | AI15: =AG15+AH15 -> 360 | AJ15: =360-AI15 -> 0 | AK15: =SUM(D15:O15) -> 0 | AL15: =IFERROR(AK15/AJ15,0) -> 0
A16: C00183 | B16: TONER XEROX 3140 / 3160 108R00909 2.5k CPT | C16: 5352137120065 | D16: 1 | E16: 5 | F16: 2 | G16: 5 | H16: 1 | I16: 1 | K16: 1 | L16: 2 | M16: 5 | N16: 2 | O16: 7 | Q16: 0.0323 | R16: 0.1613 | S16: 0.058 | T16: 0.1613 | U16: 0.0333 | V16: 0.0323 | W16: 0 | X16: 0.042 | Y16: 0.0587 | Z16: 0.1852 | AA16: 0.0614 | AB16: 0.2029 | AC16: 0 | AD16: 0.0857 | AE16: =AVERAGE(V16:AB16) -> 0.083214286 | AF16: A | AG16: {=DIASQUIEBRE(Q16:AB16)} -> 0 | AH16: {=DiasMesesGris(Q16:AB16)} -> 0 | AI16: =AG16+AH16 -> 0 | AJ16: =360-AI16 -> 360 | AK16: =SUM(D16:O16) -> 32 | AL16: =IFERROR(AK16/AJ16,0) -> 0.088888889
A17: C00184 | B17: TONER SAMSUNG MLT-104S - CPT 1665/3200/3205 1.5K | C17: 5358125120055 | D17: 65 | E17: 75 | F17: 55 | G17: 33 | H17: 69 | I17: 38 | J17: 40 | K17: 40 | L17: 43 | M17: 72 | N17: 45 | O17: 64 | P17: 1 | Q17: 2.0968 | R17: 2.4194 | S17: 1.5942 | T17: 1.0645 | U17: 2.3 | V17: 1.2258 | W17: 1.6129 | X17: 1.6807 | Y17: 1.261 | Z17: 2.6667 | AA17: 1.3825 | AB17: 1.8551 | AC17: 0.0323 | AD17: 1.7633 | AE17: =AVERAGE(V17:AB17) -> 1.6692429 | AF17: A | AG17: {=DIASQUIEBRE(Q17:AB17)} -> 0 | AH17: {=DiasMesesGris(Q17:AB17)} -> 0 | AI17: =AG17+AH17 -> 0 | AJ17: =360-AI17 -> 360 | AK17: =SUM(D17:O17) -> 639 | AL17: =IFERROR(AK17/AJ17,0) -> 1.775
A18: C00185 | B18: TONER KYOCERA TK-112/TK-110 CPT 6K | C18: 5361125120017 | Q18: 0 | R18: 0 | S18: 0 | T18: 0 | U18: 0 | V18: 0 | W18: 0 | X18: 0 | Y18: 0 | Z18: 0 | AA18: 0 | AB18: 0 | AC18: 0 | AE18: =AVERAGE(V18:AB18) -> 0 | AF18: A | AG18: {=DIASQUIEBRE(Q18:AB18)} -> 0 | AH18: {=DiasMesesGris(Q18:AB18)} -> 360 | AI18: =AG18+AH18 -> 360 | AJ18: =360-AI18 -> 0 | AK18: =SUM(D18:O18) -> 0 | AL18: =IFERROR(AK18/AJ18,0) -> 0
A19: C00186 | B19: TONER CANON FX9 CPT 2K | C19: 5358125120062 | Q19: 0 | R19: 0 | S19: 0 | T19: 0 | U19: 0 | V19: 0 | W19: 0 | X19: 0 | Y19: 0 | Z19: 0 | AA19: 0 | AB19: 0 | AC19: 0 | AE19: =AVERAGE(V19:AB19) -> 0 | AF19: D | AG19: {=DIASQUIEBRE(Q19:AB19)} -> 0 | AH19: {=DiasMesesGris(Q19:AB19)} -> 360 | AI19: =AG19+AH19 -> 360 | AJ19: =360-AI19 -> 0 | AK19: =SUM(D19:O19) -> 0 | AL19: =IFERROR(AK19/AJ19,0) -> 0
A20: C00187 | B20: TONER SAMSUNG 105L 2,5K CPT | C20: 5359137120019 | D20: 15 | E20: 6 | F20: 15 | G20: 6 | H20: 8 | I20: 3 | J20: 8 | K20: 3 | L20: 12 | M20: 5 | N20: 14 | O20: 28 | Q20: 0.4839 | R20: 0.1935 | S20: 0.4348 | T20: 0.1935 | U20: 0.2667 | V20: 0.0968 | W20: 0.3226 | X20: 0.1261 | Y20: 0.3519 | Z20: 0.1852 | AA20: 0.4301 | AB20: 0.8116 | AC20: 0 | AD20: 0.3247 | AE20: =AVERAGE(V20:AB20) -> 0.33204286 | AF20: A | AG20: {=DIASQUIEBRE(Q20:AB20)} -> 0 | AH20: {=DiasMesesGris(Q20:AB20)} -> 0 | AI20: =AG20+AH20 -> 0 | AJ20: =360-AI20 -> 360 | AK20: =SUM(D20:O20) -> 123 | AL20: =IFERROR(AK20/AJ20,0) -> 0.34166667
A21: C00188 | B21: TONER HP CE278A 2.1K CPT | C21: 5350137120535 | Q21: 0 | R21: 0 | S21: 0 | T21: 0 | U21: 0 | V21: 0 | W21: 0 | X21: 0 | Y21: 0 | Z21: 0 | AA21: 0 | AB21: 0 | AC21: 0 | AE21: =AVERAGE(V21:AB21) -> 0 | AF21: A | AG21: {=DIASQUIEBRE(Q21:AB21)} -> 0 | AH21: {=DiasMesesGris(Q21:AB21)} -> 360 | AI21: =AG21+AH21 -> 360 | AJ21: =360-AI21 -> 0 | AK21: =SUM(D21:O21) -> 0 | AL21: =IFERROR(AK21/AJ21,0) -> 0
A22: C00189 | B22: TONER HP CE255X CPT 12.5K | C22: 5350137120528 | E22: 1 | F22: 3 | I22: 1 | M22: 3 | O22: 10 | Q22: 0 | R22: 0.0323 | S22: 0.087 | T22: 0 | U22: 0 | V22: 0.0323 | W22: 0 | X22: 0 | Y22: 0 | Z22: 0.1111 | AA22: 0 | AB22: =O22/30 -> 0.33333333 | AC22: 0 | AD22: 0.0239 | AE22: =AVERAGE(V22:AB22) -> 0.068104762 | AF22: A | AG22: {=DIASQUIEBRE(Q22:AB22)} -> 28 | AH22: {=DiasMesesGris(Q22:AB22)} -> 0 | AI22: =AG22+AH22 -> 28 | AJ22: =360-AI22 -> 332 | AK22: =SUM(D22:O22) -> 18 | AL22: =IFERROR(AK22/AJ22,0) -> 0.054216867
A23: C00190 | B23: TONER BROTHER TN-450/2250 CPT 2.5K | C23: 5353125120036 | D23: 48 | E23: 45 | F23: 93 | G23: 50 | H23: 29 | I23: 243 | J23: 46 | K23: -44 | L23: 74 | M23: 75 | N23: 49 | O23: 57 | Q23: 1.5484 | R23: 1.4516 | S23: 2.6957 | T23: 1.6129 | U23: 0.9667 | V23: 7.8387 | W23: 1.8548 | X23: -1.8487 | Y23: 2.1701 | Z23: 2.7778 | AA23: 1.5054 | AB23: 1.6522 | AC23: 0 | AD23: 2.0188 | AE23: =AVERAGE(V23:AB23) -> 2.2786143 | AF23: A | AG23: {=DIASQUIEBRE(Q23:AB23)} -> 0 | AH23: {=DiasMesesGris(Q23:AB23)} -> 0 | AI23: =AG23+AH23 -> 0 | AJ23: =360-AI23 -> 360 | AK23: =SUM(D23:O23) -> 765 | AL23: =IFERROR(AK23/AJ23,0) -> 2.125
A24: C00191 | B24: TONER BROTHER TN-650 CPT 8K | Q24: 0 | R24: 0 | S24: 0 | T24: 0 | U24: 0 | V24: 0 | W24: 0 | X24: 0 | Y24: 0 | Z24: 0 | AA24: 0 | AB24: 0 | AC24: 0 | AE24: =AVERAGE(V24:AB24) -> 0 | AF24: D | AG24: {=DIASQUIEBRE(Q24:AB24)} -> 0 | AH24: {=DiasMesesGris(Q24:AB24)} -> 360 | AI24: =AG24+AH24 -> 360 | AJ24: =360-AI24 -> 0 | AK24: =SUM(D24:O24) -> 0 | AL24: =IFERROR(AK24/AJ24,0) -> 0
A25: C00192 | B25: TONER SAMSUNG CLP-409 BK CPT 1.5K | C25: 5358137120104 | Q25: 0 | R25: 0 | S25: 0 | T25: 0 | U25: 0 | V25: 0 | W25: 0 | X25: 0 | Y25: 0 | Z25: 0 | AA25: 0 | AB25: 0 | AC25: 0 | AE25: =AVERAGE(V25:AB25) -> 0 | AF25: D | AG25: {=DIASQUIEBRE(Q25:AB25)} -> 0 | AH25: {=DiasMesesGris(Q25:AB25)} -> 360 | AI25: =AG25+AH25 -> 360 | AJ25: =360-AI25 -> 0 | AK25: =SUM(D25:O25) -> 0 | AL25: =IFERROR(AK25/AJ25,0) -> 0
A26: C00193 | B26: TONER SAMSUNG CLP-409 CY CPT 1.0K | C26: 5358137120111 | Q26: 0 | R26: 0 | S26: 0 | T26: 0 | U26: 0 | V26: 0 | W26: 0 | X26: 0 | Y26: 0 | Z26: 0 | AA26: 0 | AB26: 0 | AC26: 0 | AE26: =AVERAGE(V26:AB26) -> 0 | AF26: D | AG26: {=DIASQUIEBRE(Q26:AB26)} -> 0 | AH26: {=DiasMesesGris(Q26:AB26)} -> 360 | AI26: =AG26+AH26 -> 360 | AJ26: =360-AI26 -> 0 | AK26: =SUM(D26:O26) -> 0 | AL26: =IFERROR(AK26/AJ26,0) -> 0
A27: C00194 | B27: TONER SAMSUNG CLP-409 MG CPT 1.0K | C27: 5358137120128 | Q27: 0 | R27: 0 | S27: 0 | T27: 0 | U27: 0 | V27: 0 | W27: 0 | X27: 0 | Y27: 0 | Z27: 0 | AA27: 0 | AB27: 0 | AC27: 0 | AE27: =AVERAGE(V27:AB27) -> 0 | AF27: D | AG27: {=DIASQUIEBRE(Q27:AB27)} -> 0 | AH27: {=DiasMesesGris(Q27:AB27)} -> 360 | AI27: =AG27+AH27 -> 360 | AJ27: =360-AI27 -> 0 | AK27: =SUM(D27:O27) -> 0 | AL27: =IFERROR(AK27/AJ27,0) -> 0
A28: C00195 | B28: TONER SAMSUNG CLP-409 YE CPT 1.0K | C28: 5358137120135 | Q28: 0 | R28: 0 | S28: 0 | T28: 0 | U28: 0 | V28: 0 | W28: 0 | X28: 0 | Y28: 0 | Z28: 0 | AA28: 0 | AB28: 0 | AC28: 0 | AE28: =AVERAGE(V28:AB28) -> 0 | AF28: D | AG28: {=DIASQUIEBRE(Q28:AB28)} -> 0 | AH28: {=DiasMesesGris(Q28:AB28)} -> 360 | AI28: =AG28+AH28 -> 360 | AJ28: =360-AI28 -> 0 | AK28: =SUM(D28:O28) -> 0 | AL28: =IFERROR(AK28/AJ28,0) -> 0
A29: C00196 | B29: TONER SAMSUNG CLT-407/409S BK CPT 1.5K | C29: 5358137120142 | Q29: 0 | R29: 0 | S29: 0 | T29: 0 | U29: 0 | V29: 0 | W29: 0 | X29: 0 | Y29: 0 | Z29: 0 | AA29: 0 | AB29: 0 | AC29: 0 | AE29: =AVERAGE(V29:AB29) -> 0 | AF29: A | AG29: {=DIASQUIEBRE(Q29:AB29)} -> 0 | AH29: {=DiasMesesGris(Q29:AB29)} -> 360 | AI29: =AG29+AH29 -> 360 | AJ29: =360-AI29 -> 0 | AK29: =SUM(D29:O29) -> 0 | AL29: =IFERROR(AK29/AJ29,0) -> 0
A30: C00197 | B30: TONER SAMSUNG CLT-407/409S CY CPT 1.0K | C30: 5358137120159 | Q30: 0 | R30: 0 | S30: 0 | T30: 0 | U30: 0 | V30: 0 | W30: 0 | X30: 0 | Y30: 0 | Z30: 0 | AA30: 0 | AB30: 0 | AC30: 0 | AE30: =AVERAGE(V30:AB30) -> 0 | AF30: A | AG30: {=DIASQUIEBRE(Q30:AB30)} -> 0 | AH30: {=DiasMesesGris(Q30:AB30)} -> 360 | AI30: =AG30+AH30 -> 360 | AJ30: =360-AI30 -> 0 | AK30: =SUM(D30:O30) -> 0 | AL30: =IFERROR(AK30/AJ30,0) -> 0
A31: C00198 | B31: TONER SAMSUNG CLT-407/409S MG CPT 1.0K | C31: 5358137120166 | Q31: 0 | R31: 0 | S31: 0 | T31: 0 | U31: 0 | V31: 0 | W31: 0 | X31: 0 | Y31: 0 | Z31: 0 | AA31: 0 | AB31: 0 | AC31: 0 | AE31: =AVERAGE(V31:AB31) -> 0 | AF31: A | AG31: {=DIASQUIEBRE(Q31:AB31)} -> 0 | AH31: {=DiasMesesGris(Q31:AB31)} -> 360 | AI31: =AG31+AH31 -> 360 | AJ31: =360-AI31 -> 0 | AK31: =SUM(D31:O31) -> 0 | AL31: =IFERROR(AK31/AJ31,0) -> 0
A32: C00199 | B32: TONER SAMSUNG CLT-407/409S YE CPT 1.0K | C32: 5358137120173 | Q32: 0 | R32: 0 | S32: 0 | T32: 0 | U32: 0 | V32: 0 | W32: 0 | X32: 0 | Y32: 0 | Z32: 0 | AA32: 0 | AB32: 0 | AC32: 0 | AE32: =AVERAGE(V32:AB32) -> 0 | AF32: A | AG32: {=DIASQUIEBRE(Q32:AB32)} -> 0 | AH32: {=DiasMesesGris(Q32:AB32)} -> 360 | AI32: =AG32+AH32 -> 360 | AJ32: =360-AI32 -> 0 | AK32: =SUM(D32:O32) -> 0 | AL32: =IFERROR(AK32/AJ32,0) -> 0
A33: C00200 | B33: TONER HP CB540A (128A) /CE320A/CF210X BK 2.2K CPT | C33: 5350137120566 | D33: 3 | E33: 2 | F33: 1 | G33: 1 | H33: 1 | I33: 2 | K33: 2 | L33: 1 | Q33: 0.0968 | R33: =E33/30 -> 0.066666667 | S33: 0 | T33: =G33/30 -> 0.033333333 | U33: 0.0333 | V33: 0.0645 | W33: 0 | X33: 0.084 | Y33: 0.0293 | Z33: 0 | AA33: 0 | AB33: 0 | AC33: 0 | AD33: 0.0342 | AE33: =AVERAGE(V33:AB33) -> 0.0254 | AF33: A | AG33: {=DIASQUIEBRE(Q33:AB33)} -> 29 | AH33: {=DiasMesesGris(Q33:AB33)} -> 30 | AI33: =AG33+AH33 -> 59 | AJ33: =360-AI33 -> 301 | AK33: =SUM(D33:O33) -> 13 | AL33: =IFERROR(AK33/AJ33,0) -> 0.043189369
A34: C00201 | B34: TONER HP CB541A (128A) /CE321A/CF211A CY 1.4K CPT | C34: 5350137120573 | D34: 3 | E34: 4 | F34: 1 | G34: 1 | H34: 1 | K34: 2 | O34: 1 | Q34: 0.0968 | R34: 0.129 | S34: 0.029 | T34: 0.0323 | U34: 0.0333 | V34: 0 | W34: 0 | X34: 0.084 | Y34: 0 | Z34: 0 | AA34: 0 | AB34: 0.029 | AC34: 0 | AD34: 0.0361 | AE34: =AVERAGE(V34:AB34) -> 0.016142857 | AF34: A | AG34: {=DIASQUIEBRE(Q34:AB34)} -> 0 | AH34: {=DiasMesesGris(Q34:AB34)} -> 0 | AI34: =AG34+AH34 -> 0 | AJ34: =360-AI34 -> 360 | AK34: =SUM(D34:O34) -> 13 | AL34: =IFERROR(AK34/AJ34,0) -> 0.036111111
A35: C00202 | B35: TONER HP CB542A (128A) /CE322A/CF212A YE 1.4K CPT | C35: 5350137120580 | D35: 5 | E35: 1 | G35: 1 | H35: 1 | K35: 1 | L35: 1 | O35: 1 | Q35: =D35/30 -> 0.16666667 | R35: 0.0323 | S35: 0 | T35: 0.0323 | U35: 0.0333 | V35: 0 | W35: 0 | X35: 0.042 | Y35: 0.0293 | Z35: 0 | AA35: 0 | AB35: 0.029 | AC35: 0 | AD35: 0.018 | AE35: =AVERAGE(V35:AB35) -> 0.014328571 | AF35: A | AG35: {=DIASQUIEBRE(Q35:AB35)} -> 20 | AH35: {=DiasMesesGris(Q35:AB35)} -> 0 | AI35: =AG35+AH35 -> 20 | AJ35: =360-AI35 -> 340 | AK35: =SUM(D35:O35) -> 11 | AL35: =IFERROR(AK35/AJ35,0) -> 0.032352941
A36: C00203 | B36: TONER HP CB543A (128A) /CE323A/CF213A MG 1.4K CPT | C36: 5350137120597 | D36: 1 | E36: 1 | G36: 1 | H36: 1 | K36: 2 | L36: 1 | Q36: 0.0323 | R36: 0.0323 | S36: 0 | T36: 0.0323 | U36: 0.0333 | V36: 0 | W36: 0 | X36: 0.084 | Y36: 0.0293 | Z36: 0 | AA36: 0 | AB36: 0 | AC36: 0 | AD36: 0.0203 | AE36: =AVERAGE(V36:AB36) -> 0.016185714 | AF36: A | AG36: {=DIASQUIEBRE(Q36:AB36)} -> 0 | AH36: {=DiasMesesGris(Q36:AB36)} -> 0 | AI36: =AG36+AH36 -> 0 | AJ36: =360-AI36 -> 360 | AK36: =SUM(D36:O36) -> 7 | AL36: =IFERROR(AK36/AJ36,0) -> 0.019444444
A37: C00204 | B37: TONER SAMSUNG D101/ML-2165 1.5K | C37: 5358137120180 | D37: 227 | E37: 163 | F37: 165 | G37: 124 | H37: 91 | I37: 114 | J37: 197 | K37: 111 | L37: 202 | M37: 145 | N37: 171 | O37: 170 | P37: 1 | Q37: 7.3226 | R37: 5.2581 | S37: 4.7826 | T37: 4 | U37: 3.0333 | V37: 3.6774 | W37: 7.9435 | X37: 4.6639 | Y37: 5.9238 | Z37: 5.3704 | AA37: 5.2535 | AB37: 4.9275 | AC37: 0.0323 | AD37: 5.1797 | AE37: =AVERAGE(V37:AB37) -> 5.3942857 | AF37: A | AG37: {=DIASQUIEBRE(Q37:AB37)} -> 0 | AH37: {=DiasMesesGris(Q37:AB37)} -> 0 | AI37: =AG37+AH37 -> 0 | AJ37: =360-AI37 -> 360 | AK37: =SUM(D37:O37) -> 1880 | AL37: =IFERROR(AK37/AJ37,0) -> 5.2222222
A38: C00205 | B38: TONER XEROX 3010/3040 CPT 2.2K 106R02182 | C38: 5352137120089 | F38: 3 | I38: 6 | L38: 1 | Q38: 0 | R38: 0 | S38: 0.087 | T38: 0 | U38: 0 | V38: 0.1935 | W38: 0 | X38: 0 | Y38: 0.0293 | Z38: 0 | AA38: 0 | AB38: 0 | AC38: 0 | AD38: 0.0258 | AE38: =AVERAGE(V38:AB38) -> 0.031828571 | AF38: A | AG38: {=DIASQUIEBRE(Q38:AB38)} -> 0 | AH38: {=DiasMesesGris(Q38:AB38)} -> 0 | AI38: =AG38+AH38 -> 0 | AJ38: =360-AI38 -> 360 | AK38: =SUM(D38:O38) -> 10 | AL38: =IFERROR(AK38/AJ38,0) -> 0.027777778
A39: C00206 | B39: TONER BROTHER TN-750/3385/3380/3340 CPT 8K | C39: 5353137120055 | D39: 13 | E39: 7 | F39: 57 | G39: 5 | H39: 6 | I39: 13 | J39: 7 | K39: 31 | L39: -30 | M39: 25 | N39: 7 | O39: 17 | P39: 2 | Q39: 0.4194 | R39: 0.2258 | S39: 1.6522 | T39: 0.2941 | U39: 0.2 | V39: 0.4194 | W39: 0.2823 | X39: 1.3025 | Y39: -0.8798 | Z39: 0.9259 | AA39: 0.2151 | AB39: 0.4928 | AC39: 0.0645 | AD39: 0.4778 | AE39: =AVERAGE(V39:AB39) -> 0.39402857 | AF39: A | AG39: {=DIASQUIEBRE(Q39:AB39)} -> 14 | AH39: {=DiasMesesGris(Q39:AB39)} -> 0 | AI39: =AG39+AH39 -> 14 | AJ39: =360-AI39 -> 346 | AK39: =SUM(D39:O39) -> 158 | AL39: =IFERROR(AK39/AJ39,0) -> 0.4566474
A40: C00207 | B40: TONER SAMSUNG ML2850 5.0K | C40: 5358137120197 | D40: 1 | E40: 18 | F40: 11 | G40: 13 | I40: 2 | J40: 2 | K40: 6 | L40: 4 | M40: 3 | N40: 1 | O40: 2 | Q40: 0.0323 | R40: 0.5806 | S40: 0.3188 | T40: 0.4194 | U40: 0 | V40: 0.0645 | W40: 0.0806 | X40: 0.2521 | Y40: 0.1173 | Z40: 0.1111 | AA40: 0.0307 | AB40: 0.058 | AC40: 0 | AD40: 0.1721 | AE40: =AVERAGE(V40:AB40) -> 0.10204286 | AF40: A | AG40: {=DIASQUIEBRE(Q40:AB40)} -> 0 | AH40: {=DiasMesesGris(Q40:AB40)} -> 0 | AI40: =AG40+AH40 -> 0 | AJ40: =360-AI40 -> 360 | AK40: =SUM(D40:O40) -> 63 | AL40: =IFERROR(AK40/AJ40,0) -> 0.175
...

Sheet Compras
A1: Fecha Proxima Importacion | B1: 46313 | D1: Dias Pedido | E1: 180 | G1: Dias Duracion | H1: 90 | J1: Relacion Venta Marcas | K1: 7 | L1: 1 | AN1: REVISAR | AP1: REVISAR
AN2: PEDIDO | AP2: PEDIDO | AR2: in adv gra | AU2: in adv Eco
I3: I M P O R T A C I O N - 599 | AC3: S T O C K A L 18/10/2026 | BB3: S T O C K A L 16/01/2027
A4: Codigos Barras | B4: Descripcion | C4: Articulo.1 | D4: Articulo.2 | E4: Articulo.3 | F4: Stock Act.1 | G4: Stock Act.2 | H4: Stock Act.3 | I4: Arribo | J4: Dias Arribo. | K4: Quiebre Stk.1 | L4: % Proteccion.1 | M4: Quiebre Stk.2 | N4: % Proteccion.2 | O4: Quiebre Stk.3 | P4: % Proteccion.3 | Q4: Stk.Marca 1+2+3 | R4: Pedidos.1 | S4: Pedidos.2 | T4: Pedidos.3 | U4: Stk.Arribo.1 | V4: Stk.Arribo.2 | W4: Stk.Arribo.3 | X4: FOB Arribo.1 | Y4: FOB Arribo.2 | Z4: FOB Arribo.3 | AA4: UnidxEnv | AB4: Volumen | AC4: Arribo Prox. | AD4: Dias Arribo | AE4: Quiebre Stk.1 | AF4: % Proteccion.1 | AG4: Quiebre Stk.2 | AH4: % Proteccion.2 | AI4: Quiebre Stk.3 | AJ4: % Proteccion.3 | AK4: Suma Tot. Quiebre | AL4: Pond. %Protecc. | AM4: Pedir Artic.1 | AN4: Confirmado Art.1 | AO4: Pedir Artic.2 | AP4: Confirmado Art.2 | AQ4: Pedir Artic.3 | AR4: Confirmado Art.3 | AS4: Stk.Acumulado.1 | AT4: Stk.Acumulado.2 | AU4: Stk.Acumulado.3 | AV4: FOB U$S Art.1 | AW4: Prov. Cpa. Art.1 | AX4: FOB U$S Art.2 | AY4: Prov. Cpa. Art.2 | AZ4: FOB U$S Art.3 | BA4: Prov. Cpa. Art.3 | BB4: Stk.Final.1 | BC4: % Proteccion.1 | BD4: Stk.Final.2 | BE4: % Proteccion.2 | BF4: Stk.Final.3 | BG4: % Proteccion.3 | BH4: Suma Tot. Stk.Final | BI4: Pond. %Protecc. | BJ4: Estado Art.1
A5: 5358125120017 | B5: TONER SAMSUNG CPT ML1610/2010/4521/X3117 3K Univ. | C5: C00159 | D5: E00159 | F5: 27 | I5: 46221 | J5: 17 | K5: =(F5-(0)+0-(J5*Ventas!AE2*1)) -> 24.603729 | L5: =(K5/(Ventas!AE2*1)/80) -> 2.1818448 | M5: =(G5-(0)+0-(J5*Ventas!AE495*1)) -> 0 | N5: =(M5/(Ventas!AE495*1)/85) -> #DIV/0! | O5: =(H5+0) -> 0 | Q5: =(K5+M5+O5) -> 24.603729 | R5: 0 | S5: 0 | T5: 0 | U5: =IF(K5>0,K5+R5,R5) -> 24.603729 | V5: =IF(M5>0,M5+S5,S5) -> 0 | W5: =IF(O5>0,O5+T5,T5) -> 0 | AA5: 18 | AB5: 0.005566 | AC5: 46313 | AD5: 92 | AE5: =(IF(K5>0,K5+R5,R5)-(AD5*Ventas!AE2*1.0489)) -> 11.001533 | AF5: =(AE5/(Ventas!AE2*1.0489)/80) -> 0.9301266 | AG5: =(IF(M5>0,M5+S5,S5)-(AD5*Ventas!AE495*1.0489)) -> 0 | AH5: =(AG5/(Ventas!AE495*1.0489)/85) -> #DIV/0! | AI5: =(H5+0) -> 0 | AK5: =(AE5+AG5+AI5) -> 11.001533 | AL5: =(((AF5*7)+(AH5*1)+(AJ5*0))/8) -> #DIV/0! | AM5: =(180*(Ventas!AE2*0.9644) - IF(AE5>0,AE5,0)) -> 13.467499 | AN5: 10 | AO5: =(180*(Ventas!AE495*0.9644) - IF(AG5>0,AG5,0)) -> 0 | AP5: =IF(AO5>3,CEILING(AO5,5),0) -> 0 | AQ5: =(AN5+AP5)*AB5 -> 0.05566 | AR5: =_xlfn.XLOOKUP(C5,[1]Hoja2!$C$6:$C$24,[1]Hoja2!$D$6:$D$24,0,2,1) -> 0 | AS5: =IF(AE5>0,AE5+IF(AN5>0,AN5,0),AN5) -> 21.001533 | AT5: =IF(AG5>0,AG5+IF(AP5>0,AP5,0),AP5) -> 0 | AU5: =_xlfn.XLOOKUP(D5,[1]Hoja2!$E$6:$E$24,[1]Hoja2!$F$6:$F$24,0,2,1) -> 0 | AV5: 4.6 | AW5: 3016 | AX5: 0 | AZ5: =_xlfn.XLOOKUP(C5,[2]PI!$B$15:$B$99,[2]PI!$L$15:$L$99,0,2,1) -> 4.6 | BA5: =_xlfn.XLOOKUP(D5,[2]PI!$B$15:$B$99,[2]PI!$L$15:$L$99,0,2,1) -> 0 | BB5: =(AS5-(90*Ventas!AE2*0.9644)) -> 8.7670173 | BC5: =(BB5/(Ventas!AE2*0.9644)/80) -> 0.8061532 | BD5: =(AT5-(90*Ventas!AE495*0.9644)) -> 0 | BE5: =(BD5/(Ventas!AE495*0.9644)/85) -> #DIV/0! | BH5: =(IF(BB5>0,BB5,0)+IF(BD5>0,BD5,0)+IF(BF5>0,BF5,0)) -> 8.7670173 | BI5: =(((BC5*7)+(BE5*1)+(BG5*1))/8) -> #DIV/0! | BJ5: A | BK5: =AV5*AN5+AP5*AX5 -> 46 | BL5: =(AN5)*AZ5+AP5*BA5 -> 46
A6: 5350125120257 | B6: TONER HP Q2612A / CANON FX9 / FX10 2K CPT | C6: C00160 | D6: E00160 | F6: 40 | G6: 22 | I6: 46221 | J6: 17 | K6: =(F6-(0)+0-(J6*Ventas!AE3*1)) -> 29.518529 | L6: =(K6/(Ventas!AE3*1)/80) -> 0.59845484 | M6: =(G6-(0)+0-(J6*Ventas!AE496*1)) -> 22 | N6: =(M6/(Ventas!AE496*1)/85) -> #DIV/0! | O6: =(H6+0) -> 0 | Q6: =(K6+M6+O6) -> 51.518529 | R6: 30 | S6: 0 | T6: 0 | U6: =IF(K6>0,K6+R6,R6) -> 59.518529 | V6: =IF(M6>0,M6+S6,S6) -> 22 | W6: =IF(O6>0,O6+T6,T6) -> 0 | X6: 2.3 | AA6: 20 | AB6: 0.003564 | AC6: 46313 | AD6: 92 | AE6: =(IF(K6>0,K6+R6,R6)-(AD6*Ventas!AE3*1.0489)) -> 0.021504154 | AF6: =(AE6/(Ventas!AE3*1.0489)/80) -> 0.0004156473 | AG6: =(IF(M6>0,M6+S6,S6)-(AD6*Ventas!AE496*1.0489)) -> 22 | AH6: =(AG6/(Ventas!AE496*1.0489)/85) -> #DIV/0! | AI6: =(H6+0) -> 0 | AK6: =(AE6+AG6+AI6) -> 22.021504 | AL6: =(((AF6*7)+(AH6*1)+(AJ6*0))/8) -> #DIV/0! | AM6: =(180*(Ventas!AE3*0.9644) - IF(AE6>0,AE6,0)) -> 107.00788 | AN6: =IF(AM6>3,CEILING(AM6+AO6,5),0) -> 90 | AO6: =(180*(Ventas!AE496*0.9644) - IF(AG6>0,AG6,0)) -> -22 | AP6: =IF(AO6>3,CEILING(AO6,5),0) -> 0 | AQ6: =(AN6+AP6)*AB6 -> 0.32076 | AR6: =_xlfn.XLOOKUP(C6,[1]Hoja2!$C$6:$C$24,[1]Hoja2!$D$6:$D$24,0,2,1) -> 0 | AS6: =IF(AE6>0,AE6+IF(AN6>0,AN6,0),AN6) -> 90.021504 | AT6: =IF(AG6>0,AG6+IF(AP6>0,AP6,0),AP6) -> 22 | AU6: =_xlfn.XLOOKUP(D6,[1]Hoja2!$E$6:$E$24,[1]Hoja2!$F$6:$F$24,0,2,1) -> 0 | AV6: 2.3 | AW6: 3016 | AX6: 0 | AZ6: =_xlfn.XLOOKUP(C6,[2]PI!$B$15:$B$99,[2]PI!$L$15:$L$99,0,2,1) -> 2.3 | BA6: =_xlfn.XLOOKUP(D6,[2]PI!$B$15:$B$99,[2]PI!$L$15:$L$99,0,2,1) -> 0 | BB6: =(AS6-(90*Ventas!AE3*0.9644)) -> 36.50681 | BC6: =(BB6/(Ventas!AE3*0.9644)/80) -> 0.76745579 | BD6: =(AT6-(90*Ventas!AE496*0.9644)) -> 22 | BE6: =(BD6/(Ventas!AE496*0.9644)/85) -> #DIV/0! | BH6: =(IF(BB6>0,BB6,0)+IF(BD6>0,BD6,0)+IF(BF6>0,BF6,0)) -> 58.50681 | BI6: =(((BC6*7)+(BE6*1)+(BG6*1))/8) -> #DIV/0! | BJ6: A | BK6: =AV6*AN6+AP6*AX6 -> 207 | BL6: =(AN6)*AZ6+AP6*BA6 -> 207
A7: 5357125120133 | B7: TONER LEXMARK E120 - 12018SL CPT 2K | C7: C00163 | D7: E00163 | F7: 9 | I7: 46221 | J7: 17 | K7: =(F7-(0)+0-(J7*Ventas!AE4*1)) -> 9 | M7: =(G7-(0)+0-(J7*Ventas!AE497*1)) -> 0 | O7: =(H7+0) -> 0 | Q7: =(K7+M7+O7) -> 9 | R7: 0 | S7: 0 | T7: 0 | U7: =IF(K7>0,K7+R7,R7) -> 9 | V7: =IF(M7>0,M7+S7,S7) -> 0 | W7: =IF(O7>0,O7+T7,T7) -> 0 | AA7: 18 | AB7: 0.005566 | AC7: 46313 | AD7: 92 | AE7: =(IF(K7>0,K7+R7,R7)-(AD7*Ventas!AE4*1.0489)) -> 9 | AG7: =(IF(M7>0,M7+S7,S7)-(AD7*Ventas!AE497*1.0489)) -> 0 | AI7: =(H7+0) -> 0 | AK7: =(AE7+AG7+AI7) -> 9 | AL7: =(((AF7*7)+(AH7*1)+(AJ7*0))/8) -> 0 | AM7: =(180*(Ventas!AE4*0.9644) - IF(AE7>0,AE7,0)) -> -9 | AN7: =IF(AM7>3,CEILING(AM7,5),0) -> 0 | AO7: =(180*(Ventas!AE497*0.9644) - IF(AG7>0,AG7,0)) -> 0 | AP7: =IF(AO7>3,CEILING(AO7,5),0) -> 0 | AQ7: =(AN7+AP7)*AB7 -> 0 | AR7: =_xlfn.XLOOKUP(C7,[1]Hoja2!$C$6:$C$24,[1]Hoja2!$D$6:$D$24,0,2,1) -> 0 | AS7: =IF(AE7>0,AE7+IF(AN7>0,AN7,0),AN7) -> 9 | AT7: =IF(AG7>0,AG7+IF(AP7>0,AP7,0),AP7) -> 0 | AU7: =_xlfn.XLOOKUP(D7,[1]Hoja2!$E$6:$E$24,[1]Hoja2!$F$6:$F$24,0,2,1) -> 0 | AV7: 0 | AW7: 3016 | AX7: 0 | AZ7: =_xlfn.XLOOKUP(C7,[2]PI!$B$15:$B$99,[2]PI!$L$15:$L$99,0,2,1) -> 0 | BA7: =_xlfn.XLOOKUP(D7,[2]PI!$B$15:$B$99,[2]PI!$L$15:$L$99,0,2,1) -> 0 | BH7: =(IF(BB7>0,BB7,0)+IF(BD7>0,BD7,0)+IF(BF7>0,BF7,0)) -> 0 | BI7: =(((BC7*7)+(BE7*1)+(BG7*1))/8) -> 0 | BJ7: A | BK7: =AV7*AN7+AP7*AX7 -> 0 | BL7: =(AN7)*AZ7+AP7*BA7 -> 0
A8: 5350125120127 | B8: TONER HP Q5949A / Q7553A 3K CPT | C8: C00164 | F8: 9 | I8: 46221 | J8: 17 | K8: =(F8-(0)+0-(J8*Ventas!AE5*1)) -> 8.3498714 | L8: =(K8/(Ventas!AE5*1)/80) -> 2.7292258 | M8: =(G8+0) -> 0 | O8: =(H8+0) -> 0 | Q8: =(K8+M8+O8) -> 8.3498714 | R8: 0 | S8: 0 | T8: 0 | U8: =IF(K8>0,K8+R8,R8) -> 8.3498714 | V8: =IF(M8>0,M8+S8,S8) -> 0 | W8: =IF(O8>0,O8+T8,T8) -> 0 | AA8: 18 | AB8: 0.005566 | AC8: 46313 | AD8: 92 | AE8: =(IF(K8>0,K8+R8,R8)-(AD8*Ventas!AE5*1.0489)) -> 4.6594816 | AF8: =(AE8/(Ventas!AE5*1.0489)/80) -> 1.4519886 | AG8: =(G8+0) -> 0 | AI8: =(H8+0) -> 0 | AK8: =(AE8+AG8+AI8) -> 4.6594816 | AL8: =(((AF8*7)+(AH8*1)+(AJ8*0))/8) -> 1.27049 | AM8: =(180*(Ventas!AE5*0.9644) - IF(AE8>0,AE8,0)) -> 1.9791725 | AN8: =IF(AM8>3,CEILING(AM8,5),0) -> 0 | AP8: =IF(AO8>3,CEILING(AO8,5),0) -> 0 | AQ8: =(AN8+AP8)*AB8 -> 0 | AR8: =_xlfn.XLOOKUP(C8,[1]Hoja2!$C$6:$C$24,[1]Hoja2!$D$6:$D$24,0,2,1) -> 0 | AS8: =IF(AE8>0,AE8+IF(AN8>0,AN8,0),AN8) -> 4.6594816 | AU8: =_xlfn.XLOOKUP(D8,[1]Hoja2!$E$6:$E$24,[1]Hoja2!$F$6:$F$24,0,2,1) -> 0 | AV8: 0 | AW8: 3016 | AX8: 0 | AZ8: =_xlfn.XLOOKUP(C8,[2]PI!$B$15:$B$99,[2]PI!$L$15:$L$99,0,2,1) -> 0 | BA8: =_xlfn.XLOOKUP(D8,[2]PI!$B$15:$B$99,[2]PI!$L$15:$L$99,0,2,1) -> 0 | BB8: =(AS8-(90*Ventas!AE5*0.9644)) -> 1.3401546 | BC8: =(BB8/(Ventas!AE5*0.9644)/80) -> 0.45421071 | BH8: =(IF(BB8>0,BB8,0)+IF(BD8>0,BD8,0)+IF(BF8>0,BF8,0)) -> 1.3401546 | BI8: =(((BC8*7)+(BE8*1)+(BG8*1))/8) -> 0.39743437 | BJ8: A | BK8: =AV8*AN8+AP8*AX8 -> 0 | BL8: =(AN8)*AZ8+AP8*BA8 -> 0
A9: 5350125120059 | B9: TONER HP C4092A/CANON EP-22 CPT 2.5K | C9: C00165 | D9: E00165 | F9: 1 | I9: 46221 | J9: 17 | K9: =(F9-(0)+0-(J9*Ventas!AE6*1)) -> 1 | M9: =(G9-(0)+0-(J9*Ventas!AE498*1)) -> 0 | O9: =(H9+0) -> 0 | Q9: =(K9+M9+O9) -> 1 | R9: 0 | S9: 0 | T9: 0 | U9: =IF(K9>0,K9+R9,R9) -> 1 | V9: =IF(M9>0,M9+S9,S9) -> 0 | W9: =IF(O9>0,O9+T9,T9) -> 0 | AA9: 18 | AB9: 0.004333 | AC9: 46313 | AD9: 92 | AE9: =(IF(K9>0,K9+R9,R9)-(AD9*Ventas!AE6*1.0489)) -> 1 | AG9: =(IF(M9>0,M9+S9,S9)-(AD9*Ventas!AE498*1.0489)) -> 0 | AI9: =(H9+0) -> 0 | AK9: =(AE9+AG9+AI9) -> 1 | AL9: =(((AF9*7)+(AH9*1)+(AJ9*0))/8) -> 0 | AM9: =(180*(Ventas!AE6*0.9644) - IF(AE9>0,AE9,0)) -> -1 | AN9: =IF(AM9>3,CEILING(AM9,5),0) -> 0 | AO9: =(180*(Ventas!AE498*0.9644) - IF(AG9>0,AG9,0)) -> 0 | AP9: =IF(AO9>3,CEILING(AO9,5),0) -> 0 | AQ9: =(AN9+AP9)*AB9 -> 0 | AR9: =_xlfn.XLOOKUP(C9,[1]Hoja2!$C$6:$C$24,[1]Hoja2!$D$6:$D$24,0,2,1) -> 0 | AS9: =IF(AE9>0,AE9+IF(AN9>0,AN9,0),AN9) -> 1 | AT9: =IF(AG9>0,AG9+IF(AP9>0,AP9,0),AP9) -> 0 | AU9: =_xlfn.XLOOKUP(D9,[1]Hoja2!$E$6:$E$24,[1]Hoja2!$F$6:$F$24,0,2,1) -> 0 | AV9: 0 | AW9: 3022 | AX9: 0 | AZ9: =_xlfn.XLOOKUP(C9,[2]PI!$B$15:$B$99,[2]PI!$L$15:$L$99,0,2,1) -> 0 | BA9: =_xlfn.XLOOKUP(D9,[2]PI!$B$15:$B$99,[2]PI!$L$15:$L$99,0,2,1) -> 0 | BH9: =(IF(BB9>0,BB9,0)+IF(BD9>0,BD9,0)+IF(BF9>0,BF9,0)) -> 0 | BI9: =(((BC9*7)+(BE9*1)+(BG9*1))/8) -> 0 | BJ9: A | BK9: =AV9*AN9+AP9*AX9 -> 0 | BL9: =(AN9)*AZ9+AP9*BA9 -> 0
A10: 5350125120400 | B10: TONER HP Q7553A 3K CPT | C10: C00166 | I10: 46221 | J10: 17 | K10: =(F10-(0)+0-(J10*Ventas!AE7*1)) -> 0 | M10: =(G10+0) -> 0 | O10: =(H10+0) -> 0 | Q10: =(K10+M10+O10) -> 0 | R10: 0 | S10: 0 | T10: 0 | U10: =IF(K10>0,K10+R10,R10) -> 0 | V10: =IF(M10>0,M10+S10,S10) -> 0 | W10: =IF(O10>0,O10+T10,T10) -> 0 | AC10: 46313 | AD10: 92 | AE10: =(IF(K10>0,K10+R10,R10)-(AD10*Ventas!AE7*1.0489)) -> 0 | AG10: =(G10+0) -> 0 | AI10: =(H10+0) -> 0 | AK10: =(AE10+AG10+AI10) -> 0 | AL10: =(((AF10*7)+(AH10*1)+(AJ10*0))/8) -> 0 | AM10: =(180*(Ventas!AE7*0.9644) - IF(AE10>0,AE10,0)) -> 0 | AN10: =IF(AM10>3,CEILING(AM10,5),0) -> 0 | AP10: =IF(AO10>3,CEILING(AO10,5),0) -> 0 | AQ10: =(AN10+AP10)*AB10 -> 0 | AR10: =_xlfn.XLOOKUP(C10,[1]Hoja2!$C$6:$C$24,[1]Hoja2!$D$6:$D$24,0,2,1) -> 0 | AS10: =IF(AE10>0,AE10+IF(AN10>0,AN10,0),AN10) -> 0 | AU10: =_xlfn.XLOOKUP(D10,[1]Hoja2!$E$6:$E$24,[1]Hoja2!$F$6:$F$24,0,2,1) -> 0 | AV10: 0 | AW10: 3002 | AX10: 0 | AZ10: =_xlfn.XLOOKUP(C10,[2]PI!$B$15:$B$99,[2]PI!$L$15:$L$99,0,2,1) -> 0 | BA10: =_xlfn.XLOOKUP(D10,[2]PI!$B$15:$B$99,[2]PI!$L$15:$L$99,0,2,1) -> 0 | BH10: =(IF(BB10>0,BB10,0)+IF(BD10>0,BD10,0)+IF(BF10>0,BF10,0)) -> 0 | BI10: =(((BC10*7)+(BE10*1)+(BG10*1))/8) -> 0 | BJ10: D | BK10: =AV10*AN10+AP10*AX10 -> 0 | BL10: =(AN10)*AZ10+AP10*BA10 -> 0
A11: 5352125120022 | B11: TONER XEROX 106R01271 BK 6110 CPT 2.0k | C11: C00174 | I11: 46221 | J11: 17 | K11: =(F11-(0)+0-(J11*Ventas!AE8*1)) -> 0 | M11: =(G11+0) -> 0 | O11: =(H11+0) -> 0 | Q11: =(K11+M11+O11) -> 0 | R11: 0 | S11: 0 | T11: 0 | U11: =IF(K11>0,K11+R11,R11) -> 0 | V11: =IF(M11>0,M11+S11,S11) -> 0 | W11: =IF(O11>0,O11+T11,T11) -> 0 | AA11: 48 | AB11: 0.057236 | AC11: 46313 | AD11: 92 | AE11: =(IF(K11>0,K11+R11,R11)-(AD11*Ventas!AE8*1.0489)) -> 0 | AG11: =(G11+0) -> 0 | AI11: =(H11+0) -> 0 | AK11: =(AE11+AG11+AI11) -> 0 | AL11: =(((AF11*7)+(AH11*1)+(AJ11*0))/8) -> 0 | AM11: =(180*(Ventas!AE8*0.9644) - IF(AE11>0,AE11,0)) -> 0 | AN11: =IF(AM11>3,CEILING(AM11,5),0) -> 0 | AP11: =IF(AO11>3,CEILING(AO11,5),0) -> 0 | AQ11: =(AN11+AP11)*AB11 -> 0 | AR11: =_xlfn.XLOOKUP(C11,[1]Hoja2!$C$6:$C$24,[1]Hoja2!$D$6:$D$24,0,2,1) -> 0 | AS11: =IF(AE11>0,AE11+IF(AN11>0,AN11,0),AN11) -> 0 | AU11: =_xlfn.XLOOKUP(D11,[1]Hoja2!$E$6:$E$24,[1]Hoja2!$F$6:$F$24,0,2,1) -> 0 | AV11: 0 | AW11: 2998 | AX11: 0 | AZ11: =_xlfn.XLOOKUP(C11,[2]PI!$B$15:$B$99,[2]PI!$L$15:$L$99,0,2,1) -> 0 | BA11: =_xlfn.XLOOKUP(D11,[2]PI!$B$15:$B$99,[2]PI!$L$15:$L$99,0,2,1) -> 0 | BH11: =(IF(BB11>0,BB11,0)+IF(BD11>0,BD11,0)+IF(BF11>0,BF11,0)) -> 0 | BI11: =(((BC11*7)+(BE11*1)+(BG11*1))/8) -> 0 | BJ11: A | BK11: =AV11*AN11+AP11*AX11 -> 0 | BL11: =(AN11)*AZ11+AP11*BA11 -> 0
A12: 5352125120039 | B12: TONER XEROX 106R01272 CY 6110 CPT 1.0k | C12: C00175 | F12: 3 | I12: 46221 | J12: 17 | K12: =(F12-(0)+0-(J12*Ventas!AE9*1)) -> 3 | M12: =(G12+0) -> 0 | O12: =(H12+0) -> 0 | Q12: =(K12+M12+O12) -> 3 | R12: 0 | S12: 0 | T12: 0 | U12: =IF(K12>0,K12+R12,R12) -> 3 | V12: =IF(M12>0,M12+S12,S12) -> 0 | W12: =IF(O12>0,O12+T12,T12) -> 0 | AC12: 46313 | AD12: 92 | AE12: =(IF(K12>0,K12+R12,R12)-(AD12*Ventas!AE9*1.0489)) -> 3 | AG12: =(G12+0) -> 0 | AI12: =(H12+0) -> 0 | AK12: =(AE12+AG12+AI12) -> 3 | AL12: =(((AF12*7)+(AH12*1)+(AJ12*0))/8) -> 0 | AM12: =(180*(Ventas!AE9*0.9644) - IF(AE12>0,AE12,0)) -> -3 | AN12: =IF(AM12>3,CEILING(AM12,5),0) -> 0 | AP12: =IF(AO12>3,CEILING(AO12,5),0) -> 0 | AQ12: =(AN12+AP12)*AB12 -> 0 | AR12: =_xlfn.XLOOKUP(C12,[1]Hoja2!$C$6:$C$24,[1]Hoja2!$D$6:$D$24,0,2,1) -> 0 | AS12: =IF(AE12>0,AE12+IF(AN12>0,AN12,0),AN12) -> 3 | AU12: =_xlfn.XLOOKUP(D12,[1]Hoja2!$E$6:$E$24,[1]Hoja2!$F$6:$F$24,0,2,1) -> 0 | AV12: 0 | AW12: 2998 | AX12: 0 | AZ12: =_xlfn.XLOOKUP(C12,[2]PI!$B$15:$B$99,[2]PI!$L$15:$L$99,0,2,1) -> 0 | BA12: =_xlfn.XLOOKUP(D12,[2]PI!$B$15:$B$99,[2]PI!$L$15:$L$99,0,2,1) -> 0 | BH12: =(IF(BB12>0,BB12,0)+IF(BD12>0,BD12,0)+IF(BF12>0,BF12,0)) -> 0 | BI12: =(((BC12*7)+(BE12*1)+(BG12*1))/8) -> 0 | BJ12: A | BK12: =AV12*AN12+AP12*AX12 -> 0 | BL12: =(AN12)*AZ12+AP12*BA12 -> 0
A13: 5352125120046 | B13: TONER XEROX 106R01273 MG 6110 CPT 1.0K | C13: C00176 | F13: 3 | I13: 46221 | J13: 17 | K13: =(F13-(0)+0-(J13*Ventas!AE10*1)) -> 3 | M13: =(G13+0) -> 0 | O13: =(H13+0) -> 0 | Q13: =(K13+M13+O13) -> 3 | R13: 0 | S13: 0 | T13: 0 | U13: =IF(K13>0,K13+R13,R13) -> 3 | V13: =IF(M13>0,M13+S13,S13) -> 0 | W13: =IF(O13>0,O13+T13,T13) -> 0 | AC13: 46313 | AD13: 92 | AE13: =(IF(K13>0,K13+R13,R13)-(AD13*Ventas!AE10*1.0489)) -> 3 | AG13: =(G13+0) -> 0 | AI13: =(H13+0) -> 0 | AK13: =(AE13+AG13+AI13) -> 3 | AL13: =(((AF13*7)+(AH13*1)+(AJ13*0))/8) -> 0 | AM13: =(180*(Ventas!AE10*0.9644) - IF(AE13>0,AE13,0)) -> -3 | AN13: =IF(AM13>3,CEILING(AM13,5),0) -> 0 | AP13: =IF(AO13>3,CEILING(AO13,5),0) -> 0 | AQ13: =(AN13+AP13)*AB13 -> 0 | AR13: =_xlfn.XLOOKUP(C13,[1]Hoja2!$C$6:$C$24,[1]Hoja2!$D$6:$D$24,0,2,1) -> 0 | AS13: =IF(AE13>0,AE13+IF(AN13>0,AN13,0),AN13) -> 3 | AU13: =_xlfn.XLOOKUP(D13,[1]Hoja2!$E$6:$E$24,[1]Hoja2!$F$6:$F$24,0,2,1) -> 0 | AV13: 0 | AW13: 2998 | AX13: 0 | AZ13: =_xlfn.XLOOKUP(C13,[2]PI!$B$15:$B$99,[2]PI!$L$15:$L$99,0,2,1) -> 0 | BA13: =_xlfn.XLOOKUP(D13,[2]PI!$B$15:$B$99,[2]PI!$L$15:$L$99,0,2,1) -> 0 | BH13: =(IF(BB13>0,BB13,0)+IF(BD13>0,BD13,0)+IF(BF13>0,BF13,0)) -> 0 | BI13: =(((BC13*7)+(BE13*1)+(BG13*1))/8) -> 0 | BJ13: A | BK13: =AV13*AN13+AP13*AX13 -> 0 | BL13: =(AN13)*AZ13+AP13*BA13 -> 0
A14: 5352125120053 | B14: TONER XEROX 106R01274 YE 6110 CPT 1.0K | C14: C00177 | F14: 1 | I14: 46221 | J14: 17 | K14: =(F14-(0)+0-(J14*Ventas!AE11*1)) -> 1 | M14: =(G14+0) -> 0 | O14: =(H14+0) -> 0 | Q14: =(K14+M14+O14) -> 1 | R14: 0 | S14: 0 | T14: 0 | U14: =IF(K14>0,K14+R14,R14) -> 1 | V14: =IF(M14>0,M14+S14,S14) -> 0 | W14: =IF(O14>0,O14+T14,T14) -> 0 | AC14: 46313 | AD14: 92 | AE14: =(IF(K14>0,K14+R14,R14)-(AD14*Ventas!AE11*1.0489)) -> 1 | AG14: =(G14+0) -> 0 | AI14: =(H14+0) -> 0 | AK14: =(AE14+AG14+AI14) -> 1 | AL14: =(((AF14*7)+(AH14*1)+(AJ14*0))/8) -> 0 | AM14: =(180*(Ventas!AE11*0.9644) - IF(AE14>0,AE14,0)) -> -1 | AN14: =IF(AM14>3,CEILING(AM14,5),0) -> 0 | AP14: =IF(AO14>3,CEILING(AO14,5),0) -> 0 | AQ14: =(AN14+AP14)*AB14 -> 0 | AR14: =_xlfn.XLOOKUP(C14,[1]Hoja2!$C$6:$C$24,[1]Hoja2!$D$6:$D$24,0,2,1) -> 0 | AS14: =IF(AE14>0,AE14+IF(AN14>0,AN14,0),AN14) -> 1 | AU14: =_xlfn.XLOOKUP(D14,[1]Hoja2!$E$6:$E$24,[1]Hoja2!$F$6:$F$24,0,2,1) -> 0 | AV14: 0 | AW14: 2998 | AX14: 0 | AZ14: =_xlfn.XLOOKUP(C14,[2]PI!$B$15:$B$99,[2]PI!$L$15:$L$99,0,2,1) -> 0 | BA14: =_xlfn.XLOOKUP(D14,[2]PI!$B$15:$B$99,[2]PI!$L$15:$L$99,0,2,1) -> 0 | BH14: =(IF(BB14>0,BB14,0)+IF(BD14>0,BD14,0)+IF(BF14>0,BF14,0)) -> 0 | BI14: =(((BC14*7)+(BE14*1)+(BG14*1))/8) -> 0 | BJ14: A | BK14: =AV14*AN14+AP14*AX14 -> 0 | BL14: =(AN14)*AZ14+AP14*BA14 -> 0
A15: 5353137120017 | B15: TONER BROTHER TN-360/TN-2115/2125 CPT 2.6K | C15: C00178 | D15: E00178 | F15: 65 | I15: 46221 | J15: 17 | K15: =(F15-(0)+0-(J15*Ventas!AE12*1)) -> 60.885757 | L15: =(K15/(Ventas!AE12*1)/80) -> 3.1447398 | M15: =(G15-(0)+0-(J15*Ventas!AE499*1)) -> 0 | O15: =(H15+0) -> 0 | Q15: =(K15+M15+O15) -> 60.885757 | R15: 10 | S15: 0 | T15: 0 | U15: =IF(K15>0,K15+R15,R15) -> 70.885757 | V15: =IF(M15>0,M15+S15,S15) -> 0 | W15: =IF(O15>0,O15+T15,T15) -> 0 | X15: 2.75 | AC15: 46313 | AD15: 92 | AE15: =(IF(K15>0,K15+R15,R15)-(AD15*Ventas!AE12*1.0489)) -> 47.531669 | AF15: =(AE15/(Ventas!AE12*1.0489)/80) -> 2.3405504 | AG15: =(IF(M15>0,M15+S15,S15)-(AD15*Ventas!AE499*1.0489)) -> 0 | AI15: =(H15+0) -> 0 | AK15: =(AE15+AG15+AI15) -> 47.531669 | AL15: =(((AF15*7)+(AH15*1)+(AJ15*0))/8) -> 2.0479816 | AM15: =(180*(Ventas!AE12*0.9644) - IF(AE15>0,AE15,0)) -> -5.5199251 | AN15: =IF(AM15>3,CEILING(AM15,5),0) -> 0 | AO15: =(180*(Ventas!AE499*0.9644) - IF(AG15>0,AG15,0)) -> 0 | AP15: =IF(AO15>3,CEILING(AO15,5),0) -> 0 | AQ15: =(AN15+AP15)*AB15 -> 0 | AR15: =_xlfn.XLOOKUP(C15,[1]Hoja2!$C$6:$C$24,[1]Hoja2!$D$6:$D$24,0,2,1) -> 0 | AS15: =IF(AE15>0,AE15+IF(AN15>0,AN15,0),AN15) -> 47.531669 | AT15: =IF(AG15>0,AG15+IF(AP15>0,AP15,0),AP15) -> 0 | AU15: =_xlfn.XLOOKUP(D15,[1]Hoja2!$E$6:$E$24,[1]Hoja2!$F$6:$F$24,0,2,1) -> 0 | AV15: 0 | AW15: 3016 | AX15: 0 | AZ15: =_xlfn.XLOOKUP(C15,[2]PI!$B$15:$B$99,[2]PI!$L$15:$L$99,0,2,1) -> 0 | BA15: =_xlfn.XLOOKUP(D15,[2]PI!$B$15:$B$99,[2]PI!$L$15:$L$99,0,2,1) -> 0 | BB15: =(AS15-(90*Ventas!AE12*0.9644)) -> 26.525797 | BC15: =(BB15/(Ventas!AE12*0.9644)/80) -> 1.4206276 | BH15: =(IF(BB15>0,BB15,0)+IF(BD15>0,BD15,0)+IF(BF15>0,BF15,0)) -> 26.525797 | BI15: =(((BC15*7)+(BE15*1)+(BG15*1))/8) -> 1.2430492 | BJ15: A | BK15: =AV15*AN15+AP15*AX15 -> 0 | BL15: =(AN15)*AZ15+AP15*BA15 -> 0
A16: 5353125120029 | B16: TONER BROTHER TN-580/TN-650 CPT 8K | C16: C00179 | F16: 58 | I16: 46221 | J16: 17 | K16: =(F16-(0)+0-(J16*Ventas!AE13*1)) -> 54.092186 | L16: =(K16/(Ventas!AE13*1)/80) -> 2.941437 | M16: =(G16+0) -> 0 | O16: =(H16+0) -> 0 | Q16: =(K16+M16+O16) -> 54.092186 | R16: 0 | S16: 0 | T16: 0 | U16: =IF(K16>0,K16+R16,R16) -> 54.092186 | V16: =IF(M16>0,M16+S16,S16) -> 0 | W16: =IF(O16>0,O16+T16,T16) -> 0 | AA16: 18 | AB16: 0.005566 | AC16: 46313 | AD16: 92 | AE16: =(IF(K16>0,K16+R16,R16)-(AD16*Ventas!AE13*1.0489)) -> 31.909869 | AF16: =(AE16/(Ventas!AE13*1.0489)/80) -> 1.6543064 | AG16: =(G16+0) -> 0 | AI16: =(H16+0) -> 0 | AK16: =(AE16+AG16+AI16) -> 31.909869 | AL16: =(((AF16*7)+(AH16*1)+(AJ16*0))/8) -> 1.4475181 | AM16: =(180*(Ventas!AE13*0.9644) - IF(AE16>0,AE16,0)) -> 7.9939723 | AN16: =IF(AM16>3,CEILING(AM16,5),0) -> 10 | AP16: =IF(AO16>3,CEILING(AO16,5),0) -> 0 | AQ16: =(AN16+AP16)*AB16 -> 0.05566 | AR16: =_xlfn.XLOOKUP(C16,[1]Hoja2!$C$6:$C$24,[1]Hoja2!$D$6:$D$24,0,2,1) -> 0 | AS16: =IF(AE16>0,AE16+IF(AN16>0,AN16,0),AN16) -> 41.909869 | AU16: =_xlfn.XLOOKUP(D16,[1]Hoja2!$E$6:$E$24,[1]Hoja2!$F$6:$F$24,0,2,1) -> 0 | AV16: 3.3 | AW16: 3016 | AX16: 0 | AZ16: =_xlfn.XLOOKUP(C16,[2]PI!$B$15:$B$99,[2]PI!$L$15:$L$99,0,2,1) -> 3.3 | BA16: =_xlfn.XLOOKUP(D16,[2]PI!$B$15:$B$99,[2]PI!$L$15:$L$99,0,2,1) -> 0 | BB16: =(AS16-(90*Ventas!AE13*0.9644)) -> 21.957948 | BC16: =(BB16/(Ventas!AE13*0.9644)/80) -> 1.238111 | BH16: =(IF(BB16>0,BB16,0)+IF(BD16>0,BD16,0)+IF(BF16>0,BF16,0)) -> 21.957948 | BI16: =(((BC16*7)+(BE16*1)+(BG16*1))/8) -> 1.0833471 | BJ16: A | BK16: =AV16*AN16+AP16*AX16 -> 33 | BL16: =(AN16)*AZ16+AP16*BA16 -> 33
B17: TONER OKIDATA 2500/ 2520 - CPT 2.2K | C17: C00181 | I17: 46221 | J17: 17 | K17: =(F17-(0)+0-(J17*Ventas!AE14*1)) -> 0 | M17: =(G17+0) -> 0 | O17: =(H17+0) -> 0 | Q17: =(K17+M17+O17) -> 0 | R17: 0 | S17: 0 | T17: 0 | U17: =IF(K17>0,K17+R17,R17) -> 0 | V17: =IF(M17>0,M17+S17,S17) -> 0 | W17: =IF(O17>0,O17+T17,T17) -> 0 | AC17: 46313 | AD17: 92 | AE17: =(IF(K17>0,K17+R17,R17)-(AD17*Ventas!AE14*1.0489)) -> 0 | AG17: =(G17+0) -> 0 | AI17: =(H17+0) -> 0 | AK17: =(AE17+AG17+AI17) -> 0 | AL17: =(((AF17*7)+(AH17*1)+(AJ17*0))/8) -> 0 | AM17: =(180*(Ventas!AE14*0.9644) - IF(AE17>0,AE17,0)) -> 0 | AN17: =IF(AM17>3,CEILING(AM17,5),0) -> 0 | AP17: =IF(AO17>3,CEILING(AO17,5),0) -> 0 | AQ17: =(AN17+AP17)*AB17 -> 0 | AR17: =_xlfn.XLOOKUP(C17,[1]Hoja2!$C$6:$C$24,[1]Hoja2!$D$6:$D$24,0,2,1) -> 0 | AS17: =IF(AE17>0,AE17+IF(AN17>0,AN17,0),AN17) -> 0 | AU17: =_xlfn.XLOOKUP(D17,[1]Hoja2!$E$6:$E$24,[1]Hoja2!$F$6:$F$24,0,2,1) -> 0 | AV17: 0 | AX17: 0 | AZ17: =_xlfn.XLOOKUP(C17,[2]PI!$B$15:$B$99,[2]PI!$L$15:$L$99,0,2,1) -> 0 | BA17: =_xlfn.XLOOKUP(D17,[2]PI!$B$15:$B$99,[2]PI!$L$15:$L$99,0,2,1) -> 0 | BH17: =(IF(BB17>0,BB17,0)+IF(BD17>0,BD17,0)+IF(BF17>0,BF17,0)) -> 0 | BI17: =(((BC17*7)+(BE17*1)+(BG17*1))/8) -> 0 | BJ17: D | BK17: =AV17*AN17+AP17*AX17 -> 0 | BL17: =(AN17)*AZ17+AP17*BA17 -> 0
A18: 5352125120060 | B18: TONER OKIDATA 6300 - CPT 10K | C18: C00182 | I18: 46221 | J18: 17 | K18: =(F18-(0)+0-(J18*Ventas!AE15*1)) -> 0 | M18: =(G18+0) -> 0 | O18: =(H18+0) -> 0 | Q18: =(K18+M18+O18) -> 0 | R18: 0 | S18: 0 | T18: 0 | U18: =IF(K18>0,K18+R18,R18) -> 0 | V18: =IF(M18>0,M18+S18,S18) -> 0 | W18: =IF(O18>0,O18+T18,T18) -> 0 | AA18: 6 | AB18: 0.015717 | AC18: 46313 | AD18: 92 | AE18: =(IF(K18>0,K18+R18,R18)-(AD18*Ventas!AE15*1.0489)) -> 0 | AG18: =(G18+0) -> 0 | AI18: =(H18+0) -> 0 | AK18: =(AE18+AG18+AI18) -> 0 | AL18: =(((AF18*7)+(AH18*1)+(AJ18*0))/8) -> 0 | AM18: =(180*(Ventas!AE15*0.9644) - IF(AE18>0,AE18,0)) -> 0 | AN18: =IF(AM18>3,CEILING(AM18,5),0) -> 0 | AP18: =IF(AO18>3,CEILING(AO18,5),0) -> 0 | AQ18: =(AN18+AP18)*AB18 -> 0 | AR18: =_xlfn.XLOOKUP(C18,[1]Hoja2!$C$6:$C$24,[1]Hoja2!$D$6:$D$24,0,2,1) -> 0 | AS18: =IF(AE18>0,AE18+IF(AN18>0,AN18,0),AN18) -> 0 | AU18: =_xlfn.XLOOKUP(D18,[1]Hoja2!$E$6:$E$24,[1]Hoja2!$F$6:$F$24,0,2,1) -> 0 | AV18: 0 | AX18: 0 | AZ18: =_xlfn.XLOOKUP(C18,[2]PI!$B$15:$B$99,[2]PI!$L$15:$L$99,0,2,1) -> 0 | BA18: =_xlfn.XLOOKUP(D18,[2]PI!$B$15:$B$99,[2]PI!$L$15:$L$99,0,2,1) -> 0 | BH18: =(IF(BB18>0,BB18,0)+IF(BD18>0,BD18,0)+IF(BF18>0,BF18,0)) -> 0 | BI18: =(((BC18*7)+(BE18*1)+(BG18*1))/8) -> 0 | BJ18: A | BK18: =AV18*AN18+AP18*AX18 -> 0 | BL18: =(AN18)*AZ18+AP18*BA18 -> 0
A19: 5352137120065 | B19: TONER XEROX 3140 / 3160 108R00909 2.5k CPT | C19: C00183 | D19: E00183 | F19: 43 | I19: 46221 | J19: 17 | K19: =(F19-(0)+0-(J19*Ventas!AE16*1)) -> 41.585357 | L19: =(K19/(Ventas!AE16*1)/80) -> 6.2467275 | M19: =(G19-(0)+0-(J19*Ventas!AE500*1)) -> 0 | O19: =(H19+0) -> 0 | Q19: =(K19+M19+O19) -> 41.585357 | R19: 0 | S19: 0 | T19: 0 | U19: =IF(K19>0,K19+R19,R19) -> 41.585357 | V19: =IF(M19>0,M19+S19,S19) -> 0 | W19: =IF(O19>0,O19+T19,T19) -> 0 | AA19: 12 | AB19: 0.079889 | AC19: 46313 | AD19: 92 | AE19: =(IF(K19>0,K19+R19,R19)-(AD19*Ventas!AE16*1.0489)) -> 33.555278 | AF19: =(AE19/(Ventas!AE16*1.0489)/80) -> 4.8055034 | AG19: =(IF(M19>0,M19+S19,S19)-(AD19*Ventas!AE500*1.0489)) -> 0 | AI19: =(H19+0) -> 0 | AK19: =(AE19+AG19+AI19) -> 33.555278 | AL19: =(((AF19*7)+(AH19*1)+(AJ19*0))/8) -> 4.2048154 | AM19: =(180*(Ventas!AE16*0.9644) - IF(AE19>0,AE19,0)) -> -19.109944 | AN19: =IF(AM19>3,CEILING(AM19,5),0) -> 0 | AO19: =(180*(Ventas!AE500*0.9644) - IF(AG19>0,AG19,0)) -> 0 | AP19: =IF(AO19>3,CEILING(AO19,5),0) -> 0 | AQ19: =(AN19+AP19)*AB19 -> 0 | AR19: =_xlfn.XLOOKUP(C19,[1]Hoja2!$C$6:$C$24,[1]Hoja2!$D$6:$D$24,0,2,1) -> 0 | AS19: =IF(AE19>0,AE19+IF(AN19>0,AN19,0),AN19) -> 33.555278 | AT19: =IF(AG19>0,AG19+IF(AP19>0,AP19,0),AP19) -> 0 | AU19: =_xlfn.XLOOKUP(D19,[1]Hoja2!$E$6:$E$24,[1]Hoja2!$F$6:$F$24,0,2,1) -> 0 | AV19: 0 | AW19: 3016 | AX19: 0 | AZ19: =_xlfn.XLOOKUP(C19,[2]PI!$B$15:$B$99,[2]PI!$L$15:$L$99,0,2,1) -> 0 | BA19: =_xlfn.XLOOKUP(D19,[2]PI!$B$15:$B$99,[2]PI!$L$15:$L$99,0,2,1) -> 0 | BB19: =(AS19-(90*Ventas!AE16*0.9644)) -> 26.332611 | BC19: =(BB19/(Ventas!AE16*0.9644)/80) -> 4.1015579 | BH19: =(IF(BB19>0,BB19,0)+IF(BD19>0,BD19,0)+IF(BF19>0,BF19,0)) -> 26.332611 | BI19: =(((BC19*7)+(BE19*1)+(BG19*1))/8) -> 3.5888632 | BJ19: A | BK19: =AV19*AN19+AP19*AX19 -> 0 | BL19: =(AN19)*AZ19+AP19*BA19 -> 0
A20: 5358125120055 | B20: TONER SAMSUNG MLT-104S - CPT 1665/3200/3205 1.5K | C20: C00184 | D20: E00184 | F20: 376 | G20: 50 | I20: 46221 | J20: 17 | K20: =(F20-(0)+0-(J20*Ventas!AE17*1)) -> 347.62287 | L20: =(K20/(Ventas!AE17*1)/80) -> 2.6031478 | M20: =(G20-(0)+0-(J20*Ventas!AE501*1)) -> 42.507371 | N20: =(M20/(Ventas!AE501*1)/80) -> 1.2055604 | O20: =(H20+0) -> 0 | Q20: =(K20+M20+O20) -> 390.13024 | R20: 0 | S20: 15 | T20: 0 | U20: =IF(K20>0,K20+R20,R20) -> 347.62287 | V20: =IF(M20>0,M20+S20,S20) -> 57.507371 | W20: =IF(O20>0,O20+T20,T20) -> 0 | Y20: 3.3 | AA20: 20 | AB20: 0.003886 | AC20: 46313 | AD20: 92 | AE20: =(IF(K20>0,K20+R20,R20)-(AD20*Ventas!AE17*1.0489)) -> 186.54294 | AF20: =(AE20/(Ventas!AE17*1.0489)/80) -> 1.3317884 | AG20: =(IF(M20>0,M20+S20,S20)-(AD20*Ventas!AE501*1.0489)) -> 14.976215 | AH20: =(AG20/(Ventas!AE501*1.0489)/80) -> 0.40494188 | AI20: =(H20+0) -> 0 | AK20: =(AE20+AG20+AI20) -> 201.51915 | AL20: =(((AF20*7)+(AH20*1)+(AJ20*0))/8) -> 1.2159326 | AM20: =(180*(Ventas!AE17*0.9644) - IF(AE20>0,AE20,0)) -> 103.22427 | AN20: 105 | AO20: =(180*(Ventas!AE501*0.9644) - IF(AG20>0,AG20,0)) -> 61.533219 | AP20: 75 | AQ20: =(AN20+AP20)*AB20 -> 0.69948 | AR20: =_xlfn.XLOOKUP(C20,[1]Hoja2!$C$6:$C$24,[1]Hoja2!$D$6:$D$24,0,2,1) -> 145 | AS20: =IF(AE20>0,AE20+IF(AN20>0,AN20,0),AN20) -> 291.54294 | AT20: =IF(AG20>0,AG20+IF(AP20>0,AP20,0),AP20) -> 89.976215 | AU20: =_xlfn.XLOOKUP(D20,[1]Hoja2!$E$6:$E$24,[1]Hoja2!$F$6:$F$24,0,2,1) -> 75 | AV20: 3.3 | AW20: 3016 | AX20: 3.3 | AZ20: =_xlfn.XLOOKUP(C20,[2]PI!$B$15:$B$99,[2]PI!$L$15:$L$99,0,2,1) -> 3.3 | BA20: =_xlfn.XLOOKUP(D20,[2]PI!$B$15:$B$99,[2]PI!$L$15:$L$99,0,2,1) -> 3.3 | BB20: =(AS20-(90*Ventas!AE17*0.9644)) -> 146.65934 | BC20: =(BB20/(Ventas!AE17*0.9644)/80) -> 1.1387883 | BD20: =(AT20-(90*Ventas!AE501*0.9644)) -> 51.721498 | BE20: =(BD20/(Ventas!AE501*0.9644)/80) -> 1.5210329 | BH20: =(IF(BB20>0,BB20,0)+IF(BD20>0,BD20,0)+IF(BF20>0,BF20,0)) -> 198.38083 | BI20: =(((BC20*7)+(BE20*1)+(BG20*1))/8) -> 1.1865689 | BJ20: A | BK20: =AV20*AN20+AP20*AX20 -> 594 | BL20: =(AN20)*AZ20+AP20*BA20 -> 594
A21: 5361125120017 | B21: TONER KYOCERA TK-112/TK-110 CPT 6K | C21: C00185 | I21: 46221 | J21: 17 | K21: =(F21-(0)+0-(J21*Ventas!AE18*1)) -> 0 | M21: =(G21+0) -> 0 | O21: =(H21+0) -> 0 | Q21: =(K21+M21+O21) -> 0 | R21: 0 | S21: 0 | T21: 0 | U21: =IF(K21>0,K21+R21,R21) -> 0 | V21: =IF(M21>0,M21+S21,S21) -> 0 | W21: =IF(O21>0,O21+T21,T21) -> 0 | AA21: 30 | AB21: 0.002729 | AC21: 46313 | AD21: 92 | AE21: =(IF(K21>0,K21+R21,R21)-(AD21*Ventas!AE18*1.0489)) -> 0 | AG21: =(G21+0) -> 0 | AI21: =(H21+0) -> 0 | AK21: =(AE21+AG21+AI21) -> 0 | AL21: =(((AF21*7)+(AH21*1)+(AJ21*0))/8) -> 0 | AM21: =(180*(Ventas!AE18*0.9644) - IF(AE21>0,AE21,0)) -> 0 | AN21: =IF(AM21>3,CEILING(AM21,5),0) -> 0 | AP21: =IF(AO21>3,CEILING(AO21,5),0) -> 0 | AQ21: =(AN21+AP21)*AB21 -> 0 | AR21: =_xlfn.XLOOKUP(C21,[1]Hoja2!$C$6:$C$24,[1]Hoja2!$D$6:$D$24,0,2,1) -> 0 | AS21: =IF(AE21>0,AE21+IF(AN21>0,AN21,0),AN21) -> 0 | AU21: =_xlfn.XLOOKUP(D21,[1]Hoja2!$E$6:$E$24,[1]Hoja2!$F$6:$F$24,0,2,1) -> 0 | AV21: 0 | AW21: 3022 | AX21: 0 | AZ21: =_xlfn.XLOOKUP(C21,[2]PI!$B$15:$B$99,[2]PI!$L$15:$L$99,0,2,1) -> 0 | BA21: =_xlfn.XLOOKUP(D21,[2]PI!$B$15:$B$99,[2]PI!$L$15:$L$99,0,2,1) -> 0 | BH21: =(IF(BB21>0,BB21,0)+IF(BD21>0,BD21,0)+IF(BF21>0,BF21,0)) -> 0 | BI21: =(((BC21*7)+(BE21*1)+(BG21*1))/8) -> 0 | BJ21: A | BK21: =AV21*AN21+AP21*AX21 -> 0 | BL21: =(AN21)*AZ21+AP21*BA21 -> 0
A22: 5358125120062 | B22: TONER CANON FX9 CPT 2K | C22: C00186 | I22: 46221 | J22: 17 | K22: =(F22-(0)+0-(J22*Ventas!AE19*1)) -> 0 | M22: =(G22+0) -> 0 | O22: =(H22+0) -> 0 | Q22: =(K22+M22+O22) -> 0 | R22: 0 | S22: 0 | T22: 0 | U22: =IF(K22>0,K22+R22,R22) -> 0 | V22: =IF(M22>0,M22+S22,S22) -> 0 | W22: =IF(O22>0,O22+T22,T22) -> 0 | AC22: 46313 | AD22: 92 | AE22: =(IF(K22>0,K22+R22,R22)-(AD22*Ventas!AE19*1.0489)) -> 0 | AG22: =(G22+0) -> 0 | AI22: =(H22+0) -> 0 | AK22: =(AE22+AG22+AI22) -> 0 | AL22: =(((AF22*7)+(AH22*1)+(AJ22*0))/8) -> 0 | AM22: =(180*(Ventas!AE19*0.9644) - IF(AE22>0,AE22,0)) -> 0 | AN22: =IF(AM22>3,CEILING(AM22,5),0) -> 0 | AP22: =IF(AO22>3,CEILING(AO22,5),0) -> 0 | AQ22: =(AN22+AP22)*AB22 -> 0 | AR22: =_xlfn.XLOOKUP(C22,[1]Hoja2!$C$6:$C$24,[1]Hoja2!$D$6:$D$24,0,2,1) -> 0 | AS22: =IF(AE22>0,AE22+IF(AN22>0,AN22,0),AN22) -> 0 | AU22: =_xlfn.XLOOKUP(D22,[1]Hoja2!$E$6:$E$24,[1]Hoja2!$F$6:$F$24,0,2,1) -> 0 | AV22: 0 | AW22: 3011 | AX22: 0 | AZ22: =_xlfn.XLOOKUP(C22,[2]PI!$B$15:$B$99,[2]PI!$L$15:$L$99,0,2,1) -> 0 | BA22: =_xlfn.XLOOKUP(D22,[2]PI!$B$15:$B$99,[2]PI!$L$15:$L$99,0,2,1) -> 0 | BH22: =(IF(BB22>0,BB22,0)+IF(BD22>0,BD22,0)+IF(BF22>0,BF22,0)) -> 0 | BI22: =(((BC22*7)+(BE22*1)+(BG22*1))/8) -> 0 | BJ22: D | BK22: =AV22*AN22+AP22*AX22 -> 0 | BL22: =(AN22)*AZ22+AP22*BA22 -> 0
A23: 5359137120019 | B23: TONER SAMSUNG 105L 2,5K CPT | C23: C00187 | D23: E00187 | F23: 15 | G23: 2 | I23: 46221 | J23: 17 | K23: =(F23-(0)+0-(J23*Ventas!AE20*1)) -> 9.3552714 | L23: =(K23/(Ventas!AE20*1)/80) -> 0.35218614 | M23: =(G23-(0)+0-(J23*Ventas!AE502*1)) -> 1.15 | N23: =(M23/(Ventas!AE502*1)/85) -> 0.27058824 | O23: =(H23+0) -> 0 | Q23: =(K23+M23+O23) -> 10.505271 | R23: 10 | S23: 10 | T23: 0 | U23: =IF(K23>0,K23+R23,R23) -> 19.355271 | V23: =IF(M23>0,M23+S23,S23) -> 11.15 | W23: =IF(O23>0,O23+T23,T23) -> 0 | X23: 4.3 | Y23: 4.3 | AA23: 12 | AB23: 0.006657 | AC23: 46313 | AD23: 92 | AE23: =(IF(K23>0,K23+R23,R23)-(AD23*Ventas!AE20*1.0489)) -> -12.686466 | AF23: =(AE23/(Ventas!AE20*1.0489)/80) -> -0.45532599 | AG23: =(IF(M23>0,M23+S23,S23)-(AD23*Ventas!AE502*1.0489)) -> 6.32506 | AH23: =(AG23/(Ventas!AE502*1.0489)/85) -> 1.4188668 | AI23: =(H23+0) -> 0 | AK23: =(AE23+AG23+AI23) -> -6.3614058 | AL23: =(((AF23*7)+(AH23*1)+(AJ23*0))/8) -> -0.22105189 | AM23: =(180*(Ventas!AE20*0.9644) - IF(AE23>0,AE23,0)) -> 57.639984 | AN23: 60 | AO23: =(180*(Ventas!AE502*0.9644) - IF(AG23>0,AG23,0)) -> 2.35454 | AP23: =IF(AO23>3,CEILING(AO23,5),0) -> 0 | AQ23: =(AN23+AP23)*AB23 -> 0.39942 | AR23: =_xlfn.XLOOKUP(C23,[1]Hoja2!$C$6:$C$24,[1]Hoja2!$D$6:$D$24,0,2,1) -> 0 | AS23: =IF(AE23>0,AE23+IF(AN23>0,AN23,0),AN23) -> 60 | AT23: =IF(AG23>0,AG23+IF(AP23>0,AP23,0),AP23) -> 6.32506 | AU23: =_xlfn.XLOOKUP(D23,[1]Hoja2!$E$6:$E$24,[1]Hoja2!$F$6:$F$24,0,2,1) -> 0 | AV23: 4.3 | AW23: 3016 | AX23: 0 | AZ23: =_xlfn.XLOOKUP(C23,[2]PI!$B$15:$B$99,[2]PI!$L$15:$L$99,0,2,1) -> 4.3 | BA23: =_xlfn.XLOOKUP(D23,[2]PI!$B$15:$B$99,[2]PI!$L$15:$L$99,0,2,1) -> 0 | BB23: =(AS23-(90*Ventas!AE20*0.9644)) -> 31.180008 | BC23: =(BB23/(Ventas!AE20*0.9644)/80) -> 1.2171242 | BD23: =(AT23-(90*Ventas!AE502*0.9644)) -> 1.98526 | BE23: =(BD23/(Ventas!AE502*0.9644)/85) -> 0.48436333 | BH23: =(IF(BB23>0,BB23,0)+IF(BD23>0,BD23,0)+IF(BF23>0,BF23,0)) -> 33.165268 | BI23: =(((BC23*7)+(BE23*1)+(BG23*1))/8) -> 1.1255291 | BJ23: A | BK23: =AV23*AN23+AP23*AX23 -> 258 | BL23: =(AN23)*AZ23+AP23*BA23 -> 258
A24: 5350137120535 | B24: TONER HP CE278A 2.1K CPT | C24: C00188 | I24: 46221 | J24: 17 | K24: =(F24-(0)+0-(J24*Ventas!AE21*1)) -> 0 | M24: =(G24+0) -> 0 | O24: =(H24+0) -> 0 | Q24: =(K24+M24+O24) -> 0 | R24: 0 | S24: 0 | T24: 0 | U24: =IF(K24>0,K24+R24,R24) -> 0 | V24: =IF(M24>0,M24+S24,S24) -> 0 | W24: =IF(O24>0,O24+T24,T24) -> 0 | AC24: 46313 | AD24: 92 | AE24: =(IF(K24>0,K24+R24,R24)-(AD24*Ventas!AE21*1.0489)) -> 0 | AG24: =(G24+0) -> 0 | AI24: =(H24+0) -> 0 | AK24: =(AE24+AG24+AI24) -> 0 | AL24: =(((AF24*7)+(AH24*1)+(AJ24*0))/8) -> 0 | AM24: =(180*(Ventas!AE21*0.9644) - IF(AE24>0,AE24,0)) -> 0 | AN24: =IF(AM24>3,CEILING(AM24,5),0) -> 0 | AP24: =IF(AO24>3,CEILING(AO24,5),0) -> 0 | AQ24: =(AN24+AP24)*AB24 -> 0 | AR24: =_xlfn.XLOOKUP(C24,[1]Hoja2!$C$6:$C$24,[1]Hoja2!$D$6:$D$24,0,2,1) -> 0 | AS24: =IF(AE24>0,AE24+IF(AN24>0,AN24,0),AN24) -> 0 | AU24: =_xlfn.XLOOKUP(D24,[1]Hoja2!$E$6:$E$24,[1]Hoja2!$F$6:$F$24,0,2,1) -> 0 | AV24: 0 | AW24: 3013 | AX24: 0 | AZ24: =_xlfn.XLOOKUP(C24,[2]PI!$B$15:$B$99,[2]PI!$L$15:$L$99,0,2,1) -> 0 | BA24: =_xlfn.XLOOKUP(D24,[2]PI!$B$15:$B$99,[2]PI!$L$15:$L$99,0,2,1) -> 0 | BH24: =(IF(BB24>0,BB24,0)+IF(BD24>0,BD24,0)+IF(BF24>0,BF24,0)) -> 0 | BI24: =(((BC24*7)+(BE24*1)+(BG24*1))/8) -> 0 | BJ24: A | BK24: =AV24*AN24+AP24*AX24 -> 0 | BL24: =(AN24)*AZ24+AP24*BA24 -> 0
A25: 5350137120528 | B25: TONER HP CE255X CPT 12.5K | C25: C00189 | F25: 2 | I25: 46221 | J25: 17 | K25: =(F25-(0)+0-(J25*Ventas!AE22*1)) -> 0.84221905 | L25: =(K25/(Ventas!AE22*1)/80) -> 0.15458153 | M25: =(G25+0) -> 0 | O25: =(H25+0) -> 0 | Q25: =(K25+M25+O25) -> 0.84221905 | R25: 0 | S25: 0 | T25: 0 | U25: =IF(K25>0,K25+R25,R25) -> 0.84221905 | V25: =IF(M25>0,M25+S25,S25) -> 0 | W25: =IF(O25>0,O25+T25,T25) -> 0 | AA25: 10 | AB25: 0.013318 | AC25: 46313 | AD25: 92 | AE25: =(IF(K25>0,K25+R25,R25)-(AD25*Ventas!AE22*1.0489)) -> -5.7298088 | AF25: =(AE25/(Ventas!AE22*1.0489)/80) -> -1.0026251 | AG25: =(G25+0) -> 0 | AI25: =(H25+0) -> 0 | AK25: =(AE25+AG25+AI25) -> -5.7298088 | AL25: =(((AF25*7)+(AH25*1)+(AJ25*0))/8) -> -0.87729697 | AM25: =(180*(Ventas!AE22*0.9644) - IF(AE25>0,AE25,0)) -> 11.822442 | AN25: 12 | AQ25: =(AN25+AP25)*AB25 -> 0.159816 | AR25: =_xlfn.XLOOKUP(C25,[1]Hoja2!$C$6:$C$24,[1]Hoja2!$D$6:$D$24,0,2,1) -> 0 | AS25: =IF(AE25>0,AE25+IF(AN25>0,AN25,0),AN25) -> 12 | AU25: =_xlfn.XLOOKUP(D25,[1]Hoja2!$E$6:$E$24,[1]Hoja2!$F$6:$F$24,0,2,1) -> 0 | AV25: 7.1 | AW25: 3016 | AX25: 0 | AZ25: =_xlfn.XLOOKUP(C25,[2]PI!$B$15:$B$99,[2]PI!$L$15:$L$99,0,2,1) -> 7.1 | BA25: =_xlfn.XLOOKUP(D25,[2]PI!$B$15:$B$99,[2]PI!$L$15:$L$99,0,2,1) -> 0 | BB25: =(AS25-(90*Ventas!AE22*0.9644)) -> 6.0887791 | BC25: =(BB25/(Ventas!AE22*0.9644)/80) -> 1.1587922 | BH25: =(IF(BB25>0,BB25,0)+IF(BD25>0,BD25,0)+IF(BF25>0,BF25,0)) -> 6.0887791 | BI25: =(((BC25*7)+(BE25*1)+(BG25*1))/8) -> 1.0139431 | BJ25: A | BK25: =AV25*AN25+AP25*AX25 -> 85.2 | BL25: =(AN25)*AZ25+AP25*BA25 -> 85.2
A26: 5353125120036 | B26: TONER BROTHER TN-450/2250 CPT 2.5K | C26: C00190 | D26: E00190 | F26: 321 | G26: 20 | I26: 46221 | J26: 17 | K26: =(F26-(0)+0-(J26*Ventas!AE23*1)) -> 282.26356 | L26: =(K26/(Ventas!AE23*1)/80) -> 1.5484387 | M26: =(G26-(0)+0-(J26*Ventas!AE503*1)) -> 14.085943 | N26: =(M26/(Ventas!AE503*1)/80) -> 0.50612681 | O26: =(H26+0) -> 0 | Q26: =(K26+M26+O26) -> 296.3495 | R26: 96 | S26: 50 | T26: 0 | U26: =IF(K26>0,K26+R26,R26) -> 378.26356 | V26: =IF(M26>0,M26+S26,S26) -> 64.085943 | W26: =IF(O26>0,O26+T26,T26) -> 0 | X26: 2.1 | Y26: 2.1 | AA26: 18 | AB26: 0.005566 | AC26: 46313 | AD26: 92 | AE26: =(IF(K26>0,K26+R26,R26)-(AD26*Ventas!AE23*1.0489)) -> 158.38001 | AF26: =(AE26/(Ventas!AE23*1.0489)/80) -> 0.828334 | AG26: =(IF(M26>0,M26+S26,S26)-(AD26*Ventas!AE503*1.0489)) -> 30.515389 | AH26: =(AG26/(Ventas!AE503*1.0489)/80) -> 1.0453416 | AI26: =(H26+0) -> 0 | AK26: =(AE26+AG26+AI26) -> 188.8954 | AL26: =(((AF26*7)+(AH26*1)+(AJ26*0))/8) -> 0.85545995 | AM26: =(180*(Ventas!AE23*0.9644) - IF(AE26>0,AE26,0)) -> 237.1692 | AN26: 216 | AO26: =(180*(Ventas!AE503*0.9644) - IF(AG26>0,AG26,0)) -> 29.874788 | AP26: =IF(AO26>3,CEILING(AO26,5),0) -> 30 | AQ26: =(AN26+AP26)*AB26 -> 1.369236 | AR26: =_xlfn.XLOOKUP(C26,[1]Hoja2!$C$6:$C$24,[1]Hoja2!$D$6:$D$24,0,2,1) -> 0 | AS26: =IF(AE26>0,AE26+IF(AN26>0,AN26,0),AN26) -> 374.38001 | AT26: =IF(AG26>0,AG26+IF(AP26>0,AP26,0),AP26) -> 60.515389 | AU26: =_xlfn.XLOOKUP(D26,[1]Hoja2!$E$6:$E$24,[1]Hoja2!$F$6:$F$24,0,2,1) -> 0 | AV26: 2.2 | AW26: 3016 | AX26: 2.2 | AZ26: =_xlfn.XLOOKUP(C26,[2]PI!$B$15:$B$99,[2]PI!$L$15:$L$99,0,2,1) -> 2.2 | BA26: =_xlfn.XLOOKUP(D26,[2]PI!$B$15:$B$99,[2]PI!$L$15:$L$99,0,2,1) -> 2.2 | BB26: =(AS26-(90*Ventas!AE23*0.9644)) -> 176.60541 | BC26: =(BB26/(Ventas!AE23*0.9644)/80) -> 1.0045834 | BD26: =(AT26-(90*Ventas!AE503*0.9644)) -> 30.3203 | BE26: =(BD26/(Ventas!AE503*0.9644)/80) -> 1.1296651 | BH26: =(IF(BB26>0,BB26,0)+IF(BD26>0,BD26,0)+IF(BF26>0,BF26,0)) -> 206.92571 | BI26: =(((BC26*7)+(BE26*1)+(BG26*1))/8) -> 1.0202186 | BJ26: A | BK26: =AV26*AN26+AP26*AX26 -> 541.2 | BL26: =(AN26)*AZ26+AP26*BA26 -> 541.2
B27: TONER BROTHER TN-650 CPT 8K | C27: C00191 | I27: 46221 | J27: 17 | K27: =(F27-(0)+0-(J27*Ventas!AE24*1)) -> 0 | M27: =(G27+0) -> 0 | O27: =(H27+0) -> 0 | Q27: =(K27+M27+O27) -> 0 | R27: 0 | S27: 0 | T27: 0 | U27: =IF(K27>0,K27+R27,R27) -> 0 | V27: =IF(M27>0,M27+S27,S27) -> 0 | W27: =IF(O27>0,O27+T27,T27) -> 0 | AC27: 46313 | AD27: 92 | AE27: =(IF(K27>0,K27+R27,R27)-(AD27*Ventas!AE24*1.0489)) -> 0 | AG27: =(G27+0) -> 0 | AI27: =(H27+0) -> 0 | AK27: =(AE27+AG27+AI27) -> 0 | AL27: =(((AF27*7)+(AH27*1)+(AJ27*0))/8) -> 0 | AM27: =(180*(Ventas!AE24*0.9644) - IF(AE27>0,AE27,0)) -> 0 | AN27: =IF(AM27>3,CEILING(AM27,5),0) -> 0 | AP27: =IF(AO27>3,CEILING(AO27,5),0) -> 0 | AQ27: =(AN27+AP27)*AB27 -> 0 | AR27: =_xlfn.XLOOKUP(C27,[1]Hoja2!$C$6:$C$24,[1]Hoja2!$D$6:$D$24,0,2,1) -> 0 | AS27: =IF(AE27>0,AE27+IF(AN27>0,AN27,0),AN27) -> 0 | AU27: =_xlfn.XLOOKUP(D27,[1]Hoja2!$E$6:$E$24,[1]Hoja2!$F$6:$F$24,0,2,1) -> 0 | AV27: 0 | AW27: 2998 | AX27: 0 | AZ27: =_xlfn.XLOOKUP(C27,[2]PI!$B$15:$B$99,[2]PI!$L$15:$L$99,0,2,1) -> 0 | BA27: =_xlfn.XLOOKUP(D27,[2]PI!$B$15:$B$99,[2]PI!$L$15:$L$99,0,2,1) -> 0 | BH27: =(IF(BB27>0,BB27,0)+IF(BD27>0,BD27,0)+IF(BF27>0,BF27,0)) -> 0 | BI27: =(((BC27*7)+(BE27*1)+(BG27*1))/8) -> 0 | BJ27: D | BK27: =AV27*AN27+AP27*AX27 -> 0 | BL27: =(AN27)*AZ27+AP27*BA27 -> 0
A28: 5358137120104 | B28: TONER SAMSUNG CLP-409 BK CPT 1.5K | C28: C00192 | F28: 1 | I28: 46221 | J28: 17 | K28: =(F28-(0)+0-(J28*Ventas!AE25*1)) -> 1 | M28: =(G28+0) -> 0 | O28: =(H28+0) -> 0 | Q28: =(K28+M28+O28) -> 1 | R28: 0 | S28: 0 | T28: 0 | U28: =IF(K28>0,K28+R28,R28) -> 1 | V28: =IF(M28>0,M28+S28,S28) -> 0 | W28: =IF(O28>0,O28+T28,T28) -> 0 | AA28: 10 | AB28: 0.006349 | AC28: 46313 | AD28: 92 | AE28: =(IF(K28>0,K28+R28,R28)-(AD28*Ventas!AE25*1.0489)) -> 1 | AG28: =(G28+0) -> 0 | AI28: =(H28+0) -> 0 | AK28: =(AE28+AG28+AI28) -> 1 | AL28: =(((AF28*7)+(AH28*1)+(AJ28*0))/8) -> 0 | AM28: =(180*(Ventas!AE25*0.9644) - IF(AE28>0,AE28,0)) -> -1 | AN28: =IF(AM28>3,CEILING(AM28,5),0) -> 0 | AP28: =IF(AO28>3,CEILING(AO28,5),0) -> 0 | AQ28: =(AN28+AP28)*AB28 -> 0 | AR28: =_xlfn.XLOOKUP(C28,[1]Hoja2!$C$6:$C$24,[1]Hoja2!$D$6:$D$24,0,2,1) -> 0 | AS28: =IF(AE28>0,AE28+IF(AN28>0,AN28,0),AN28) -> 1 | AU28: =_xlfn.XLOOKUP(D28,[1]Hoja2!$E$6:$E$24,[1]Hoja2!$F$6:$F$24,0,2,1) -> 0 | AV28: 0 | AW28: 3011 | AX28: 0 | AZ28: =_xlfn.XLOOKUP(C28,[2]PI!$B$15:$B$99,[2]PI!$L$15:$L$99,0,2,1) -> 0 | BA28: =_xlfn.XLOOKUP(D28,[2]PI!$B$15:$B$99,[2]PI!$L$15:$L$99,0,2,1) -> 0 | BH28: =(IF(BB28>0,BB28,0)+IF(BD28>0,BD28,0)+IF(BF28>0,BF28,0)) -> 0 | BI28: =(((BC28*7)+(BE28*1)+(BG28*1))/8) -> 0 | BJ28: D | BK28: =AV28*AN28+AP28*AX28 -> 0 | BL28: =(AN28)*AZ28+AP28*BA28 -> 0
